Workbook

Sheet Rohdaten
B1: hours | AG1: t0 | AH1: 1.abiotic
A2: PM1.1 | B2: 0 | D2: 1 | E2: 2 | F2: 3 | G2: 4 | H2: 5 | I2: 6 | J2: 7 | K2: 8 | L2: 9 | M2: 10 | N2: 11 | O2: 12 | AH2: 1 | AI2: 2 | AJ2: 3 | AK2: 4 | AL2: 5 | AM2: 6 | AN2: 7 | AO2: 8 | AP2: 9 | AQ2: 10 | AR2: 11 | AS2: 12
C3: A | D3: 0.128 | E3: 0.185 | F3: 0.117 | G3: 0.12 | H3: 0.119 | I3: 0.118 | J3: 0.118 | K3: 0.118 | L3: 0.167 | M3: 0.119 | N3: 0.121 | O3: 0.136 | P3: 490 | AG3: A | AH3: 0.123 | AI3: 0.17 | AJ3: 0.112 | AK3: 0.113 | AL3: 0.111 | AM3: 0.114 | AN3: 0.113 | AO3: 0.113 | AP3: 0.112 | AQ3: 0.111 | AR3: 0.113 | AS3: 0.116 | AT3: 490
D4: 0.099 | E4: 0.086 | F4: 0.089 | G4: 0.09 | H4: 0.091 | I4: 0.088 | J4: 0.09 | K4: 0.091 | L4: 0.138 | M4: 0.091 | N4: 0.093 | O4: 0.105 | P4: 750 | AH4: 0.099 | AI4: 0.089 | AJ4: 0.088 | AK4: 0.087 | AL4: 0.086 | AM4: 0.087 | AN4: 0.087 | AO4: 0.088 | AP4: 0.087 | AQ4: 0.088 | AR4: 0.088 | AS4: 0.092 | AT4: 750
C5: B | D5: 0.126 | E5: 0.117 | F5: 0.123 | G5: 0.127 | H5: 0.129 | I5: 0.121 | J5: 0.121 | K5: 0.212 | L5: 0.124 | M5: 0.126 | N5: 0.12 | O5: 0.125 | P5: 490 | AG5: B | AH5: 0.119 | AI5: 0.111 | AJ5: 0.113 | AK5: 0.115 | AL5: 0.12 | AM5: 0.117 | AN5: 0.115 | AO5: 0.197 | AP5: 0.114 | AQ5: 0.113 | AR5: 0.112 | AS5: 0.113 | AT5: 490
D6: 0.096 | E6: 0.091 | F6: 0.093 | G6: 0.095 | H6: 0.092 | I6: 0.092 | J6: 0.093 | K6: 0.093 | L6: 0.095 | M6: 0.096 | N6: 0.09 | O6: 0.095 | P6: 750 | AH6: 0.092 | AI6: 0.089 | AJ6: 0.088 | AK6: 0.088 | AL6: 0.09 | AM6: 0.09 | AN6: 0.09 | AO6: 0.088 | AP6: 0.089 | AQ6: 0.089 | AR6: 0.087 | AS6: 0.089 | AT6: 750
C7: C | D7: 0.126 | E7: 0.125 | F7: 0.122 | G7: 0.257 | H7: 0.121 | I7: 0.128 | J7: 0.122 | K7: 0.125 | L7: 0.155 | M7: 0.118 | N7: 0.117 | O7: 0.128 | P7: 490 | AG7: C | AH7: 0.118 | AI7: 0.121 | AJ7: 0.12 | AK7: 0.252 | AL7: 0.132 | AM7: 0.139 | AN7: 0.128 | AO7: 0.122 | AP7: 0.123 | AQ7: 0.114 | AR7: 0.113 | AS7: 0.113 | AT7: 490
D8: 0.095 | E8: 0.088 | F8: 0.093 | G8: 0.095 | H8: 0.092 | I8: 0.095 | J8: 0.091 | K8: 0.095 | L8: 0.125 | M8: 0.09 | N8: 0.09 | O8: 0.099 | P8: 750 | AH8: 0.092 | AI8: 0.088 | AJ8: 0.093 | AK8: 0.092 | AL8: 0.105 | AM8: 0.107 | AN8: 0.097 | AO8: 0.093 | AP8: 0.097 | AQ8: 0.091 | AR8: 0.089 | AS8: 0.088 | AT8: 750
C9: D | D9: 0.126 | E9: 0.116 | F9: 0.122 | G9: 0.125 | H9: 0.122 | I9: 0.13 | J9: 0.125 | K9: 0.121 | L9: 0.124 | M9: 0.124 | N9: 0.123 | O9: 0.124 | P9: 490 | AG9: D | AH9: 0.113 | AI9: 0.111 | AJ9: 0.114 | AK9: 0.116 | AL9: 0.117 | AM9: 0.116 | AN9: 0.118 | AO9: 0.12 | AP9: 0.116 | AQ9: 0.114 | AR9: 0.113 | AS9: 0.114 | AT9: 490
D10: 0.096 | E10: 0.089 | F10: 0.093 | G10: 0.097 | H10: 0.091 | I10: 0.098 | J10: 0.094 | K10: 0.09 | L10: 0.092 | M10: 0.095 | N10: 0.095 | O10: 0.093 | P10: 750 | AH10: 0.089 | AI10: 0.088 | AJ10: 0.09 | AK10: 0.092 | AL10: 0.093 | AM10: 0.09 | AN10: 0.09 | AO10: 0.092 | AP10: 0.091 | AQ10: 0.09 | AR10: 0.089 | AS10: 0.088 | AT10: 750
C11: E | D11: 0.121 | E11: 0.11 | F11: 0.118 | G11: 0.131 | H11: 0.117 | I11: 0.121 | J11: 0.124 | K11: 0.12 | L11: 0.12 | M11: 0.117 | N11: 0.115 | O11: 0.124 | P11: 490 | AG11: E | AH11: 0.126 | AI11: 0.115 | AJ11: 0.121 | AK11: 0.13 | AL11: 0.118 | AM11: 0.117 | AN11: 0.126 | AO11: 0.118 | AP11: 0.135 | AQ11: 0.124 | AR11: 0.221 | AS11: 0.114 | AT11: 490
D12: 0.093 | E12: 0.087 | F12: 0.093 | G12: 0.093 | H12: 0.089 | I12: 0.092 | J12: 0.094 | K12: 0.091 | L12: 0.09 | M12: 0.089 | N12: 0.09 | O12: 0.094 | P12: 750 | AH12: 0.098 | AI12: 0.091 | AJ12: 0.096 | AK12: 0.094 | AL12: 0.093 | AM12: 0.091 | AN12: 0.096 | AO12: 0.091 | AP12: 0.105 | AQ12: 0.097 | AR12: 0.098 | AS12: 0.089 | AT12: 750
C13: F | D13: 0.125 | E13: 0.11 | F13: 0.122 | G13: 0.117 | H13: 0.12 | I13: 0.122 | J13: 0.121 | K13: 0.125 | L13: 0.126 | M13: 0.117 | N13: 0.116 | O13: 0.121 | P13: 490 | AG13: F | AH13: 0.124 | AI13: 0.112 | AJ13: 0.115 | AK13: 0.118 | AL13: 0.113 | AM13: 0.115 | AN13: 0.115 | AO13: 0.116 | AP13: 0.116 | AQ13: 0.113 | AR13: 0.113 | AS13: 0.115 | AT13: 490
D14: 0.097 | E14: 0.087 | F14: 0.096 | G14: 0.091 | H14: 0.092 | I14: 0.093 | J14: 0.091 | K14: 0.094 | L14: 0.095 | M14: 0.089 | N14: 0.089 | O14: 0.091 | P14: 750 | AH14: 0.096 | AI14: 0.089 | AJ14: 0.092 | AK14: 0.094 | AL14: 0.09 | AM14: 0.089 | AN14: 0.088 | AO14: 0.089 | AP14: 0.091 | AQ14: 0.089 | AR14: 0.089 | AS14: 0.09 | AT14: 750
C15: G | D15: 0.122 | E15: 0.108 | F15: 0.114 | G15: 0.126 | H15: 0.112 | I15: 0.118 | J15: 0.125 | K15: 0.12 | L15: 0.121 | M15: 0.116 | N15: 0.116 | O15: 0.119 | P15: 490 | AG15: G | AH15: 0.119 | AI15: 0.112 | AJ15: 0.115 | AK15: 0.117 | AL15: 0.11 | AM15: 0.117 | AN15: 0.119 | AO15: 0.114 | AP15: 0.115 | AQ15: 0.114 | AR15: 0.113 | AS15: 0.113 | AT15: 490
D16: 0.094 | E16: 0.086 | F16: 0.09 | G16: 0.099 | H16: 0.088 | I16: 0.09 | J16: 0.094 | K16: 0.093 | L16: 0.093 | M16: 0.089 | N16: 0.089 | O16: 0.091 | P16: 750 | AH16: 0.093 | AI16: 0.091 | AJ16: 0.093 | AK16: 0.092 | AL16: 0.088 | AM16: 0.091 | AN16: 0.09 | AO16: 0.09 | AP16: 0.09 | AQ16: 0.09 | AR16: 0.089 | AS16: 0.088 | AT16: 750
C17: H | D17: 0.116 | E17: 0.115 | F17: 0.118 | G17: 0.123 | H17: 0.129 | I17: 0.264 | J17: 0.129 | K17: 0.124 | L17: 0.126 | M17: 0.153 | N17: 0.144 | O17: 0.123 | P17: 490 | AG17: H | AH17: 0.113 | AI17: 0.115 | AJ17: 0.116 | AK17: 0.116 | AL17: 0.12 | AM17: 0.197 | AN17: 0.116 | AO17: 0.117 | AP17: 0.117 | AQ17: 0.117 | AR17: 0.112 | AS17: 0.117 | AT17: 490
D18: 0.089 | E18: 0.088 | F18: 0.089 | G18: 0.093 | H18: 0.091 | I18: 0.092 | J18: 0.095 | K18: 0.091 | L18: 0.092 | M18: 0.12 | N18: 0.114 | O18: 0.091 | P18: 750 | AH18: 0.089 | AI18: 0.089 | AJ18: 0.088 | AK18: 0.088 | AL18: 0.087 | AM18: 0.088 | AN18: 0.088 | AO18: 0.088 | AP18: 0.087 | AQ18: 0.087 | AR18: 0.086 | AS18: 0.087 | AT18: 750
A20: PM1.1 | B20: 24 | D20: 1 | E20: 2 | F20: 3 | G20: 4 | H20: 5 | I20: 6 | J20: 7 | K20: 8 | L20: 9 | M20: 10 | N20: 11 | O20: 12 | Q20: PM1.2 | R20: 24 | T20: 1 | U20: 2 | V20: 3 | W20: 4 | X20: 5 | Y20: 6 | Z20: 7 | AA20: 8 | AB20: 9 | AC20: 10 | AD20: 11 | AE20: 12
C21: A | D21: 0.164 | E21: 0.368 | F21: 0.17 | G21: 0.172 | H21: 0.186 | I21: 0.179 | J21: 0.239 | K21: 0.347 | L21: 0.228 | M21: 0.402 | N21: 0.928 | O21: 0.37 | P21: 490 | S21: A | T21: 0.166 | U21: 0.409 | V21: 0.173 | W21: 0.175 | X21: 0.182 | Y21: 0.185 | Z21: 0.242 | AA21: 0.357 | AB21: 0.256 | AC21: 0.434 | AD21: 0.9 | AE21: 0.369 | AF21: 490
D22: 0.118 | E22: 0.127 | F22: 0.123 | G22: 0.123 | H22: 0.137 | I22: 0.119 | J22: 0.175 | K22: 0.241 | L22: 0.158 | M22: 0.254 | N22: 0.527 | O22: 0.265 | P22: 750 | T22: 0.118 | U22: 0.131 | V22: 0.126 | W22: 0.125 | X22: 0.134 | Y22: 0.123 | Z22: 0.175 | AA22: 0.26 | AB22: 0.179 | AC22: 0.302 | AD22: 0.563 | AE22: 0.256 | AF22: 750
C23: B | D23: 0.168 | E23: 0.451 | F23: 0.393 | G23: 0.182 | H23: 0.197 | I23: 0.232 | J23: 0.25 | K23: 0.665 | L23: 0.256 | M23: 0.219 | N23: 0.506 | O23: 0.353 | P23: 490 | S23: B | T23: 0.168 | U23: 0.357 | V23: 0.339 | W23: 0.181 | X23: 0.198 | Y23: 0.248 | Z23: 0.268 | AA23: 0.621 | AB23: 0.267 | AC23: 0.247 | AD23: 0.427 | AE23: 0.326 | AF23: 490
D24: 0.12 | E24: 0.318 | F24: 0.281 | G24: 0.122 | H24: 0.135 | I24: 0.173 | J24: 0.192 | K24: 0.173 | L24: 0.193 | M24: 0.183 | N24: 0.341 | O24: 0.243 | P24: 750 | T24: 0.121 | U24: 0.232 | V24: 0.234 | W24: 0.122 | X24: 0.135 | Y24: 0.18 | Z24: 0.198 | AA24: 0.185 | AB24: 0.193 | AC24: 0.195 | AD24: 0.282 | AE24: 0.219 | AF24: 750
C25: C | D25: 0.17 | E25: 0.182 | F25: 0.169 | G25: 0.759 | H25: 0.188 | I25: 0.348 | J25: 0.853 | K25: 0.267 | L25: 0.939 | M25: 0.313 | N25: 0.231 | O25: 0.282 | P25: 490 | S25: C | T25: 0.167 | U25: 0.175 | V25: 0.168 | W25: 0.758 | X25: 0.188 | Y25: 0.337 | Z25: 0.899 | AA25: 0.29 | AB25: 0.898 | AC25: 0.326 | AD25: 0.23 | AE25: 0.275 | AF25: 490
D26: 0.122 | E26: 0.112 | F26: 0.122 | G26: 0.256 | H26: 0.138 | I26: 0.214 | J26: 0.508 | K26: 0.187 | L26: 0.549 | M26: 0.227 | N26: 0.168 | O26: 0.203 | P26: 750 | T26: 0.12 | U26: 0.108 | V26: 0.122 | W26: 0.245 | X26: 0.137 | Y26: 0.205 | Z26: 0.531 | AA26: 0.185 | AB26: 0.513 | AC26: 0.234 | AD26: 0.169 | AE26: 0.194 | AF26: 750
C27: D | D27: 0.174 | E27: 0.157 | F27: 0.164 | G27: 0.177 | H27: 0.196 | I27: 0.243 | J27: 0.225 | K27: 0.23 | L27: 0.216 | M27: 0.233 | N27: 0.536 | O27: 0.269 | P27: 490 | S27: D | T27: 0.166 | U27: 0.16 | V27: 0.165 | W27: 0.181 | X27: 0.203 | Y27: 0.242 | Z27: 0.238 | AA27: 0.258 | AB27: 0.236 | AC27: 0.243 | AD27: 0.465 | AE27: 0.261 | AF27: 490
D28: 0.124 | E28: 0.114 | F28: 0.118 | G28: 0.13 | H28: 0.142 | I28: 0.174 | J28: 0.166 | K28: 0.172 | L28: 0.16 | M28: 0.18 | N28: 0.355 | O28: 0.192 | P28: 750 | T28: 0.118 | U28: 0.116 | V28: 0.12 | W28: 0.133 | X28: 0.147 | Y28: 0.177 | Z28: 0.176 | AA28: 0.19 | AB28: 0.173 | AC28: 0.181 | AD28: 0.285 | AE28: 0.185 | AF28: 750
C29: E | D29: 0.277 | E29: 0.155 | F29: 0.162 | G29: 0.195 | H29: 0.184 | I29: 0.2 | J29: 0.197 | K29: 0.215 | L29: 0.282 | M29: 0.264 | N29: 0.222 | O29: 0.238 | P29: 490 | S29: E | T29: 0.232 | U29: 0.155 | V29: 0.164 | W29: 0.207 | X29: 0.175 | Y29: 0.203 | Z29: 0.212 | AA29: 0.223 | AB29: 0.296 | AC29: 0.316 | AD29: 0.224 | AE29: 0.233 | AF29: 490
D30: 0.199 | E30: 0.115 | F30: 0.119 | G30: 0.124 | H30: 0.132 | I30: 0.146 | J30: 0.144 | K30: 0.159 | L30: 0.213 | M30: 0.186 | N30: 0.166 | O30: 0.172 | P30: 750 | T30: 0.174 | U30: 0.115 | V30: 0.122 | W30: 0.132 | X30: 0.126 | Y30: 0.149 | Z30: 0.157 | AA30: 0.165 | AB30: 0.2 | AC30: 0.219 | AD30: 0.168 | AE30: 0.169 | AF30: 750
C31: F | D31: 0.159 | E31: 0.148 | F31: 0.16 | G31: 0.201 | H31: 0.168 | I31: 0.174 | J31: 0.199 | K31: 0.201 | L31: 0.179 | M31: 0.168 | N31: 0.194 | O31: 0.215 | P31: 490 | S31: F | T31: 0.155 | U31: 0.153 | V31: 0.162 | W31: 0.161 | X31: 0.165 | Y31: 0.18 | Z31: 0.177 | AA31: 0.206 | AB31: 0.185 | AC31: 0.18 | AD31: 0.198 | AE31: 0.218 | AF31: 490
D32: 0.115 | E32: 0.11 | F32: 0.118 | G32: 0.118 | H32: 0.123 | I32: 0.126 | J32: 0.14 | K32: 0.145 | L32: 0.129 | M32: 0.118 | N32: 0.143 | O32: 0.156 | P32: 750 | T32: 0.113 | U32: 0.115 | V32: 0.121 | W32: 0.118 | X32: 0.122 | Y32: 0.131 | Z32: 0.13 | AA32: 0.149 | AB32: 0.136 | AC32: 0.129 | AD32: 0.146 | AE32: 0.157 | AF32: 750
C33: G | D33: 0.161 | E33: 0.146 | F33: 0.138 | G33: 0.16 | H33: 0.164 | I33: 0.175 | J33: 0.179 | K33: 0.168 | L33: 0.177 | M33: 0.184 | N33: 0.165 | O33: 0.17 | P33: 490 | S33: G | T33: 0.16 | U33: 0.146 | V33: 0.138 | W33: 0.162 | X33: 0.171 | Y33: 0.172 | Z33: 0.175 | AA33: 0.172 | AB33: 0.183 | AC33: 0.236 | AD33: 0.166 | AE33: 0.175 | AF33: 490
D34: 0.115 | E34: 0.109 | F34: 0.099 | G34: 0.116 | H34: 0.124 | I34: 0.129 | J34: 0.131 | K34: 0.123 | L34: 0.131 | M34: 0.137 | N34: 0.121 | O34: 0.122 | P34: 750 | T34: 0.115 | U34: 0.11 | V34: 0.1 | W34: 0.117 | X34: 0.13 | Y34: 0.126 | Z34: 0.128 | AA34: 0.127 | AB34: 0.138 | AC34: 0.169 | AD34: 0.124 | AE34: 0.127 | AF34: 750
C35: H | D35: 0.159 | E35: 0.154 | F35: 0.166 | G35: 0.162 | H35: 0.295 | I35: 0.519 | J35: 0.184 | K35: 0.182 | L35: 0.177 | M35: 0.169 | N35: 0.19 | O35: 0.165 | P35: 490 | S35: H | T35: 0.157 | U35: 0.154 | V35: 0.163 | W35: 0.157 | X35: 0.303 | Y35: 0.523 | Z35: 0.18 | AA35: 0.184 | AB35: 0.179 | AC35: 0.171 | AD35: 0.183 | AE35: 0.168 | AF35: 490
D36: 0.115 | E36: 0.112 | F36: 0.118 | G36: 0.114 | H36: 0.177 | I36: 0.124 | J36: 0.097 | K36: 0.124 | L36: 0.119 | M36: 0.115 | N36: 0.124 | O36: 0.116 | P36: 750 | T36: 0.113 | U36: 0.112 | V36: 0.116 | W36: 0.11 | X36: 0.18 | Y36: 0.127 | Z36: 0.094 | AA36: 0.127 | AB36: 0.12 | AC36: 0.116 | AD36: 0.123 | AE36: 0.12 | AF36: 750
A38: PM1.1 | B38: 48 | D38: 1 | E38: 2 | F38: 3 | G38: 4 | H38: 5 | I38: 6 | J38: 7 | K38: 8 | L38: 9 | M38: 10 | N38: 11 | O38: 12 | Q38: PM1.2 | R38: 48 | T38: 1 | U38: 2 | V38: 3 | W38: 4 | X38: 5 | Y38: 6 | Z38: 7 | AA38: 8 | AB38: 9 | AC38: 10 | AD38: 11 | AE38: 12
C39: A | D39: 0.153 | E39: 0.399 | F39: 0.162 | G39: 0.161 | H39: 0.174 | I39: 0.167 | J39: 0.224 | K39: 0.503 | L39: 0.213 | M39: 0.512 | N39: 0.971 | O39: 0.541 | P39: 490 | S39: A | T39: 0.155 | U39: 0.439 | V39: 0.164 | W39: 1.18 | X39: 0.171 | Y39: 0.338 | Z39: 0.228 | AA39: 0.55 | AB39: 0.25 | AC39: 0.613 | AD39: 0.977 | AE39: 0.541 | AF39: 490
D40: 0.108 | E40: 0.127 | F40: 0.115 | G40: 0.114 | H40: 0.126 | I40: 0.104 | J40: 0.16 | K40: 0.32 | L40: 0.149 | M40: 0.344 | N40: 0.596 | O40: 0.376 | P40: 750 | T40: 0.109 | U40: 0.13 | V40: 0.116 | W40: 0.384 | X40: 0.124 | Y40: 0.168 | Z40: 0.16 | AA40: 0.343 | AB40: 0.169 | AC40: 0.392 | AD40: 0.619 | AE40: 0.381 | AF40: 750
C41: B | D41: 0.157 | E41: 0.674 | F41: 0.611 | G41: 0.174 | H41: 0.193 | I41: 0.221 | J41: 0.261 | K41: 0.871 | L41: 0.263 | M41: 0.239 | N41: 0.756 | O41: 0.356 | P41: 490 | S41: B | T41: 0.163 | U41: 0.595 | V41: 0.52 | W41: 0.177 | X41: 0.194 | Y41: 0.346 | Z41: 0.274 | AA41: 0.753 | AB41: 0.262 | AC41: 0.259 | AD41: 0.7 | AE41: 0.32 | AF41: 490
D42: 0.11 | E42: 0.414 | F42: 0.393 | G42: 0.113 | H42: 0.126 | I42: 0.159 | J42: 0.183 | K42: 0.31 | L42: 0.183 | M42: 0.182 | N42: 0.475 | O42: 0.234 | P42: 750 | T42: 0.115 | U42: 0.361 | V42: 0.328 | W42: 0.116 | X42: 0.126 | Y42: 0.202 | Z42: 0.19 | AA42: 0.22 | AB42: 0.184 | AC42: 0.196 | AD42: 0.41 | AE42: 0.215 | AF42: 750
...

Sheet Steigung
A1: PM1 | B1: t0 | C1: - | D1: t1
B2: =Rohdaten!D21-Rohdaten!D3 -> 0.036 | C2: =Rohdaten!E21-Rohdaten!E3 -> 0.183 | D2: =Rohdaten!F21-Rohdaten!F3 -> 0.053 | E2: =Rohdaten!G21-Rohdaten!G3 -> 0.052 | F2: =Rohdaten!H21-Rohdaten!H3 -> 0.067 | G2: =Rohdaten!I21-Rohdaten!I3 -> 0.061 | H2: =Rohdaten!J21-Rohdaten!J3 -> 0.121 | I2: =Rohdaten!K21-Rohdaten!K3 -> 0.229 | ... M2: =Rohdaten!O21-Rohdaten!O3 -> 0.234 | O2: =Rohdaten!T21-Rohdaten!D3 -> 0.038 | P2: =Rohdaten!U21-Rohdaten!E3 -> 0.224 | Q2: =Rohdaten!V21-Rohdaten!F3 -> 0.056 | R2: =Rohdaten!W21-Rohdaten!G3 -> 0.055 | S2: =Rohdaten!X21-Rohdaten!H3 -> 0.063 | T2: =Rohdaten!Y21-Rohdaten!I3 -> 0.067 | U2: =Rohdaten!Z21-Rohdaten!J3 -> 0.124 | V2: =Rohdaten!AA21-Rohdaten!K3 -> 0.239 | ... Z2: =Rohdaten!AE21-Rohdaten!O3 -> 0.233
B3: =Rohdaten!D22-Rohdaten!D4 -> 0.019 | C3: =Rohdaten!E22-Rohdaten!E4 -> 0.041 | D3: =Rohdaten!F22-Rohdaten!F4 -> 0.034 | E3: =Rohdaten!G22-Rohdaten!G4 -> 0.033 | F3: =Rohdaten!H22-Rohdaten!H4 -> 0.046 | G3: =Rohdaten!I22-Rohdaten!I4 -> 0.031 | H3: =Rohdaten!J22-Rohdaten!J4 -> 0.085 | I3: =Rohdaten!K22-Rohdaten!K4 -> 0.15 | ... M3: =Rohdaten!O22-Rohdaten!O4 -> 0.16 | O3: =Rohdaten!T22-Rohdaten!D4 -> 0.019 | P3: =Rohdaten!U22-Rohdaten!E4 -> 0.045 | Q3: =Rohdaten!V22-Rohdaten!F4 -> 0.037 | R3: =Rohdaten!W22-Rohdaten!G4 -> 0.035 | S3: =Rohdaten!X22-Rohdaten!H4 -> 0.043 | T3: =Rohdaten!Y22-Rohdaten!I4 -> 0.035 | U3: =Rohdaten!Z22-Rohdaten!J4 -> 0.085 | V3: =Rohdaten!AA22-Rohdaten!K4 -> 0.169 | ... Z3: =Rohdaten!AE22-Rohdaten!O4 -> 0.151
B4: =Rohdaten!D23-Rohdaten!D5 -> 0.042 | C4: =Rohdaten!E23-Rohdaten!E5 -> 0.334 | D4: =Rohdaten!F23-Rohdaten!F5 -> 0.27 | E4: =Rohdaten!G23-Rohdaten!G5 -> 0.055 | F4: =Rohdaten!H23-Rohdaten!H5 -> 0.068 | G4: =Rohdaten!I23-Rohdaten!I5 -> 0.111 | H4: =Rohdaten!J23-Rohdaten!J5 -> 0.129 | I4: =Rohdaten!K23-Rohdaten!K5 -> 0.453 | ... M4: =Rohdaten!O23-Rohdaten!O5 -> 0.228 | O4: =Rohdaten!T23-Rohdaten!D5 -> 0.042 | P4: =Rohdaten!U23-Rohdaten!E5 -> 0.24 | Q4: =Rohdaten!V23-Rohdaten!F5 -> 0.216 | R4: =Rohdaten!W23-Rohdaten!G5 -> 0.054 | S4: =Rohdaten!X23-Rohdaten!H5 -> 0.069 | T4: =Rohdaten!Y23-Rohdaten!I5 -> 0.127 | U4: =Rohdaten!Z23-Rohdaten!J5 -> 0.147 | V4: =Rohdaten!AA23-Rohdaten!K5 -> 0.409 | ... Z4: =Rohdaten!AE23-Rohdaten!O5 -> 0.201
B5: =Rohdaten!D24-Rohdaten!D6 -> 0.024 | C5: =Rohdaten!E24-Rohdaten!E6 -> 0.227 | D5: =Rohdaten!F24-Rohdaten!F6 -> 0.188 | E5: =Rohdaten!G24-Rohdaten!G6 -> 0.027 | F5: =Rohdaten!H24-Rohdaten!H6 -> 0.043 | G5: =Rohdaten!I24-Rohdaten!I6 -> 0.081 | H5: =Rohdaten!J24-Rohdaten!J6 -> 0.099 | I5: =Rohdaten!K24-Rohdaten!K6 -> 0.08 | ... M5: =Rohdaten!O24-Rohdaten!O6 -> 0.148 | O5: =Rohdaten!T24-Rohdaten!D6 -> 0.025 | P5: =Rohdaten!U24-Rohdaten!E6 -> 0.141 | Q5: =Rohdaten!V24-Rohdaten!F6 -> 0.141 | R5: =Rohdaten!W24-Rohdaten!G6 -> 0.027 | S5: =Rohdaten!X24-Rohdaten!H6 -> 0.043 | T5: =Rohdaten!Y24-Rohdaten!I6 -> 0.088 | U5: =Rohdaten!Z24-Rohdaten!J6 -> 0.105 | V5: =Rohdaten!AA24-Rohdaten!K6 -> 0.092 | ... Z5: =Rohdaten!AE24-Rohdaten!O6 -> 0.124
B6: =Rohdaten!D25-Rohdaten!D7 -> 0.044 | C6: =Rohdaten!E25-Rohdaten!E7 -> 0.057 | D6: =Rohdaten!F25-Rohdaten!F7 -> 0.047 | E6: =Rohdaten!G25-Rohdaten!G7 -> 0.502 | F6: =Rohdaten!H25-Rohdaten!H7 -> 0.067 | G6: =Rohdaten!I25-Rohdaten!I7 -> 0.22 | H6: =Rohdaten!J25-Rohdaten!J7 -> 0.731 | I6: =Rohdaten!K25-Rohdaten!K7 -> 0.142 | ... M6: =Rohdaten!O25-Rohdaten!O7 -> 0.154 | O6: =Rohdaten!T25-Rohdaten!D7 -> 0.041 | P6: =Rohdaten!U25-Rohdaten!E7 -> 0.05 | Q6: =Rohdaten!V25-Rohdaten!F7 -> 0.046 | R6: =Rohdaten!W25-Rohdaten!G7 -> 0.501 | S6: =Rohdaten!X25-Rohdaten!H7 -> 0.067 | T6: =Rohdaten!Y25-Rohdaten!I7 -> 0.209 | U6: =Rohdaten!Z25-Rohdaten!J7 -> 0.777 | V6: =Rohdaten!AA25-Rohdaten!K7 -> 0.165 | ... Z6: =Rohdaten!AE25-Rohdaten!O7 -> 0.147
B7: =Rohdaten!D26-Rohdaten!D8 -> 0.027 | C7: =Rohdaten!E26-Rohdaten!E8 -> 0.024 | D7: =Rohdaten!F26-Rohdaten!F8 -> 0.029 | E7: =Rohdaten!G26-Rohdaten!G8 -> 0.161 | F7: =Rohdaten!H26-Rohdaten!H8 -> 0.046 | G7: =Rohdaten!I26-Rohdaten!I8 -> 0.119 | H7: =Rohdaten!J26-Rohdaten!J8 -> 0.417 | I7: =Rohdaten!K26-Rohdaten!K8 -> 0.092 | ... M7: =Rohdaten!O26-Rohdaten!O8 -> 0.104 | O7: =Rohdaten!T26-Rohdaten!D8 -> 0.025 | P7: =Rohdaten!U26-Rohdaten!E8 -> 0.02 | Q7: =Rohdaten!V26-Rohdaten!F8 -> 0.029 | R7: =Rohdaten!W26-Rohdaten!G8 -> 0.15 | S7: =Rohdaten!X26-Rohdaten!H8 -> 0.045 | T7: =Rohdaten!Y26-Rohdaten!I8 -> 0.11 | U7: =Rohdaten!Z26-Rohdaten!J8 -> 0.44 | V7: =Rohdaten!AA26-Rohdaten!K8 -> 0.09 | ... Z7: =Rohdaten!AE26-Rohdaten!O8 -> 0.095
B8: =Rohdaten!D27-Rohdaten!D9 -> 0.048 | C8: =Rohdaten!E27-Rohdaten!E9 -> 0.041 | D8: =Rohdaten!F27-Rohdaten!F9 -> 0.042 | E8: =Rohdaten!G27-Rohdaten!G9 -> 0.052 | F8: =Rohdaten!H27-Rohdaten!H9 -> 0.074 | G8: =Rohdaten!I27-Rohdaten!I9 -> 0.113 | H8: =Rohdaten!J27-Rohdaten!J9 -> 0.1 | I8: =Rohdaten!K27-Rohdaten!K9 -> 0.109 | ... M8: =Rohdaten!O27-Rohdaten!O9 -> 0.145 | O8: =Rohdaten!T27-Rohdaten!D9 -> 0.04 | P8: =Rohdaten!U27-Rohdaten!E9 -> 0.044 | Q8: =Rohdaten!V27-Rohdaten!F9 -> 0.043 | R8: =Rohdaten!W27-Rohdaten!G9 -> 0.056 | S8: =Rohdaten!X27-Rohdaten!H9 -> 0.081 | T8: =Rohdaten!Y27-Rohdaten!I9 -> 0.112 | U8: =Rohdaten!Z27-Rohdaten!J9 -> 0.113 | V8: =Rohdaten!AA27-Rohdaten!K9 -> 0.137 | ... Z8: =Rohdaten!AE27-Rohdaten!O9 -> 0.137
B9: =Rohdaten!D28-Rohdaten!D10 -> 0.028 | C9: =Rohdaten!E28-Rohdaten!E10 -> 0.025 | D9: =Rohdaten!F28-Rohdaten!F10 -> 0.025 | E9: =Rohdaten!G28-Rohdaten!G10 -> 0.033 | F9: =Rohdaten!H28-Rohdaten!H10 -> 0.051 | G9: =Rohdaten!I28-Rohdaten!I10 -> 0.076 | H9: =Rohdaten!J28-Rohdaten!J10 -> 0.072 | I9: =Rohdaten!K28-Rohdaten!K10 -> 0.082 | ... M9: =Rohdaten!O28-Rohdaten!O10 -> 0.099 | O9: =Rohdaten!T28-Rohdaten!D10 -> 0.022 | P9: =Rohdaten!U28-Rohdaten!E10 -> 0.027 | Q9: =Rohdaten!V28-Rohdaten!F10 -> 0.027 | R9: =Rohdaten!W28-Rohdaten!G10 -> 0.036 | S9: =Rohdaten!X28-Rohdaten!H10 -> 0.056 | T9: =Rohdaten!Y28-Rohdaten!I10 -> 0.079 | U9: =Rohdaten!Z28-Rohdaten!J10 -> 0.082 | V9: =Rohdaten!AA28-Rohdaten!K10 -> 0.1 | ... Z9: =Rohdaten!AE28-Rohdaten!O10 -> 0.092
B10: =Rohdaten!D29-Rohdaten!D11 -> 0.156 | C10: =Rohdaten!E29-Rohdaten!E11 -> 0.045 | D10: =Rohdaten!F29-Rohdaten!F11 -> 0.044 | E10: =Rohdaten!G29-Rohdaten!G11 -> 0.064 | F10: =Rohdaten!H29-Rohdaten!H11 -> 0.067 | G10: =Rohdaten!I29-Rohdaten!I11 -> 0.079 | H10: =Rohdaten!J29-Rohdaten!J11 -> 0.073 | I10: =Rohdaten!K29-Rohdaten!K11 -> 0.095 | ... M10: =Rohdaten!O29-Rohdaten!O11 -> 0.114 | O10: =Rohdaten!T29-Rohdaten!D11 -> 0.111 | P10: =Rohdaten!U29-Rohdaten!E11 -> 0.045 | Q10: =Rohdaten!V29-Rohdaten!F11 -> 0.046 | R10: =Rohdaten!W29-Rohdaten!G11 -> 0.076 | S10: =Rohdaten!X29-Rohdaten!H11 -> 0.058 | T10: =Rohdaten!Y29-Rohdaten!I11 -> 0.082 | U10: =Rohdaten!Z29-Rohdaten!J11 -> 0.088 | V10: =Rohdaten!AA29-Rohdaten!K11 -> 0.103 | ... Z10: =Rohdaten!AE29-Rohdaten!O11 -> 0.109
B11: =Rohdaten!D30-Rohdaten!D12 -> 0.106 | C11: =Rohdaten!E30-Rohdaten!E12 -> 0.028 | D11: =Rohdaten!F30-Rohdaten!F12 -> 0.026 | E11: =Rohdaten!G30-Rohdaten!G12 -> 0.031 | F11: =Rohdaten!H30-Rohdaten!H12 -> 0.043 | G11: =Rohdaten!I30-Rohdaten!I12 -> 0.054 | H11: =Rohdaten!J30-Rohdaten!J12 -> 0.05 | I11: =Rohdaten!K30-Rohdaten!K12 -> 0.068 | ... M11: =Rohdaten!O30-Rohdaten!O12 -> 0.078 | O11: =Rohdaten!T30-Rohdaten!D12 -> 0.081 | P11: =Rohdaten!U30-Rohdaten!E12 -> 0.028 | Q11: =Rohdaten!V30-Rohdaten!F12 -> 0.029 | R11: =Rohdaten!W30-Rohdaten!G12 -> 0.039 | S11: =Rohdaten!X30-Rohdaten!H12 -> 0.037 | T11: =Rohdaten!Y30-Rohdaten!I12 -> 0.057 | U11: =Rohdaten!Z30-Rohdaten!J12 -> 0.063 | V11: =Rohdaten!AA30-Rohdaten!K12 -> 0.074 | ... Z11: =Rohdaten!AE30-Rohdaten!O12 -> 0.075
B12: =Rohdaten!D31-Rohdaten!D13 -> 0.034 | C12: =Rohdaten!E31-Rohdaten!E13 -> 0.038 | D12: =Rohdaten!F31-Rohdaten!F13 -> 0.038 | E12: =Rohdaten!G31-Rohdaten!G13 -> 0.084 | F12: =Rohdaten!H31-Rohdaten!H13 -> 0.048 | G12: =Rohdaten!I31-Rohdaten!I13 -> 0.052 | H12: =Rohdaten!J31-Rohdaten!J13 -> 0.078 | I12: =Rohdaten!K31-Rohdaten!K13 -> 0.076 | ... M12: =Rohdaten!O31-Rohdaten!O13 -> 0.094 | O12: =Rohdaten!T31-Rohdaten!D13 -> 0.03 | P12: =Rohdaten!U31-Rohdaten!E13 -> 0.043 | Q12: =Rohdaten!V31-Rohdaten!F13 -> 0.04 | R12: =Rohdaten!W31-Rohdaten!G13 -> 0.044 | S12: =Rohdaten!X31-Rohdaten!H13 -> 0.045 | T12: =Rohdaten!Y31-Rohdaten!I13 -> 0.058 | U12: =Rohdaten!Z31-Rohdaten!J13 -> 0.056 | V12: =Rohdaten!AA31-Rohdaten!K13 -> 0.081 | ... Z12: =Rohdaten!AE31-Rohdaten!O13 -> 0.097
B13: =Rohdaten!D32-Rohdaten!D14 -> 0.018 | C13: =Rohdaten!E32-Rohdaten!E14 -> 0.023 | D13: =Rohdaten!F32-Rohdaten!F14 -> 0.022 | E13: =Rohdaten!G32-Rohdaten!G14 -> 0.027 | F13: =Rohdaten!H32-Rohdaten!H14 -> 0.031 | G13: =Rohdaten!I32-Rohdaten!I14 -> 0.033 | H13: =Rohdaten!J32-Rohdaten!J14 -> 0.049 | I13: =Rohdaten!K32-Rohdaten!K14 -> 0.051 | ... M13: =Rohdaten!O32-Rohdaten!O14 -> 0.065 | O13: =Rohdaten!T32-Rohdaten!D14 -> 0.016 | P13: =Rohdaten!U32-Rohdaten!E14 -> 0.028 | Q13: =Rohdaten!V32-Rohdaten!F14 -> 0.025 | R13: =Rohdaten!W32-Rohdaten!G14 -> 0.027 | S13: =Rohdaten!X32-Rohdaten!H14 -> 0.03 | T13: =Rohdaten!Y32-Rohdaten!I14 -> 0.038 | U13: =Rohdaten!Z32-Rohdaten!J14 -> 0.039 | V13: =Rohdaten!AA32-Rohdaten!K14 -> 0.055 | ... Z13: =Rohdaten!AE32-Rohdaten!O14 -> 0.066
... B17: =Rohdaten!D36-Rohdaten!D18 -> 0.026 | C17: =Rohdaten!E36-Rohdaten!E18 -> 0.024 | D17: =Rohdaten!F36-Rohdaten!F18 -> 0.029 | E17: =Rohdaten!G36-Rohdaten!G18 -> 0.021 | F17: =Rohdaten!H36-Rohdaten!H18 -> 0.086 | G17: =Rohdaten!I36-Rohdaten!I18 -> 0.032 | H17: =Rohdaten!J36-Rohdaten!J18 -> 0.002 | I17: =Rohdaten!K36-Rohdaten!K18 -> 0.033 | ... M17: =Rohdaten!O36-Rohdaten!O18 -> 0.025 | O17: =Rohdaten!T36-Rohdaten!D18 -> 0.024 | P17: =Rohdaten!U36-Rohdaten!E18 -> 0.024 | Q17: =Rohdaten!V36-Rohdaten!F18 -> 0.027 | R17: =Rohdaten!W36-Rohdaten!G18 -> 0.017 | S17: =Rohdaten!X36-Rohdaten!H18 -> 0.089 | T17: =Rohdaten!Y36-Rohdaten!I18 -> 0.035 | U17: =Rohdaten!Z36-Rohdaten!J18 -> -0.001 | V17: =Rohdaten!AA36-Rohdaten!K18 -> 0.036 | ... Z17: =Rohdaten!AE36-Rohdaten!O18 -> 0.029
B19: t1 | C19: - | D19: t2
B20: =Rohdaten!D39-Rohdaten!D21 -> -0.011 | C20: =Rohdaten!E39-Rohdaten!E21 -> 0.031 | D20: =Rohdaten!F39-Rohdaten!F21 -> -0.008 | E20: =Rohdaten!G39-Rohdaten!G21 -> -0.011 | F20: =Rohdaten!H39-Rohdaten!H21 -> -0.012 | G20: =Rohdaten!I39-Rohdaten!I21 -> -0.012 | H20: =Rohdaten!J39-Rohdaten!J21 -> -0.015 | I20: =Rohdaten!K39-Rohdaten!K21 -> 0.156 | ... M20: =Rohdaten!O39-Rohdaten!O21 -> 0.171 | O20: =Rohdaten!T39-Rohdaten!T21 -> -0.011 | P20: =Rohdaten!U39-Rohdaten!U21 -> 0.03 | Q20: =Rohdaten!V39-Rohdaten!V21 -> -0.009 | R20: =Rohdaten!W39-Rohdaten!W21 -> 1.005 | S20: =Rohdaten!X39-Rohdaten!X21 -> -0.011 | T20: =Rohdaten!Y39-Rohdaten!Y21 -> 0.153 | U20: =Rohdaten!Z39-Rohdaten!Z21 -> -0.014 | V20: =Rohdaten!AA39-Rohdaten!AA21 -> 0.193 | ... Z20: =Rohdaten!AE39-Rohdaten!AE21 -> 0.172
B21: =Rohdaten!D40-Rohdaten!D22 -> -0.01 | C21: =Rohdaten!E40-Rohdaten!E22 -> 0 | D21: =Rohdaten!F40-Rohdaten!F22 -> -0.008 | E21: =Rohdaten!G40-Rohdaten!G22 -> -0.009 | F21: =Rohdaten!H40-Rohdaten!H22 -> -0.011 | G21: =Rohdaten!I40-Rohdaten!I22 -> -0.015 | H21: =Rohdaten!J40-Rohdaten!J22 -> -0.015 | I21: =Rohdaten!K40-Rohdaten!K22 -> 0.079 | ... M21: =Rohdaten!O40-Rohdaten!O22 -> 0.111 | O21: =Rohdaten!T40-Rohdaten!T22 -> -0.009 | P21: =Rohdaten!U40-Rohdaten!U22 -> -0.001 | Q21: =Rohdaten!V40-Rohdaten!V22 -> -0.01 | R21: =Rohdaten!W40-Rohdaten!W22 -> 0.259 | S21: =Rohdaten!X40-Rohdaten!X22 -> -0.01 | T21: =Rohdaten!Y40-Rohdaten!Y22 -> 0.045 | U21: =Rohdaten!Z40-Rohdaten!Z22 -> -0.015 | V21: =Rohdaten!AA40-Rohdaten!AA22 -> 0.083 | ... Z21: =Rohdaten!AE40-Rohdaten!AE22 -> 0.125
B22: =Rohdaten!D41-Rohdaten!D23 -> -0.011 | C22: =Rohdaten!E41-Rohdaten!E23 -> 0.223 | D22: =Rohdaten!F41-Rohdaten!F23 -> 0.218 | E22: =Rohdaten!G41-Rohdaten!G23 -> -0.008 | F22: =Rohdaten!H41-Rohdaten!H23 -> -0.004 | G22: =Rohdaten!I41-Rohdaten!I23 -> -0.011 | H22: =Rohdaten!J41-Rohdaten!J23 -> 0.011 | I22: =Rohdaten!K41-Rohdaten!K23 -> 0.206 | ... M22: =Rohdaten!O41-Rohdaten!O23 -> 0.003 | O22: =Rohdaten!T41-Rohdaten!T23 -> -0.005 | P22: =Rohdaten!U41-Rohdaten!U23 -> 0.238 | Q22: =Rohdaten!V41-Rohdaten!V23 -> 0.181 | R22: =Rohdaten!W41-Rohdaten!W23 -> -0.004 | S22: =Rohdaten!X41-Rohdaten!X23 -> -0.004 | T22: =Rohdaten!Y41-Rohdaten!Y23 -> 0.098 | U22: =Rohdaten!Z41-Rohdaten!Z23 -> 0.006 | V22: =Rohdaten!AA41-Rohdaten!AA23 -> 0.132 | ... Z22: =Rohdaten!AE41-Rohdaten!AE23 -> -0.006
B23: =Rohdaten!D42-Rohdaten!D24 -> -0.01 | C23: =Rohdaten!E42-Rohdaten!E24 -> 0.096 | D23: =Rohdaten!F42-Rohdaten!F24 -> 0.112 | E23: =Rohdaten!G42-Rohdaten!G24 -> -0.009 | F23: =Rohdaten!H42-Rohdaten!H24 -> -0.009 | G23: =Rohdaten!I42-Rohdaten!I24 -> -0.014 | H23: =Rohdaten!J42-Rohdaten!J24 -> -0.009 | I23: =Rohdaten!K42-Rohdaten!K24 -> 0.137 | ... M23: =Rohdaten!O42-Rohdaten!O24 -> -0.009 | O23: =Rohdaten!T42-Rohdaten!T24 -> -0.006 | P23: =Rohdaten!U42-Rohdaten!U24 -> 0.129 | Q23: =Rohdaten!V42-Rohdaten!V24 -> 0.094 | R23: =Rohdaten!W42-Rohdaten!W24 -> -0.006 | S23: =Rohdaten!X42-Rohdaten!X24 -> -0.009 | T23: =Rohdaten!Y42-Rohdaten!Y24 -> 0.022 | U23: =Rohdaten!Z42-Rohdaten!Z24 -> -0.008 | V23: =Rohdaten!AA42-Rohdaten!AA24 -> 0.035 | ... Z23: =Rohdaten!AE42-Rohdaten!AE24 -> -0.004
B24: =Rohdaten!D43-Rohdaten!D25 -> -0.009 | C24: =Rohdaten!E43-Rohdaten!E25 -> -0.003 | D24: =Rohdaten!F43-Rohdaten!F25 -> -0.009 | E24: =Rohdaten!G43-Rohdaten!G25 -> 0.137 | F24: =Rohdaten!H43-Rohdaten!H25 -> -0.006 | G24: =Rohdaten!I43-Rohdaten!I25 -> 0.03 | H24: =Rohdaten!J43-Rohdaten!J25 -> 0.139 | I24: =Rohdaten!K43-Rohdaten!K25 -> 0.284 | ... M24: =Rohdaten!O43-Rohdaten!O25 -> -0.021 | O24: =Rohdaten!T43-Rohdaten!T25 -> 0.05 | P24: =Rohdaten!U43-Rohdaten!U25 -> 0 | Q24: =Rohdaten!V43-Rohdaten!V25 -> -0.007 | R24: =Rohdaten!W43-Rohdaten!W25 -> 0.134 | S24: =Rohdaten!X43-Rohdaten!X25 -> -0.005 | T24: =Rohdaten!Y43-Rohdaten!Y25 -> 0.023 | U24: =Rohdaten!Z43-Rohdaten!Z25 -> 0.095 | V24: =Rohdaten!AA43-Rohdaten!AA25 -> 0.274 | ... Z24: =Rohdaten!AE43-Rohdaten!AE25 -> -0.013
B25: =Rohdaten!D44-Rohdaten!D26 -> -0.009 | C25: =Rohdaten!E44-Rohdaten!E26 -> -0.008 | D25: =Rohdaten!F44-Rohdaten!F26 -> -0.009 | E25: =Rohdaten!G44-Rohdaten!G26 -> 0.06 | F25: =Rohdaten!H44-Rohdaten!H26 -> -0.008 | G25: =Rohdaten!I44-Rohdaten!I26 -> 0.01 | H25: =Rohdaten!J44-Rohdaten!J26 -> 0.084 | I25: =Rohdaten!K44-Rohdaten!K26 -> 0.077 | ... M25: =Rohdaten!O44-Rohdaten!O26 -> -0.022 | O25: =Rohdaten!T44-Rohdaten!T26 -> 0.006 | P25: =Rohdaten!U44-Rohdaten!U26 -> -0.006 | Q25: =Rohdaten!V44-Rohdaten!V26 -> -0.008 | R25: =Rohdaten!W44-Rohdaten!W26 -> 0.06 | S25: =Rohdaten!X44-Rohdaten!X26 -> -0.007 | T25: =Rohdaten!Y44-Rohdaten!Y26 -> 0.009 | U25: =Rohdaten!Z44-Rohdaten!Z26 -> 0.064 | V25: =Rohdaten!AA44-Rohdaten!AA26 -> 0.078 | ... Z25: =Rohdaten!AE44-Rohdaten!AE26 -> -0.012
B26: =Rohdaten!D45-Rohdaten!D27 -> 1.144 | C26: =Rohdaten!E45-Rohdaten!E27 -> -0.008 | D26: =Rohdaten!F45-Rohdaten!F27 -> -0.009 | E26: =Rohdaten!G45-Rohdaten!G27 -> 0.028 | F26: =Rohdaten!H45-Rohdaten!H27 -> 0.014 | G26: =Rohdaten!I45-Rohdaten!I27 -> -0.007 | H26: =Rohdaten!J45-Rohdaten!J27 -> -0.006 | I26: =Rohdaten!K45-Rohdaten!K27 -> 0.004 | ... M26: =Rohdaten!O45-Rohdaten!O27 -> 0.01 | O26: =Rohdaten!T45-Rohdaten!T27 -> 0.774 | P26: =Rohdaten!U45-Rohdaten!U27 -> -0.005 | Q26: =Rohdaten!V45-Rohdaten!V27 -> -0.005 | R26: =Rohdaten!W45-Rohdaten!W27 -> -0.007 | S26: =Rohdaten!X45-Rohdaten!X27 -> -0.001 | T26: =Rohdaten!Y45-Rohdaten!Y27 -> -0.006 | U26: =Rohdaten!Z45-Rohdaten!Z27 -> -0.006 | V26: =Rohdaten!AA45-Rohdaten!AA27 -> -0.005 | ... Z26: =Rohdaten!AE45-Rohdaten!AE27 -> -0.015
B27: =Rohdaten!D46-Rohdaten!D28 -> 0.304 | C27: =Rohdaten!E46-Rohdaten!E28 -> -0.008 | D27: =Rohdaten!F46-Rohdaten!F28 -> -0.009 | E27: =Rohdaten!G46-Rohdaten!G28 -> 0.006 | F27: =Rohdaten!H46-Rohdaten!H28 -> 0 | G27: =Rohdaten!I46-Rohdaten!I28 -> -0.012 | H27: =Rohdaten!J46-Rohdaten!J28 -> -0.01 | I27: =Rohdaten!K46-Rohdaten!K28 -> -0.006 | ... M27: =Rohdaten!O46-Rohdaten!O28 -> -0.01 | O27: =Rohdaten!T46-Rohdaten!T28 -> 0.152 | P27: =Rohdaten!U46-Rohdaten!U28 -> -0.005 | Q27: =Rohdaten!V46-Rohdaten!V28 -> -0.007 | R27: =Rohdaten!W46-Rohdaten!W28 -> -0.006 | S27: =Rohdaten!X46-Rohdaten!X28 -> -0.002 | T27: =Rohdaten!Y46-Rohdaten!Y28 -> -0.014 | U27: =Rohdaten!Z46-Rohdaten!Z28 -> -0.012 | V27: =Rohdaten!AA46-Rohdaten!AA28 -> -0.012 | ... Z27: =Rohdaten!AE46-Rohdaten!AE28 -> -0.014
B28: =Rohdaten!D47-Rohdaten!D29 -> 1.465 | C28: =Rohdaten!E47-Rohdaten!E29 -> -0.008 | D28: =Rohdaten!F47-Rohdaten!F29 -> -0.008 | E28: =Rohdaten!G47-Rohdaten!G29 -> 0 | F28: =Rohdaten!H47-Rohdaten!H29 -> -0.005 | G28: =Rohdaten!I47-Rohdaten!I29 -> -0.011 | H28: =Rohdaten!J47-Rohdaten!J29 -> -0.009 | I28: =Rohdaten!K47-Rohdaten!K29 -> -0.009 | ... M28: =Rohdaten!O47-Rohdaten!O29 -> -0.017 | O28: =Rohdaten!T47-Rohdaten!T29 -> 1.287 | P28: =Rohdaten!U47-Rohdaten!U29 -> -0.006 | Q28: =Rohdaten!V47-Rohdaten!V29 -> 0.034 | R28: =Rohdaten!W47-Rohdaten!W29 -> -0.002 | S28: =Rohdaten!X47-Rohdaten!X29 -> 0.002 | T28: =Rohdaten!Y47-Rohdaten!Y29 -> -0.006 | U28: =Rohdaten!Z47-Rohdaten!Z29 -> -0.001 | V28: =Rohdaten!AA47-Rohdaten!AA29 -> -0.007 | ... Z28: =Rohdaten!AE47-Rohdaten!AE29 -> -0.009
B29: =Rohdaten!D48-Rohdaten!D30 -> 0.471 | C29: =Rohdaten!E48-Rohdaten!E30 -> -0.008 | D29: =Rohdaten!F48-Rohdaten!F30 -> -0.008 | E29: =Rohdaten!G48-Rohdaten!G30 -> -0.007 | F29: =Rohdaten!H48-Rohdaten!H30 -> -0.006 | G29: =Rohdaten!I48-Rohdaten!I30 -> -0.011 | H29: =Rohdaten!J48-Rohdaten!J30 -> -0.01 | I29: =Rohdaten!K48-Rohdaten!K30 -> -0.009 | ... M29: =Rohdaten!O48-Rohdaten!O30 -> -0.017 | O29: =Rohdaten!T48-Rohdaten!T30 -> 0.403 | P29: =Rohdaten!U48-Rohdaten!U30 -> -0.006 | Q29: =Rohdaten!V48-Rohdaten!V30 -> 0.009 | R29: =Rohdaten!W48-Rohdaten!W30 -> -0.008 | S29: =Rohdaten!X48-Rohdaten!X30 -> 0 | T29: =Rohdaten!Y48-Rohdaten!Y30 -> -0.008 | U29: =Rohdaten!Z48-Rohdaten!Z30 -> -0.007 | V29: =Rohdaten!AA48-Rohdaten!AA30 -> -0.009 | ... Z29: =Rohdaten!AE48-Rohdaten!AE30 -> -0.011
B30: =Rohdaten!D49-Rohdaten!D31 -> -0.011 | C30: =Rohdaten!E49-Rohdaten!E31 -> -0.007 | D30: =Rohdaten!F49-Rohdaten!F31 -> -0.009 | E30: =Rohdaten!G49-Rohdaten!G31 -> -0.046 | F30: =Rohdaten!H49-Rohdaten!H31 -> -0.009 | G30: =Rohdaten!I49-Rohdaten!I31 -> 0.358 | H30: =Rohdaten!J49-Rohdaten!J31 -> 0.031 | I30: =Rohdaten!K49-Rohdaten!K31 -> -0.012 | ... M30: =Rohdaten!O49-Rohdaten!O31 -> 0.104 | O30: =Rohdaten!T49-Rohdaten!T31 -> -0.009 | P30: =Rohdaten!U49-Rohdaten!U31 -> -0.006 | Q30: =Rohdaten!V49-Rohdaten!V31 -> -0.006 | R30: =Rohdaten!W49-Rohdaten!W31 -> -0.005 | S30: =Rohdaten!X49-Rohdaten!X31 -> -0.005 | T30: =Rohdaten!Y49-Rohdaten!Y31 -> -0.006 | U30: =Rohdaten!Z49-Rohdaten!Z31 -> -0.007 | V30: =Rohdaten!AA49-Rohdaten!AA31 -> -0.009 | ... Z30: =Rohdaten!AE49-Rohdaten!AE31 -> 0.106
B31: =Rohdaten!D50-Rohdaten!D32 -> -0.01 | C31: =Rohdaten!E50-Rohdaten!E32 -> -0.007 | D31: =Rohdaten!F50-Rohdaten!F32 -> -0.008 | E31: =Rohdaten!G50-Rohdaten!G32 -> -0.007 | F31: =Rohdaten!H50-Rohdaten!H32 -> -0.008 | G31: =Rohdaten!I50-Rohdaten!I32 -> 0.117 | H31: =Rohdaten!J50-Rohdaten!J32 -> -0.011 | I31: =Rohdaten!K50-Rohdaten!K32 -> -0.012 | ... M31: =Rohdaten!O50-Rohdaten!O32 -> 0.07 | O31: =Rohdaten!T50-Rohdaten!T32 -> -0.009 | P31: =Rohdaten!U50-Rohdaten!U32 -> -0.006 | Q31: =Rohdaten!V50-Rohdaten!V32 -> -0.006 | R31: =Rohdaten!W50-Rohdaten!W32 -> -0.006 | S31: =Rohdaten!X50-Rohdaten!X32 -> -0.006 | T31: =Rohdaten!Y50-Rohdaten!Y32 -> -0.007 | U31: =Rohdaten!Z50-Rohdaten!Z32 -> -0.009 | V31: =Rohdaten!AA50-Rohdaten!AA32 -> -0.01 | ... Z31: =Rohdaten!AE50-Rohdaten!AE32 -> 0.072
... B35: =Rohdaten!D54-Rohdaten!D36 -> 0.026 | C35: =Rohdaten!E54-Rohdaten!E36 -> -0.007 | D35: =Rohdaten!F54-Rohdaten!F36 -> -0.008 | E35: =Rohdaten!G54-Rohdaten!G36 -> -0.007 | F35: =Rohdaten!H54-Rohdaten!H36 -> -0.011 | G35: =Rohdaten!I54-Rohdaten!I36 -> 0.001 | H35: =Rohdaten!J54-Rohdaten!J36 -> -0.005 | I35: =Rohdaten!K54-Rohdaten!K36 -> 0.035 | ... M35: =Rohdaten!O54-Rohdaten!O36 -> -0.006 | O35: =Rohdaten!T54-Rohdaten!T36 -> -0.008 | P35: =Rohdaten!U54-Rohdaten!U36 -> -0.008 | Q35: =Rohdaten!V54-Rohdaten!V36 -> 0.002 | R35: =Rohdaten!W54-Rohdaten!W36 -> -0.005 | S35: =Rohdaten!X54-Rohdaten!X36 -> -0.01 | T35: =Rohdaten!Y54-Rohdaten!Y36 -> 0.001 | U35: =Rohdaten!Z54-Rohdaten!Z36 -> -0.005 | V35: =Rohdaten!AA54-Rohdaten!AA36 -> -0.008 | ... Z35: =Rohdaten!AE54-Rohdaten!AE36 -> -0.013
B37: t2 | C37: - | D37: t3
B38: =Rohdaten!D57-Rohdaten!D39 -> -0.001 | C38: =Rohdaten!E57-Rohdaten!E39 -> 0.002 | D38: =Rohdaten!F57-Rohdaten!F39 -> -0.003 | E38: =Rohdaten!G57-Rohdaten!G39 -> -0.001 | F38: =Rohdaten!H57-Rohdaten!H39 -> 0 | G38: =Rohdaten!I57-Rohdaten!I39 -> -0.001 | H38: =Rohdaten!J57-Rohdaten!J39 -> -0.003 | I38: =Rohdaten!K57-Rohdaten!K39 -> 0.03 | ... M38: =Rohdaten!O57-Rohdaten!O39 -> 0.025 | O38: =Rohdaten!T57-Rohdaten!T39 -> -0.002 | P38: =Rohdaten!U57-Rohdaten!U39 -> 0.003 | Q38: =Rohdaten!V57-Rohdaten!V39 -> -0.003 | R38: =Rohdaten!W57-Rohdaten!W39 -> 0.111 | S38: =Rohdaten!X57-Rohdaten!X39 -> -0.002 | T38: =Rohdaten!Y57-Rohdaten!Y39 -> 0.267 | U38: =Rohdaten!Z57-Rohdaten!Z39 -> -0.003 | V38: =Rohdaten!AA57-Rohdaten!AA39 -> 0.02 | ... Z38: =Rohdaten!AE57-Rohdaten!AE39 -> 0.028
B39: =Rohdaten!D58-Rohdaten!D40 -> -0.002 | C39: =Rohdaten!E58-Rohdaten!E40 -> -0.001 | D39: =Rohdaten!F58-Rohdaten!F40 -> -0.002 | E39: =Rohdaten!G58-Rohdaten!G40 -> -0.002 | F39: =Rohdaten!H58-Rohdaten!H40 -> -0.001 | G39: =Rohdaten!I58-Rohdaten!I40 -> -0.001 | H39: =Rohdaten!J58-Rohdaten!J40 -> -0.003 | I39: =Rohdaten!K58-Rohdaten!K40 -> 0.019 | ... M39: =Rohdaten!O58-Rohdaten!O40 -> 0.02 | O39: =Rohdaten!T58-Rohdaten!T40 -> -0.002 | P39: =Rohdaten!U58-Rohdaten!U40 -> -0.001 | Q39: =Rohdaten!V58-Rohdaten!V40 -> -0.001 | R39: =Rohdaten!W58-Rohdaten!W40 -> 0.025 | S39: =Rohdaten!X58-Rohdaten!X40 -> -0.002 | T39: =Rohdaten!Y58-Rohdaten!Y40 -> 0.089 | U39: =Rohdaten!Z58-Rohdaten!Z40 -> -0.003 | V39: =Rohdaten!AA58-Rohdaten!AA40 -> 0.021 | ... Z39: =Rohdaten!AE58-Rohdaten!AE40 -> 0.022
B40: =Rohdaten!D59-Rohdaten!D41 -> -0.001 | C40: =Rohdaten!E59-Rohdaten!E41 -> 0.029 | D40: =Rohdaten!F59-Rohdaten!F41 -> 0.05 | E40: =Rohdaten!G59-Rohdaten!G41 -> 0 | F40: =Rohdaten!H59-Rohdaten!H41 -> -0.001 | G40: =Rohdaten!I59-Rohdaten!I41 -> -0.004 | H40: =Rohdaten!J59-Rohdaten!J41 -> -0.002 | I40: =Rohdaten!K59-Rohdaten!K41 -> 0.14 | ... M40: =Rohdaten!O59-Rohdaten!O41 -> 0.006 | O40: =Rohdaten!T59-Rohdaten!T41 -> -0.002 | P40: =Rohdaten!U59-Rohdaten!U41 -> 0.034 | Q40: =Rohdaten!V59-Rohdaten!V41 -> 0.023 | R40: =Rohdaten!W59-Rohdaten!W41 -> 0.002 | S40: =Rohdaten!X59-Rohdaten!X41 -> -0.001 | T40: =Rohdaten!Y59-Rohdaten!Y41 -> 0.083 | U40: =Rohdaten!Z59-Rohdaten!Z41 -> -0.003 | V40: =Rohdaten!AA59-Rohdaten!AA41 -> 0.033 | ... Z40: =Rohdaten!AE59-Rohdaten!AE41 -> 0
B41: =Rohdaten!D60-Rohdaten!D42 -> -0.001 | C41: =Rohdaten!E60-Rohdaten!E42 -> 0.019 | D41: =Rohdaten!F60-Rohdaten!F42 -> 0.03 | E41: =Rohdaten!G60-Rohdaten!G42 -> -0.001 | F41: =Rohdaten!H60-Rohdaten!H42 -> -0.001 | G41: =Rohdaten!I60-Rohdaten!I42 -> -0.004 | H41: =Rohdaten!J60-Rohdaten!J42 -> -0.001 | I41: =Rohdaten!K60-Rohdaten!K42 -> 0.06 | ... M41: =Rohdaten!O60-Rohdaten!O42 -> 0.002 | O41: =Rohdaten!T60-Rohdaten!T42 -> -0.002 | P41: =Rohdaten!U60-Rohdaten!U42 -> 0.023 | Q41: =Rohdaten!V60-Rohdaten!V42 -> 0.008 | R41: =Rohdaten!W60-Rohdaten!W42 -> 0.002 | S41: =Rohdaten!X60-Rohdaten!X42 -> -0.001 | T41: =Rohdaten!Y60-Rohdaten!Y42 -> 0.016 | U41: =Rohdaten!Z60-Rohdaten!Z42 -> -0.003 | V41: =Rohdaten!AA60-Rohdaten!AA42 -> 0.01 | ... Z41: =Rohdaten!AE60-Rohdaten!AE42 -> -0.002
B42: =Rohdaten!D61-Rohdaten!D43 -> -0.002 | C42: =Rohdaten!E61-Rohdaten!E43 -> 0 | D42: =Rohdaten!F61-Rohdaten!F43 -> -0.001 | E42: =Rohdaten!G61-Rohdaten!G43 -> 0.012 | F42: =Rohdaten!H61-Rohdaten!H43 -> -0.001 | G42: =Rohdaten!I61-Rohdaten!I43 -> 0.004 | H42: =Rohdaten!J61-Rohdaten!J43 -> 0.005 | I42: =Rohdaten!K61-Rohdaten!K43 -> 0.074 | ... M42: =Rohdaten!O61-Rohdaten!O43 -> -0.005 | O42: =Rohdaten!T61-Rohdaten!T43 -> 0.069 | P42: =Rohdaten!U61-Rohdaten!U43 -> 0 | Q42: =Rohdaten!V61-Rohdaten!V43 -> -0.002 | R42: =Rohdaten!W61-Rohdaten!W43 -> 0.007 | S42: =Rohdaten!X61-Rohdaten!X43 -> -0.002 | T42: =Rohdaten!Y61-Rohdaten!Y43 -> 0.003 | U42: =Rohdaten!Z61-Rohdaten!Z43 -> 0.011 | V42: =Rohdaten!AA61-Rohdaten!AA43 -> 0.026 | ... Z42: =Rohdaten!AE61-Rohdaten!AE43 -> -0.004
B43: =Rohdaten!D62-Rohdaten!D44 -> -0.003 | C43: =Rohdaten!E62-Rohdaten!E44 -> 0 | D43: =Rohdaten!F62-Rohdaten!F44 -> -0.001 | E43: =Rohdaten!G62-Rohdaten!G44 -> 0.004 | F43: =Rohdaten!H62-Rohdaten!H44 -> -0.001 | G43: =Rohdaten!I62-Rohdaten!I44 -> 0.001 | H43: =Rohdaten!J62-Rohdaten!J44 -> 0.003 | I43: =Rohdaten!K62-Rohdaten!K44 -> 0.026 | ... M43: =Rohdaten!O62-Rohdaten!O44 -> -0.003 | O43: =Rohdaten!T62-Rohdaten!T44 -> 0.022 | P43: =Rohdaten!U62-Rohdaten!U44 -> -0.001 | Q43: =Rohdaten!V62-Rohdaten!V44 -> -0.001 | R43: =Rohdaten!W62-Rohdaten!W44 -> -0.001 | S43: =Rohdaten!X62-Rohdaten!X44 -> -0.001 | T43: =Rohdaten!Y62-Rohdaten!Y44 -> 0 | U43: =Rohdaten!Z62-Rohdaten!Z44 -> 0.005 | V43: =Rohdaten!AA62-Rohdaten!AA44 -> -0.009 | ... Z43: =Rohdaten!AE62-Rohdaten!AE44 -> -0.003
B44: =Rohdaten!D63-Rohdaten!D45 -> -0.067 | C44: =Rohdaten!E63-Rohdaten!E45 -> -0.001 | D44: =Rohdaten!F63-Rohdaten!F45 -> -0.001 | E44: =Rohdaten!G63-Rohdaten!G45 -> 0.018 | F44: =Rohdaten!H63-Rohdaten!H45 -> 0.027 | G44: =Rohdaten!I63-Rohdaten!I45 -> -0.001 | H44: =Rohdaten!J63-Rohdaten!J45 -> -0.002 | I44: =Rohdaten!K63-Rohdaten!K45 -> 0.001 | ... M44: =Rohdaten!O63-Rohdaten!O45 -> 0.019 | O44: =Rohdaten!T63-Rohdaten!T45 -> 0.46 | P44: =Rohdaten!U63-Rohdaten!U45 -> -0.002 | Q44: =Rohdaten!V63-Rohdaten!V45 -> -0.002 | R44: =Rohdaten!W63-Rohdaten!W45 -> -0.002 | S44: =Rohdaten!X63-Rohdaten!X45 -> 0 | T44: =Rohdaten!Y63-Rohdaten!Y45 -> -0.001 | U44: =Rohdaten!Z63-Rohdaten!Z45 -> -0.002 | V44: =Rohdaten!AA63-Rohdaten!AA45 -> -0.002 | ... Z44: =Rohdaten!AE63-Rohdaten!AE45 -> -0.004
B45: =Rohdaten!D64-Rohdaten!D46 -> -0.034 | C45: =Rohdaten!E64-Rohdaten!E46 -> -0.001 | D45: =Rohdaten!F64-Rohdaten!F46 -> -0.001 | E45: =Rohdaten!G64-Rohdaten!G46 -> 0.006 | F45: =Rohdaten!H64-Rohdaten!H46 -> 0.006 | G45: =Rohdaten!I64-Rohdaten!I46 -> -0.002 | H45: =Rohdaten!J64-Rohdaten!J46 -> -0.002 | I45: =Rohdaten!K64-Rohdaten!K46 -> 0 | ... M45: =Rohdaten!O64-Rohdaten!O46 -> 0.004 | O45: =Rohdaten!T64-Rohdaten!T46 -> 0.182 | P45: =Rohdaten!U64-Rohdaten!U46 -> -0.002 | Q45: =Rohdaten!V64-Rohdaten!V46 -> -0.001 | R45: =Rohdaten!W64-Rohdaten!W46 -> -0.003 | S45: =Rohdaten!X64-Rohdaten!X46 -> -0.001 | T45: =Rohdaten!Y64-Rohdaten!Y46 -> -0.002 | U45: =Rohdaten!Z64-Rohdaten!Z46 -> -0.002 | V45: =Rohdaten!AA64-Rohdaten!AA46 -> -0.003 | ... Z45: =Rohdaten!AE64-Rohdaten!AE46 -> -0.004
B46: =Rohdaten!D65-Rohdaten!D47 -> 0.008 | C46: =Rohdaten!E65-Rohdaten!E47 -> -0.001 | D46: =Rohdaten!F65-Rohdaten!F47 -> 0 | E46: =Rohdaten!G65-Rohdaten!G47 -> -0.001 | F46: =Rohdaten!H65-Rohdaten!H47 -> 0.001 | G46: =Rohdaten!I65-Rohdaten!I47 -> -0.001 | H46: =Rohdaten!J65-Rohdaten!J47 -> -0.002 | I46: =Rohdaten!K65-Rohdaten!K47 -> -0.001 | ... M46: =Rohdaten!O65-Rohdaten!O47 -> -0.002 | O46: =Rohdaten!T65-Rohdaten!T47 -> 0.084 | P46: =Rohdaten!U65-Rohdaten!U47 -> -0.002 | Q46: =Rohdaten!V65-Rohdaten!V47 -> 0.042 | R46: =Rohdaten!W65-Rohdaten!W47 -> 0.001 | S46: =Rohdaten!X65-Rohdaten!X47 -> -0.002 | T46: =Rohdaten!Y65-Rohdaten!Y47 -> 0.005 | U46: =Rohdaten!Z65-Rohdaten!Z47 -> 0.021 | V46: =Rohdaten!AA65-Rohdaten!AA47 -> -0.003 | ... Z46: =Rohdaten!AE65-Rohdaten!AE47 -> -0.003
B47: =Rohdaten!D66-Rohdaten!D48 -> 0.008 | C47: =Rohdaten!E66-Rohdaten!E48 -> -0.001 | D47: =Rohdaten!F66-Rohdaten!F48 -> 0 | E47: =Rohdaten!G66-Rohdaten!G48 -> -0.001 | F47: =Rohdaten!H66-Rohdaten!H48 -> 0.001 | G47: =Rohdaten!I66-Rohdaten!I48 -> -0.001 | H47: =Rohdaten!J66-Rohdaten!J48 -> -0.001 | I47: =Rohdaten!K66-Rohdaten!K48 -> -0.002 | ... M47: =Rohdaten!O66-Rohdaten!O48 -> 0.001 | O47: =Rohdaten!T66-Rohdaten!T48 -> 0.054 | P47: =Rohdaten!U66-Rohdaten!U48 -> -0.003 | Q47: =Rohdaten!V66-Rohdaten!V48 -> 0.013 | R47: =Rohdaten!W66-Rohdaten!W48 -> 0 | S47: =Rohdaten!X66-Rohdaten!X48 -> -0.002 | T47: =Rohdaten!Y66-Rohdaten!Y48 -> 0.005 | U47: =Rohdaten!Z66-Rohdaten!Z48 -> 0.014 | V47: =Rohdaten!AA66-Rohdaten!AA48 -> -0.003 | ... Z47: =Rohdaten!AE66-Rohdaten!AE48 -> -0.003
B48: =Rohdaten!D67-Rohdaten!D49 -> -0.001 | C48: =Rohdaten!E67-Rohdaten!E49 -> 0 | D48: =Rohdaten!F67-Rohdaten!F49 -> 0 | E48: =Rohdaten!G67-Rohdaten!G49 -> 0.002 | F48: =Rohdaten!H67-Rohdaten!H49 -> -0.001 | G48: =Rohdaten!I67-Rohdaten!I49 -> 0.181 | H48: =Rohdaten!J67-Rohdaten!J49 -> 0.008 | I48: =Rohdaten!K67-Rohdaten!K49 -> -0.001 | ... M48: =Rohdaten!O67-Rohdaten!O49 -> 0.01 | O48: =Rohdaten!T67-Rohdaten!T49 -> -0.002 | P48: =Rohdaten!U67-Rohdaten!U49 -> -0.001 | Q48: =Rohdaten!V67-Rohdaten!V49 -> -0.001 | R48: =Rohdaten!W67-Rohdaten!W49 -> -0.002 | S48: =Rohdaten!X67-Rohdaten!X49 -> -0.002 | T48: =Rohdaten!Y67-Rohdaten!Y49 -> -0.002 | U48: =Rohdaten!Z67-Rohdaten!Z49 -> -0.002 | V48: =Rohdaten!AA67-Rohdaten!AA49 -> 0.001 | ... Z48: =Rohdaten!AE67-Rohdaten!AE49 -> 0.008
...

Sheet Wachstum
B1: 1 | C1: 2 | D1: 3 | E1: 4 | F1: 5 | G1: 6 | H1: 7 | I1: 8 | J1: 9 | K1: 10 | L1: 11 | M1: 12 | O1: PM1.2 | P1: 72 | R1: 1 | S1: 2 | T1: 3 | U1: 4 | V1: 5 | W1: 6 | X1: 7 | Y1: 8 | Z1: 9 | AA1: 10 | AB1: 11 | AC1: 12
A2: A | B2: 0.145 | C2: 0.415 | D2: 0.153 | E2: 0.154 | F2: 0.167 | G2: 0.163 | H2: 0.212 | I2: 0.601 | J2: 0.203 | K2: 0.644 | L2: 0.971 | M2: 0.452 | N2: 490 | Q2: A | R2: 0.145 | S2: 0.459 | T2: 0.155 | U2: 1.193 | V2: 0.162 | W2: 1.265 | X2: 0.215 | Y2: 0.59 | Z2: 0.235 | AA2: 0.701 | AB2: 0.96 | AC2: 0.234 | AD2: 490
B3: 0.1 | C3: 0.124 | D3: 0.107 | E3: 0.106 | F3: 0.118 | G3: 0.098 | H3: 0.148 | I3: 0.377 | J3: 0.139 | K3: 0.436 | L3: 0.593 | M3: 0.334 | N3: 750 | R3: 0.1 | S3: 0.127 | T3: 0.108 | U3: 0.337 | V3: 0.115 | W3: 0.465 | X3: 0.148 | Y3: 0.375 | Z3: 0.157 | AA3: 0.44 | AB3: 0.606 | AC3: 0.197 | AD3: 750
A4: B | B4: 0.15 | C4: 0.766 | D4: 0.723 | E4: 0.174 | F4: 0.19 | G4: 0.21 | H4: 0.253 | I4: 1.107 | J4: 0.259 | K4: 0.232 | L4: 0.903 | M4: 0.77 | N4: 490 | Q4: B | R4: 0.151 | S4: 0.716 | T4: 0.591 | U4: 0.178 | V4: 0.192 | W4: 1.303 | X4: 0.264 | Y4: 0.882 | Z4: 0.255 | AA4: 0.246 | AB4: 0.834 | AC4: 0.313 | AD4: 490
B5: 0.102 | C5: 0.476 | D5: 0.46 | E5: 0.109 | F5: 0.119 | G5: 0.148 | H5: 0.174 | I5: 0.431 | J5: 0.175 | K5: 0.169 | L5: 0.569 | M5: 0.318 | N5: 750 | R5: 0.104 | S5: 0.443 | T5: 0.36 | U5: 0.114 | V5: 0.119 | W5: 0.445 | X5: 0.178 | Y5: 0.288 | Z5: 0.174 | AA5: 0.18 | AB5: 0.507 | AC5: 0.206 | AD5: 750
A6: C | B6: 0.154 | C6: 0.179 | D6: 0.154 | E6: 0.958 | F6: 0.178 | G6: 0.393 | H6: 1.02 | I6: 0.641 | J6: 1.051 | K6: 0.702 | L6: 0.224 | M6: 0.24 | N6: 490 | Q6: C | R6: 0.25 | S6: 0.175 | T6: 0.154 | U6: 0.942 | V6: 0.178 | W6: 0.373 | X6: 1.164 | Y6: 0.608 | Z6: 1.021 | AA6: 0.705 | AB6: 0.224 | AC6: 0.24 | AD6: 490
B7: 0.103 | C7: 0.099 | D7: 0.107 | E7: 0.34 | F7: 0.125 | G7: 0.226 | H7: 0.612 | I7: 0.282 | J7: 0.6 | K7: 0.461 | L7: 0.15 | M7: 0.164 | N7: 750 | R7: 0.133 | S7: 0.097 | T7: 0.108 | U7: 0.315 | V7: 0.126 | W7: 0.216 | X7: 0.633 | Y7: 0.242 | Z7: 0.598 | AA7: 0.464 | AB7: 0.151 | AC7: 0.164 | AD7: 750
A8: D | B8: 1.119 | C8: 0.144 | D8: 0.15 | E8: 0.186 | F8: 0.74 | G8: 0.234 | H8: 0.213 | I8: 0.233 | J8: 0.202 | K8: 0.233 | L8: 0.887 | M8: 0.273 | N8: 490 | Q8: D | R8: 0.961 | S8: 0.148 | T8: 0.154 | U8: 0.166 | V8: 0.198 | W8: 0.235 | X8: 0.223 | Y8: 0.249 | Z8: 0.228 | AA8: 0.232 | AB8: 0.8 | AC8: 0.224 | AD8: 490
B9: 0.343 | C9: 0.101 | D9: 0.104 | E9: 0.125 | F9: 0.25 | G9: 0.153 | H9: 0.149 | I9: 0.161 | J9: 0.141 | K9: 0.16 | L9: 0.545 | M9: 0.174 | N9: 750 | R9: 0.285 | S9: 0.104 | T9: 0.108 | U9: 0.119 | V9: 0.14 | W9: 0.154 | X9: 0.155 | Y9: 0.17 | Z9: 0.156 | AA9: 0.16 | AB9: 0.468 | AC9: 0.153 | AD9: 750
A10: E | B10: 1.523 | C10: 0.142 | D10: 0.15 | E10: 0.198 | F10: 0.177 | G10: 0.189 | H10: 0.182 | I10: 0.201 | J10: 0.679 | K10: 0.258 | L10: 0.201 | M10: 0.218 | N10: 490 | Q10: E | R10: 1.569 | S10: 0.142 | T10: 0.205 | U10: 0.208 | V10: 0.171 | W10: 0.196 | X10: 0.226 | Y10: 0.207 | Z10: 0.61 | AA10: 0.303 | AB10: 0.204 | AC10: 0.214 | AD10: 490
B11: 0.529 | C11: 0.101 | D11: 0.106 | E11: 0.113 | F11: 0.123 | G11: 0.133 | H11: 0.128 | I11: 0.143 | J11: 0.39 | K11: 0.175 | L11: 0.145 | M11: 0.152 | N11: 750 | R11: 0.676 | S11: 0.102 | T11: 0.128 | U11: 0.119 | V11: 0.119 | W11: 0.139 | X11: 0.151 | Y11: 0.147 | Z11: 0.328 | AA11: 0.201 | AB11: 0.147 | AC11: 0.148 | AD11: 750
A12: F | B12: 0.141 | C12: 0.137 | D12: 0.146 | E12: 0.153 | F12: 0.153 | G12: 0.971 | H12: 0.233 | I12: 0.184 | J12: 0.161 | K12: 0.17 | L12: 0.179 | M12: 0.355 | N12: 490 | Q12: F | R12: 0.139 | S12: 0.141 | T12: 0.15 | U12: 0.151 | V12: 0.153 | W12: 0.167 | X12: 0.164 | Y12: 0.235 | Z12: 0.17 | AA12: 0.182 | AB12: 0.182 | AC12: 0.358 | AD12: 490
B13: 0.097 | C13: 0.098 | D13: 0.105 | E13: 0.108 | F13: 0.109 | G13: 0.296 | H13: 0.126 | I13: 0.127 | J13: 0.11 | K13: 0.106 | L13: 0.126 | M13: 0.247 | N13: 750 | R13: 0.096 | S13: 0.102 | T13: 0.108 | U13: 0.108 | V13: 0.109 | W13: 0.117 | X13: 0.115 | Y13: 0.141 | Z13: 0.118 | AA13: 0.115 | AB13: 0.13 | AC13: 0.248 | AD13: 750
A14: G | B14: 0.144 | C14: 0.134 | D14: 0.131 | E14: 0.145 | F14: 1.209 | G14: 0.16 | H14: 0.309 | I14: 0.245 | J14: 0.169 | K14: 0.179 | L14: 0.157 | M14: 1.078 | N14: 490 | Q14: G | R14: 1.4 | S14: 0.135 | T14: 0.131 | U14: 0.148 | V14: 0.19 | W14: 0.163 | X14: 0.166 | Y14: 0.16 | Z14: 0.175 | AA14: 0.223 | AB14: 0.154 | AC14: 0.155 | AD14: 490
B15: 0.099 | C15: 0.097 | D15: 0.092 | E15: 0.102 | F15: 0.394 | G15: 0.113 | H15: 0.123 | I15: 0.144 | J15: 0.122 | K15: 0.129 | L15: 0.111 | M15: 0.271 | N15: 750 | R15: 0.429 | S15: 0.099 | T15: 0.092 | U15: 0.104 | V15: 0.14 | W15: 0.117 | X15: 0.111 | Y15: 0.113 | Z15: 0.127 | AA15: 0.156 | AB15: 0.109 | AC15: 0.107 | AD15: 750
A16: H | B16: 0.283 | C16: 0.372 | D16: 0.151 | E16: 0.151 | F16: 0.281 | G16: 0.614 | H16: 0.202 | I16: 1.155 | J16: 1.192 | K16: 0.162 | L16: 0.191 | M16: 0.151 | N16: 490 | Q16: H | R16: 0.141 | S16: 0.14 | T16: 0.216 | U16: 0.219 | V16: 0.288 | W16: 0.618 | X16: 0.199 | Y16: 0.177 | Z16: 0.168 | AA16: 1.247 | AB16: 0.177 | AC16: 0.148 | AD16: 490
B17: 0.156 | C17: 0.199 | D17: 0.103 | E17: 0.102 | F17: 0.157 | G17: 0.123 | H17: 0.089 | I17: 0.325 | J17: 0.362 | K17: 0.103 | L17: 0.123 | M17: 0.103 | N17: 750 | R17: 0.098 | S17: 0.098 | T17: 0.127 | U17: 0.121 | V17: 0.16 | W17: 0.125 | X17: 0.085 | Y17: 0.11 | Z17: 0.105 | AA17: 0.411 | AB17: 0.118 | AC17: 0.101 | AD17: 750
A19: biotic | B19: t0 | C19: PM1.1
B20: 1 | C20: 2 | D20: 3 | E20: 4 | F20: 5 | G20: 6 | H20: 7 | I20: 8 | J20: 9 | K20: 10 | L20: 11 | M20: 12
A21: A | B21: 0.128 | C21: 0.185 | D21: 0.117 | E21: 0.12 | F21: 0.119 | G21: 0.118 | H21: 0.118 | I21: 0.118 | J21: 0.167 | K21: 0.119 | L21: 0.121 | M21: 0.136 | N21: 490
B22: 0.099 | C22: 0.086 | D22: 0.089 | E22: 0.09 | F22: 0.091 | G22: 0.088 | H22: 0.09 | I22: 0.091 | J22: 0.138 | K22: 0.091 | L22: 0.093 | M22: 0.105 | N22: 750
A23: B | B23: 0.126 | C23: 0.117 | D23: 0.123 | E23: 0.127 | F23: 0.129 | G23: 0.121 | H23: 0.121 | I23: 0.212 | J23: 0.124 | K23: 0.126 | L23: 0.12 | M23: 0.125 | N23: 490
B24: 0.096 | C24: 0.091 | D24: 0.093 | E24: 0.095 | F24: 0.092 | G24: 0.092 | H24: 0.093 | I24: 0.093 | J24: 0.095 | K24: 0.096 | L24: 0.09 | M24: 0.095 | N24: 750
A25: C | B25: 0.126 | C25: 0.125 | D25: 0.122 | E25: 0.257 | F25: 0.121 | G25: 0.128 | H25: 0.122 | I25: 0.125 | J25: 0.155 | K25: 0.118 | L25: 0.117 | M25: 0.128 | N25: 490
B26: 0.095 | C26: 0.088 | D26: 0.093 | E26: 0.095 | F26: 0.092 | G26: 0.095 | H26: 0.091 | I26: 0.095 | J26: 0.125 | K26: 0.09 | L26: 0.09 | M26: 0.099 | N26: 750
A27: D | B27: 0.126 | C27: 0.116 | D27: 0.122 | E27: 0.125 | F27: 0.122 | G27: 0.13 | H27: 0.125 | I27: 0.121 | J27: 0.124 | K27: 0.124 | L27: 0.123 | M27: 0.124 | N27: 490
B28: 0.096 | C28: 0.089 | D28: 0.093 | E28: 0.097 | F28: 0.091 | G28: 0.098 | H28: 0.094 | I28: 0.09 | J28: 0.092 | K28: 0.095 | L28: 0.095 | M28: 0.093 | N28: 750
A29: E | B29: 0.121 | C29: 0.11 | D29: 0.118 | E29: 0.131 | F29: 0.117 | G29: 0.121 | H29: 0.124 | I29: 0.12 | J29: 0.12 | K29: 0.117 | L29: 0.115 | M29: 0.124 | N29: 490
B30: 0.093 | C30: 0.087 | D30: 0.093 | E30: 0.093 | F30: 0.089 | G30: 0.092 | H30: 0.094 | I30: 0.091 | J30: 0.09 | K30: 0.089 | L30: 0.09 | M30: 0.094 | N30: 750
A31: F | B31: 0.125 | C31: 0.11 | D31: 0.122 | E31: 0.117 | F31: 0.12 | G31: 0.122 | H31: 0.121 | I31: 0.125 | J31: 0.126 | K31: 0.117 | L31: 0.116 | M31: 0.121 | N31: 490
B32: 0.097 | C32: 0.087 | D32: 0.096 | E32: 0.091 | F32: 0.092 | G32: 0.093 | H32: 0.091 | I32: 0.094 | J32: 0.095 | K32: 0.089 | L32: 0.089 | M32: 0.091 | N32: 750
A33: G | B33: 0.122 | C33: 0.108 | D33: 0.114 | E33: 0.126 | F33: 0.112 | G33: 0.118 | H33: 0.125 | I33: 0.12 | J33: 0.121 | K33: 0.116 | L33: 0.116 | M33: 0.119 | N33: 490
B34: 0.094 | C34: 0.086 | D34: 0.09 | E34: 0.099 | F34: 0.088 | G34: 0.09 | H34: 0.094 | I34: 0.093 | J34: 0.093 | K34: 0.089 | L34: 0.089 | M34: 0.091 | N34: 750
A35: H | B35: 0.116 | C35: 0.115 | D35: 0.118 | E35: 0.123 | F35: 0.129 | G35: 0.264 | H35: 0.129 | I35: 0.124 | J35: 0.126 | K35: 0.153 | L35: 0.144 | M35: 0.123 | N35: 490
B36: 0.089 | C36: 0.088 | D36: 0.089 | E36: 0.093 | F36: 0.091 | G36: 0.092 | H36: 0.095 | I36: 0.091 | J36: 0.092 | K36: 0.12 | L36: 0.114 | M36: 0.091 | N36: 750
A38: Ergebnisse
A39: PM1.1 | B39: 1 | C39: 2 | D39: 3 | E39: 4 | F39: 5 | G39: 6 | H39: 7 | I39: 8 | J39: 9 | K39: 10 | L39: 11 | M39: 12 | O39: PM1.2 | P39: 1 | Q39: 2 | R39: 3 | S39: 4 | T39: 5 | U39: 6 | V39: 7 | W39: 8 | X39: 9 | Y39: 10 | Z39: 11 | AA39: 12
A40: A | B40: =B2-B21 -> 0.017 | C40: =C2-C21 -> 0.23 | D40: =D2-D21 -> 0.036 | E40: =E2-E21 -> 0.034 | F40: =F2-F21 -> 0.048 | G40: =G2-G21 -> 0.045 | H40: =H2-H21 -> 0.094 | I40: =I2-I21 -> 0.483 | ... M40: =M2-M21 -> 0.316 | P40: =R2-B21 -> 0.017 | Q40: =S2-C21 -> 0.274 | R40: =T2-D21 -> 0.038 | S40: =U2-E21 -> 1.073 | T40: =V2-F21 -> 0.043 | U40: =W2-G21 -> 1.147 | V40: =X2-H21 -> 0.097 | W40: =Y2-I21 -> 0.472 | ... AA40: =AC2-M21 -> 0.098 | AB40: A
B41: =B3-B22 -> 0.001 | C41: =C3-C22 -> 0.038 | D41: =D3-D22 -> 0.018 | E41: =E3-E22 -> 0.016 | F41: =F3-F22 -> 0.027 | G41: =G3-G22 -> 0.01 | H41: =H3-H22 -> 0.058 | I41: =I3-I22 -> 0.286 | ... M41: =M3-M22 -> 0.229 | P41: =R3-B22 -> 0.001 | Q41: =S3-C22 -> 0.041 | R41: =T3-D22 -> 0.019 | S41: =U3-E22 -> 0.247 | T41: =V3-F22 -> 0.024 | U41: =W3-G22 -> 0.377 | V41: =X3-H22 -> 0.058 | W41: =Y3-I22 -> 0.284 | ... AA41: =AC3-M22 -> 0.092
A42: B | B42: =B4-B23 -> 0.024 | C42: =C4-C23 -> 0.649 | D42: =D4-D23 -> 0.6 | E42: =E4-E23 -> 0.047 | F42: =F4-F23 -> 0.061 | G42: =G4-G23 -> 0.089 | H42: =H4-H23 -> 0.132 | I42: =I4-I23 -> 0.895 | ... M42: =M4-M23 -> 0.645 | P42: =R4-B23 -> 0.025 | Q42: =S4-C23 -> 0.599 | R42: =T4-D23 -> 0.468 | S42: =U4-E23 -> 0.051 | T42: =V4-F23 -> 0.063 | U42: =W4-G23 -> 1.182 | V42: =X4-H23 -> 0.143 | W42: =Y4-I23 -> 0.67 | ... AA42: =AC4-M23 -> 0.188 | AB42: B
...
