Workbook

Sheet Proteome Amino Acid Composition
A1: Based on FASTA File Proteome Sequences PENDANT/ Helmholtz Munich | B1: Total amount of AA: | D1: 4000178 | N1: GAM: | O1: Protein | P1: DNA | Q1: RNA | R1: Total
A2: Amino Acid Full Name | B2: Amino Acids 1-Letter Code: | C2: Absolute Amount: | D2: Relative Amount i.e. Molar Percentage (mol/mol): | E2: Molecular Weight (g/mol): | F2: Molecular Weight - 1 Water Molecule during polymerization (18.0153 g/mol) | G2: Weight of AA per mole Protein (g AA/mol Protein) | H2: Weight of AA per weight of Protein (g AA/g Protein) | I2: mmol AA / g DW | J2: g AA / g DW | N2: mmol Protein per g DW: | O2: =SUM(I3:I22) -> 2.768864 | P2: 0.0095847008 | Q2: 0.30696051
A3: Alanine | B3: A | C3: 422758 | D3: =(C3)/($D$1) -> 0.1056848 | E3: 89.1 | F3: =(E3)-18.0153 -> 71.0847 | G3: =(D3)*(F3) -> 7.5125721 | H3: =(G3)*1/($G$23) -> 0.068924091 | I3: =((H3)*('Elemental Equation'!$E$2)*1000)/(F3) -> 0.29262683 | J3: =((H3)*('Elemental Equation'!$E$2)) -> 0.020801291 | N3: wt % | O3: ='Elemental Equation'!B2 -> 0.3018 | P3: ='Elemental Equation'!B3 -> 0.003 | Q3: ='Elemental Equation'!B4 -> 0.1
A4: Arginine | B4: R | C4: 255293 | D4: =(C4)/($D$1) -> 0.06382041 | E4: 174.2 | F4: =(E4)-18.0153 -> 156.1847 | G4: =(D4)*(F4) -> 9.9677716 | H4: =(G4)*1/($G$23) -> 0.091449318 | I4: =((H4)*('Elemental Equation'!$E$2)*1000)/(F4) -> 0.17671004 | J4: =((H4)*('Elemental Equation'!$E$2)) -> 0.027599404 | N4: Cp = mmol -P/mmol (Proteine) | O4: 4.324 | P4: 1.365 | Q4: 0.406
A5: Asparagine | B5: N | C5: 134463 | D5: =(C5)/($D$1) -> 0.033614254 | E5: 132.1 | F5: =(E5)-18.0153 -> 114.0847 | G5: =(D5)*(F5) -> 3.8348721 | H5: =(G5)*1/($G$23) -> 0.035183033 | I5: =((H5)*('Elemental Equation'!$E$2)*1000)/(F5) -> 0.093073299 | J5: =((H5)*('Elemental Equation'!$E$2)) -> 0.010618239 | N5: Result (mmol -P/g DW) | O5: =((O2)*(O4)) -> 11.972568 | P5: =((P2)*(P4)) -> 0.013083117 | Q5: =((Q2)*(Q4)) -> 0.12462597 | R5: =SUM(O5:Q5) -> 12.110277
A6: Aspartic Acid | B6: D | C6: 232095 | D6: =(C6)/($D$1) -> 0.058021168 | E6: 133.1 | F6: =(E6)-18.0153 -> 115.0847 | G6: =(D6)*(F6) -> 6.6773487 | H6: =(G6)*1/($G$23) -> 0.061261334 | I6: =((H6)*('Elemental Equation'!$E$2)*1000)/(F6) -> 0.16065272 | J6: =((H6)*('Elemental Equation'!$E$2)) -> 0.018488671 | N6: Growth-associated maintenance: Hydrolysis of 11,97257 mmol ATP/g DW
A7: Cystein | B7: C | C7: 42755 | D7: =(C7)/($D$1) -> 0.010688274 | E7: 121.3 | F7: =(E7)-18.0153 -> 103.2847 | G7: =(D7)*(F7) -> 1.1039352 | H7: =(G7)*1/($G$23) -> 0.010128053 | I7: =((H7)*('Elemental Equation'!$E$2)*1000)/(F7) -> 0.029594378 | J7: =((H7)*('Elemental Equation'!$E$2)) -> 0.0030566465 | M7: Weight of Water per mole Protein | N7: Weight of Water per weight of Protein | P7: mmol H2O / g DW per Proteinsynthesis
A8: Glutamine | B8: Q | C8: 177738 | D8: =(C8)/($D$1) -> 0.044432523 | E8: 147.1 | F8: =(E8)-18.0153 -> 129.0847 | G8: =(D8)*(F8) -> 5.7355589 | H8: =(G8)*1/($G$23) -> 0.052620883 | I8: =((H8)*('Elemental Equation'!$E$2)*1000)/(F8) -> 0.12302761 | J8: =((H8)*('Elemental Equation'!$E$2)) -> 0.015880983 | M8: =19*18.0153 -> 342.2907 | N8: =(M8)*1/($G$23) -> 3.1403459 | P8: =((N8)*('Elemental Equation'!$E$2)*1000)/18.0153 -> 52.608416
A9: Glutamic Acid | B9: E | C9: 213967 | D9: =(C9)/($D$1) -> 0.05348937 | E9: 146.2 | F9: =(E9)-18.0153 -> 128.1847 | G9: =(D9)*(F9) -> 6.8565188 | H9: =(G9)*1/($G$23) -> 0.06290513 | I9: =((H9)*('Elemental Equation'!$E$2)*1000)/(F9) -> 0.14810479 | J9: =((H9)*('Elemental Equation'!$E$2)) -> 0.018984768
A10: Glycine | B10: G | C10: 257703 | D10: =(C10)/($D$1) -> 0.064422883 | E10: 75.1 | F10: =(E10)-18.0153 -> 57.0847 | G10: =(D10)*(F10) -> 3.677561 | H10: =(G10)*1/($G$23) -> 0.033739782 | I10: =((H10)*('Elemental Equation'!$E$2)*1000)/(F10) -> 0.1783782 | J10: =((H10)*('Elemental Equation'!$E$2)) -> 0.010182666
A11: Histidine | B11: H | C11: 105129 | D11: =(C11)/($D$1) -> 0.02628108 | E11: 155.2 | F11: =(E11)-18.0153 -> 137.1847 | G11: =(D11)*(F11) -> 3.6053621 | H11: =(G11)*1/($G$23) -> 0.033077394 | I11: =((H11)*('Elemental Equation'!$E$2)*1000)/(F11) -> 0.072768738 | J11: =((H11)*('Elemental Equation'!$E$2)) -> 0.0099827575
A12: Isoleucine | B12: I | C12: 166207 | D12: =(C12)/($D$1) -> 0.041549901 | E12: 131.2 | F12: =(E12)-18.0153 -> 113.1847 | G12: =(D12)*(F12) -> 4.7028131 | H12: =(G12)*1/($G$23) -> 0.043145957 | I12: =((H12)*('Elemental Equation'!$E$2)*1000)/(F12) -> 0.11504603 | J12: =((H12)*('Elemental Equation'!$E$2)) -> 0.01302145
A13: Leucine | B13: L | C13: 358325 | D13: =(C13)/($D$1) -> 0.089577264 | E13: 131.2 | F13: =(E13)-18.0153 -> 113.1847 | G13: =(D13)*(F13) -> 10.138776 | H13: =(G13)*1/($G$23) -> 0.093018195 | I13: =((H13)*('Elemental Equation'!$E$2)*1000)/(F13) -> 0.24802726 | J13: =((H13)*('Elemental Equation'!$E$2)) -> 0.028072891
A14: Lysine | B14: K | C14: 176258 | D14: =(C14)/($D$1) -> 0.044062539 | E14: 146.2 | F14: =(E14)-18.0153 -> 128.1847 | G14: =(D14)*(F14) -> 5.6481434 | H14: =(G14)*1/($G$23) -> 0.05181889 | I14: =((H14)*('Elemental Equation'!$E$2)*1000)/(F14) -> 0.12200318 | J14: =((H14)*('Elemental Equation'!$E$2)) -> 0.015638941
A15: Methionine | B15: M | C15: 76920 | D15: =(C15)/($D$1) -> 0.019229144 | E15: 149.2 | F15: =(E15)-18.0153 -> 131.1847 | G15: =(D15)*(F15) -> 2.5225695 | H15: =(G15)*1/($G$23) -> 0.023143313 | I15: =((H15)*('Elemental Equation'!$E$2)*1000)/(F15) -> 0.053242886 | J15: =((H15)*('Elemental Equation'!$E$2)) -> 0.006984652
A16: Phenylalanine | B16: F | C16: 129091 | D16: =(C16)/($D$1) -> 0.032271314 | E16: 165.2 | F16: =(E16)-18.0153 -> 147.1847 | G16: =(D16)*(F16) -> 4.7498437 | H16: =(G16)*1/($G$23) -> 0.043577439 | I16: =((H16)*('Elemental Equation'!$E$2)*1000)/(F16) -> 0.08935488 | J16: =((H16)*('Elemental Equation'!$E$2)) -> 0.013151671
A17: Proline | B17: P | C17: 234789 | D17: =(C17)/($D$1) -> 0.058694638 | E17: 115.1 | F17: =(E17)-18.0153 -> 97.0847 | G17: =(D17)*(F17) -> 5.6983513 | H17: =(G17)*1/($G$23) -> 0.052279523 | I17: =((H17)*('Elemental Equation'!$E$2)*1000)/(F17) -> 0.16251747 | J17: =((H17)*('Elemental Equation'!$E$2)) -> 0.01577796
A18: Serine | B18: S | C18: 404286 | D18: =(C18)/($D$1) -> 0.101067 | E18: 105.1 | F18: =(E18)-18.0153 -> 87.0847 | G18: =(D18)*(F18) -> 8.8013896 | H18: =(G18)*1/($G$23) -> 0.080748347 | I18: =((H18)*('Elemental Equation'!$E$2)*1000)/(F18) -> 0.27984079 | J18: =((H18)*('Elemental Equation'!$E$2)) -> 0.024369851
A19: Threonine | B19: T | C19: 240431 | D19: =(C19)/($D$1) -> 0.060105075 | E19: 119.1 | F19: =(E19)-18.0153 -> 101.0847 | G19: =(D19)*(F19) -> 6.0757035 | H19: =(G19)*1/($G$23) -> 0.05574154 | I19: =((H19)*('Elemental Equation'!$E$2)*1000)/(F19) -> 0.16642278 | J19: =((H19)*('Elemental Equation'!$E$2)) -> 0.016822797
A20: Tryptophan | B20: W | C20: 47468 | D20: =(C20)/($D$1) -> 0.011866472 | E20: 204.2 | F20: =(E20)-18.0153 -> 186.1847 | G20: =(D20)*(F20) -> 2.2093555 | H20: =(G20)*1/($G$23) -> 0.020269732 | I20: =((H20)*('Elemental Equation'!$E$2)*1000)/(F20) -> 0.032856647 | J20: =((H20)*('Elemental Equation'!$E$2)) -> 0.006117405
... A22: Valine | B22: V | C22: 234552 | D22: =(C22)/($D$1) -> 0.058635391 | E22: 117.1 | F22: =(E22)-18.0153 -> 99.0847 | G22: =(D22)*(F22) -> 5.8098701 | H22: =(G22)*1/($G$23) -> 0.053302652 | I22: =((H22)*('Elemental Equation'!$E$2)*1000)/(F22) -> 0.16235342 | J22: =((H22)*('Elemental Equation'!$E$2)) -> 0.01608674
A23: Control Sum: | C23: =SUM(C3:C22) -> 4000178 | D23: =SUM(D3:D22) -> 1 | E23: =SUM(E3:E22) -> 2738.2 | F23: Weight of Protein (g) per mole Protein (g/mol): | G23: =SUM(G3:G22) -> 108.99777 | J23: Summe | K23: =SUM(J3:J22) -> 0.3018
D24: Absolute amount of C per AA | E24: Absolute amount of H | F24: Absolute amount of O | G24: Absolute amount of N | H24: Absolute amount of S | I24: Relative amount of C | J24: Relative amount of H | K24: Relative amount of O | L24: Relative amount of N | M24: Relative amount of S
C25: Alanine | D25: 3 | E25: 7 | F25: 2 | G25: 1 | H25: 0 | I25: =(D25)*($D3) -> 0.31705439 | J25: =(E25)*($D3) -> 0.73979358 | K25: =(F25)*($D3) -> 0.21136959 | L25: =(G25)*($D3) -> 0.1056848 | M25: =(H25)*($D3) -> 0
C26: Arginine | D26: 6 | E26: 15 | F26: 2 | G26: 4 | H26: 0 | I26: =(D26)*($D4) -> 0.38292246 | J26: =(E26)*($D4) -> 0.95730615 | K26: =(F26)*($D4) -> 0.12764082 | L26: =(G26)*($D4) -> 0.25528164 | M26: =(H26)*($D4) -> 0
C27: Asparagine | D27: 4 | E27: 8 | F27: 3 | G27: 2 | H27: 0 | I27: =(D27)*($D5) -> 0.13445702 | J27: =(E27)*($D5) -> 0.26891403 | K27: =(F27)*($D5) -> 0.10084276 | L27: =(G27)*($D5) -> 0.067228508 | M27: =(H27)*($D5) -> 0
C28: Aspartic Acid | D28: 4 | E28: 6 | F28: 4 | G28: 1 | H28: 0 | I28: =(D28)*($D6) -> 0.23208467 | J28: =(E28)*($D6) -> 0.34812701 | K28: =(F28)*($D6) -> 0.23208467 | L28: =(G28)*($D6) -> 0.058021168 | M28: =(H28)*($D6) -> 0
C29: Cystein | D29: 3 | E29: 7 | F29: 2 | G29: 1 | H29: 1 | I29: =(D29)*($D7) -> 0.032064823 | J29: =(E29)*($D7) -> 0.074817921 | K29: =(F29)*($D7) -> 0.021376549 | L29: =(G29)*($D7) -> 0.010688274 | M29: =(H29)*($D7) -> 0.010688274
C30: Glutamine | D30: 5 | E30: 10 | F30: 3 | G30: 2 | H30: 0 | I30: =(D30)*($D8) -> 0.22216261 | J30: =(E30)*($D8) -> 0.44432523 | K30: =(F30)*($D8) -> 0.13329757 | L30: =(G30)*($D8) -> 0.088865046 | M30: =(H30)*($D8) -> 0
C31: Glutamic Acid | D31: 5 | E31: 8 | F31: 4 | G31: 1 | H31: 0 | I31: =(D31)*($D9) -> 0.26744685 | J31: =(E31)*($D9) -> 0.42791496 | K31: =(F31)*($D9) -> 0.21395748 | L31: =(G31)*($D9) -> 0.05348937 | M31: =(H31)*($D9) -> 0
C32: Glycine | D32: 2 | E32: 5 | F32: 2 | G32: 1 | H32: 0 | I32: =(D32)*($D10) -> 0.12884577 | J32: =(E32)*($D10) -> 0.32211442 | K32: =(F32)*($D10) -> 0.12884577 | L32: =(G32)*($D10) -> 0.064422883 | M32: =(H32)*($D10) -> 0
C33: Histidine | D33: 6 | E33: 9 | F33: 2 | G33: 3 | H33: 0 | I33: =(D33)*($D11) -> 0.15768648 | J33: =(E33)*($D11) -> 0.23652972 | K33: =(F33)*($D11) -> 0.052562161 | L33: =(G33)*($D11) -> 0.078843241 | M33: =(H33)*($D11) -> 0
C34: Isoleucine | D34: 6 | E34: 13 | F34: 2 | G34: 1 | H34: 0 | I34: =(D34)*($D12) -> 0.24929941 | J34: =(E34)*($D12) -> 0.54014871 | K34: =(F34)*($D12) -> 0.083099802 | L34: =(G34)*($D12) -> 0.041549901 | M34: =(H34)*($D12) -> 0
C35: Leucine | D35: 6 | E35: 13 | F35: 2 | G35: 1 | H35: 0 | I35: =(D35)*($D13) -> 0.53746358 | J35: =(E35)*($D13) -> 1.1645044 | K35: =(F35)*($D13) -> 0.17915453 | L35: =(G35)*($D13) -> 0.089577264 | M35: =(H35)*($D13) -> 0
C36: Lysine | D36: 6 | E36: 15 | F36: 2 | G36: 2 | H36: 0 | I36: =(D36)*($D14) -> 0.26437524 | J36: =(E36)*($D14) -> 0.66093809 | K36: =(F36)*($D14) -> 0.088125078 | L36: =(G36)*($D14) -> 0.088125078 | M36: =(H36)*($D14) -> 0
... C44: Valine | D44: 5 | E44: 11 | F44: 2 | G44: 1 | H44: 0 | I44: =(D44)*($D22) -> 0.29317695 | J44: =(E44)*($D22) -> 0.6449893 | K44: =(F44)*($D22) -> 0.11727078 | L44: =(G44)*($D22) -> 0.058635391 | M44: =(H44)*($D22) -> 0
C45: Total Elemental Equation per mole protein: | D45: =SUM(D25:D44) -> 107 | E45: =SUM(E25:E44) -> 197 | F45: =SUM(F25:F44) -> 49 | G45: =SUM(G25:G44) -> 29 | H45: =SUM(H25:H44) -> 2 | I45: =SUM(I25:I44) -> 4.775632 | J45: =SUM(J25:J44) -> 9.5633442 | K45: =SUM(K25:K44) -> 2.4847264 | ... M45: =SUM(M25:M44) -> 0.029917419
H46: Normalized to C: | I46: =(I45)/($I$45) -> 1 | J46: =(J45)/($I$45) -> 2.0025296 | K46: =(K45)/($I$45) -> 0.52029269 | L46: =(L45)/($I$45) -> 0.28854803 | M46: =(M45)/($I$45) -> 0.0062645989

Sheet Genome DNA Composition
A1: Based on FASTA File Proteome Sequences PENDANT/ Helmholtz Munich | B1: Total amount of Desoxy Nucleotides: | D1: =(19667013-22900) -> 19644113
A2: Nucleotide Full Name | B2: 1-Letter Code: | C2: Absolute Amount: | D2: Relative Amount i.e. Molar Percentage (mol/mol): | E2: Molecular Weight (g/mol): | F2: Molecular Weight - Pyrophosphate during polymerization (173.943 g/mol) | G2: Weight of dNTP per mole DNA (g AA/mol DNA) | H2: Weight of dNTP per weight of DNA (g dNTP/g DNA) | I2: mmol dNTP / g DW | J2: g dNTP / g DW | M2: Total amount of DNA per g DW: | N2: 0.0095847008
A3: desoxyAdeninetriphosphate | B3: A | C3: =9030014/2 -> 4515007 | D3: =(C3)/($D$1) -> 0.22984021 | E3: 491.18162 | F3: =(E3)-173.943 -> 317.23862 | G3: =(D3)*(F3) -> 72.914191 | H3: =(G3)*1/($G$7) -> 0.23295357 | I3: =((H3)*('Elemental Equation'!$E$3)*1000)/(F3) -> 0.0022029496 | J3: =((H3)*('Elemental Equation'!$E$3)) -> 0.0006988607 | M3: wt % | N3: ='Elemental Equation'!B3 -> 0.003
A4: desoxyThyminetriphosphat | B4: T | C4: =9030014/2 -> 4515007 | D4: =(C4)/($D$1) -> 0.22984021 | E4: 482.168 | F4: =(E4)-173.943 -> 308.225 | G4: =(D4)*(F4) -> 70.842498 | H4: =(G4)*1/($G$7) -> 0.22633471 | I4: =((H4)*('Elemental Equation'!$E$3)*1000)/(F4) -> 0.0022029496 | J4: =((H4)*('Elemental Equation'!$E$3)) -> 0.00067900414 | M4: Cp = mmol -P/mmol (Proteine) | N4: 1.365
A5: desoxyGuanosintriphosphat | B5: G | C5: =10614099/2 -> 5307049.5 | D5: =(C5)/($D$1) -> 0.27015979 | E5: 507.18102 | F5: =(E5)-173.943 -> 333.23802 | G5: =(D5)*(F5) -> 90.027515 | H5: =(G5)*1/($G$7) -> 0.28762893 | I5: =((H5)*('Elemental Equation'!$E$3)*1000)/(F5) -> 0.0025894008 | J5: =((H5)*('Elemental Equation'!$E$3)) -> 0.0008628868 | M5: Result (mmol -P/g DW) | N5: =((N2)*(N4)) -> 0.013083117
A6: desoxyCytidintriphosphat | B6: C | C6: =10614099/2 -> 5307049.5 | D6: =(C6)/($D$1) -> 0.27015979 | E6: 467.15692 | F6: =(E6)-173.943 -> 293.21392 | G6: =(D6)*(F6) -> 79.214613 | H6: =(G6)*1/($G$7) -> 0.25308279 | I6: =((H6)*('Elemental Equation'!$E$3)*1000)/(F6) -> 0.0025894008 | J6: =((H6)*('Elemental Equation'!$E$3)) -> 0.00075924836
F7: Weight of DNA (g) per mole DNA (g/mol): | G7: =SUM(G3:G6) -> 312.99882 | I7: =SUM(I3:I6) -> 0.0095847008
C13: Absolute amount of C per AA | D13: Absolute amount of H | E13: Absolute amount of O minus the Os from Pyrophosphate | F13: Absolute amount of N | G13: Absolute amount of P minus the Ps from pyrophosphate | H13: Relative amount of C | I13: Relative amount of H | J13: Relative amount of O | K13: Relative amount of N | L13: Relative amount of P
B14: dAMP | C14: 10 | D14: 12 | E14: =12-7 -> 5 | F14: 5 | G14: 1 | H14: =(C14)*(D3) -> 2.2984021 | I14: =(D14)*(D3) -> 2.7580825 | J14: =(E14)*(D3) -> 1.149201 | K14: =(F14)*(D3) -> 1.149201 | L14: =(G14)*(D3) -> 0.22984021
B15: dTMP | C15: 10 | D15: 13 | E15: =14-7 -> 7 | F15: 2 | G15: 1 | H15: =(C15)*(D4) -> 2.2984021 | I15: =(D15)*(D4) -> 2.9879227 | J15: =(E15)*(D4) -> 1.6088814 | K15: =(F15)*(D4) -> 0.45968041 | L15: =(G15)*(D4) -> 0.22984021
B16: dGMP | C16: 10 | D16: 12 | E16: =13-7 -> 6 | F16: 5 | G16: 1 | H16: =(C16)*(D5) -> 2.7015979 | I16: =(D16)*(D5) -> 3.2419175 | J16: =(E16)*(D5) -> 1.6209588 | K16: =(F16)*(D5) -> 1.350799 | L16: =(G16)*(D5) -> 0.27015979
B17: dCMP | C17: 9 | D17: 12 | E17: =13-7 -> 6 | F17: 3 | G17: 1 | H17: =(C17)*(D6) -> 2.4314381 | I17: =(D17)*(D6) -> 3.2419175 | J17: =(E17)*(D6) -> 1.6209588 | K17: =(F17)*(D6) -> 0.81047938 | L17: =(G17)*(D6) -> 0.27015979
B18: Total Elemental Equation per mole DNA: | C18: =SUM(C14:C17) -> 39 | D18: =SUM(F14:F17) -> 15 | E18: =SUM(E14:E17) -> 24 | F18: =SUM(D14:D17) -> 49 | G18: =SUM(G14:G17) -> 4 | H18: =SUM(H14:H17) -> 9.7298402 | I18: =SUM(I14:I17) -> 12.22984 | J18: =SUM(J14:J17) -> 6 | K18: =SUM(K14:K17) -> 3.7701598 | L18: =SUM(L14:L17) -> 1
G19: Normalized to C: | H19: =(H18)/($H$18) -> 1 | I19: =(I18)/($H$18) -> 1.2569415 | J19: =(J18)/($H$18) -> 0.61665966 | K19: =(K18)/($H$18) -> 0.38748425 | L19: =(L18)/($H$18) -> 0.10277661

Sheet Genome RNA Composition
A1: Based on FASTA File Proteome Sequences PENDANT/ Helmholtz Munich | B1: Total amount of Nucleotides: | D1: =(19667013-22900) -> 19644113
A2: Nucleotide Full Name | B2: 1-Letter Code: | C2: Absolute Amount: | D2: Relative Amount i.e. Molar Percentage (mol/mol): | E2: Molecular Weight (g/mol): | F2: Molecular Weight - Pyrophosphate during polymerization (173.943 g/mol) | G2: Weight of NTP per mole RNA (g NTP/mol RNA) | H2: Weight of dNTP per weight of RNA (g RNA/g DW) | I2: mmol NTP / g DW | J2: g NTP / g DW | L2: Total amount of DNA per g DW: | M2: 0.30696051
A3: Adeninetriphosphate | B3: A | C3: =9030014/2 -> 4515007 | D3: =(C3)/($D$1) -> 0.22984021 | E3: 507.18 | F3: =(E3)-173.943 -> 333.237 | G3: =(D3)*(F3) -> 76.591261 | H3: =(G3)*1/($G$7) -> 0.23510493 | I3: =((H3)*('Elemental Equation'!$E$4)*1000)/(F3) -> 0.070551868 | J3: =((H3)*('Elemental Equation'!$E$4)) -> 0.023510493 | L3: wt % | M3: ='Elemental Equation'!B4 -> 0.1
A4: Uridintriphosphat | B4: U | C4: =9030014/2 -> 4515007 | D4: =(C4)/($D$1) -> 0.22984021 | E4: 484.14 | F4: =(E4)-173.943 -> 310.197 | G4: =(D4)*(F4) -> 71.295743 | H4: =(G4)*1/($G$7) -> 0.21884978 | I4: =((H4)*('Elemental Equation'!$E$4)*1000)/(F4) -> 0.070551868 | J4: =((H4)*('Elemental Equation'!$E$4)) -> 0.021884978 | L4: Cp = mmol -P/mmol (Proteine) | M4: 0.406
A5: Guanosintriphosphat | B5: G | C5: =10614099/2 -> 5307049.5 | D5: =(C5)/($D$1) -> 0.27015979 | E5: 523.18 | F5: =(E5)-173.943 -> 349.237 | G5: =(D5)*(F5) -> 94.349796 | H5: =(G5)*1/($G$7) -> 0.28961662 | I5: =((H5)*('Elemental Equation'!$E$4)*1000)/(F5) -> 0.082928389 | J5: =((H5)*('Elemental Equation'!$E$4)) -> 0.028961662 | L5: Result (mmol -P/g DW) | M5: =((M2)*(M4)) -> 0.12462597
A6: Cytidintriphosphat | B6: C | C6: =10614099/2 -> 5307049.5 | D6: =(C6)/($D$1) -> 0.27015979 | E6: 483.16 | F6: =(E6)-173.943 -> 309.217 | G6: =(D6)*(F6) -> 83.538001 | H6: =(G6)*1/($G$7) -> 0.25642868 | I6: =((H6)*('Elemental Equation'!$E$4)*1000)/(F6) -> 0.082928389 | J6: =((H6)*('Elemental Equation'!$E$4)) -> 0.025642868
F7: Weight of RNA (g) per mole RNA(g/mol): | G7: =SUM(G3:G6) -> 325.7748 | H7: =SUM(H3:H6) -> 1 | I7: =SUM(I3:I6) -> 0.30696051
B9: Absolute amount of C per AA | C9: Absolute amount of H | D9: Absolute amount of O | E9: Absolute amount of N | F9: Absolute amount of P | G9: Relative amount of C | H9: Relative amount of H | I9: Relative amount of O | J9: Relative amount of N | K9: Relative amount of P
A10: AMP | B10: 10 | C10: 12 | D10: 7 | E10: 5 | F10: 1 | G10: =(B10)*(D3) -> 2.2984021 | H10: =(C10)*(D3) -> 2.7580825 | I10: =(D10)*(D3) -> 1.6088814 | J10: =(E10)*(D3) -> 1.149201 | K10: =(F10)*(D3) -> 0.22984021
A11: UMP | B11: 9 | C11: 11 | D11: 9 | E11: 2 | F11: 1 | G11: =(B11)*(D4) -> 2.0685619 | H11: =(C11)*(D4) -> 2.5282423 | I11: =(D11)*(D4) -> 2.0685619 | J11: =(E11)*(D4) -> 0.45968041 | K11: =(F11)*(D4) -> 0.22984021
A12: GMP | B12: 10 | C12: 12 | D12: 8 | E12: 5 | F12: 1 | G12: =(B12)*(D5) -> 2.7015979 | H12: =(C12)*(D5) -> 3.2419175 | I12: =(D12)*(D5) -> 2.1612783 | J12: =(E12)*(D5) -> 1.350799 | K12: =(F12)*(D5) -> 0.27015979
A13: CMP | B13: 9 | C13: 12 | D13: 8 | E13: 3 | F13: 1 | G13: =(B13)*(D6) -> 2.4314381 | H13: =(C13)*(D6) -> 3.2419175 | I13: =(D13)*(D6) -> 2.1612783 | J13: =(E13)*(D6) -> 0.81047938 | K13: =(F13)*(D6) -> 0.27015979
A14: Total Elemental Equation per mole DNA: | B14: =SUM(B10:B13) -> 38 | C14: =SUM(C10:C13) -> 47 | D14: =SUM(D10:D13) -> 32 | E14: =SUM(E10:E13) -> 15 | F14: =SUM(F10:F13) -> 4 | G14: =SUM(G10:G13) -> 9.5 | H14: =SUM(H10:H13) -> 11.77016 | I14: =SUM(I10:I13) -> 8 | ... K14: =SUM(K10:K13) -> 1
F15: Normalized to C: | G15: =(G14)/($G$14) -> 1 | H15: =(H14)/($G$14) -> 1.2389642 | I15: =(I14)/($G$14) -> 0.84210526 | J15: =(J14)/($G$14) -> 0.39685893 | K15: =(K14)/($G$14) -> 0.10526316

Sheet Lipid Composition
A1: Based on A. Hernandez, D. Cooke, M. Lewis et al. (1997) | B1: Total amount of Nucleotides (µg/mg protein): | D1: =SUM(C3:C7) -> 546.8
A2: TOTAL LIPIDS of plasma membrane (Combination of fatty acids, sterols and phospholipids!) | B2: Abbreviation: | C2: Absolute Amount (µg/mg protein): | D2: Relative Amount (no unit): | E2: Average Molecular Weight (g/mol) combined from average molecular weight of lipids in complexes composition and phosphatidyl core: | F2: Adapted Absolute Amount based on lipids present in Model! (µg/mg protein) | G2: Adapted Relative Amount (w/w) based on lipids present in Model!: | H2: Weight of lipids per mole Total lipids (g lipids/mol Total lipids) | I2: Weight of lipids per weight of lipids (g lipids/g total lipids) | J2: mmol Lipid / g DW | K2: g Lipids/ g DW
A3: Phoshpatidylethanolamine | B3: PE | C3: 125.3 | D3: =(C3)/($D$1) -> 0.22915143 | E3: =269.147 +2*(H59) -> 802.21453 | F3: 125.3 | G3: =(F3)/($F$10) -> 0.30047962 | H3: =(E3)* (G3) -> 241.04911 | I3: =(H3)*1/($H$10) -> 0.4126641 | J3: =((I3)*('Elemental Equation'!$E$5)*1000)/(E3) -> 0.20632831 | K3: =(I3)*('Elemental Equation'!$E$5) -> 0.16551957
A4: Phoshatidylcholine | B4: PC | C4: 79.1 | D4: =(C4)/($D$1) -> 0.14465984 | E4: =311.228+ 2*(H59) -> 844.29553 | F4: 79.1 | G4: =(F4)/($F$10) -> 0.18968825 | H4: =(E4)* (G4) -> 160.15294 | I4: =(H4)*1/($H$10) -> 0.27417387 | J4: =((I4)*('Elemental Equation'!$E$5)*1000)/(E4) -> 0.13025195 | K4: =(I4)*('Elemental Equation'!$E$5) -> 0.10997114
B5: Free Sterols | C5: 146.6 | D5: =(C5)/($D$1) -> 0.26810534 | E5: =(H27) -> 396.65 | F5: 146.6 | G5: =(F5)/($F$10) -> 0.35155875 | H5: =(E5)* (G5) -> 139.44578 | I5: =(H5)*1/($H$10) -> 0.23872424 | J5: =((I5)*('Elemental Equation'!$E$5)*1000)/(E5) -> 0.24140248 | K5: =(I5)*('Elemental Equation'!$E$5) -> 0.095752293
B6: CLB Fatty Acids | C6: =334.2 -(C3)-(C4) -> 129.8 | D6: =(C6)/($D$1) -> 0.23738113 | E6: =(H59) -> 266.53377 | F6: 0 | G6: =(F6)/($F$10) -> 0 | H6: =(E6)* (G6) -> 0 | I6: =(H6)*1/($H$10) -> 0 | K6: =(I6)*('Elemental Equation'!$E$5) -> 0
B7: Free Fatty Acids | C7: 66 | D7: =(C7)/($D$1) -> 0.12070227 | E7: =(H44) -> 274.72262 | F7: 66 | G7: =(F7)/($F$10) -> 0.15827338 | H7: =(E7)* (G7) -> 43.481278 | I7: =(H7)*1/($H$10) -> 0.074437786 | J7: =((I7)*('Elemental Equation'!$E$5)*1000)/(E7) -> 0.10868052 | K7: =(I7)*('Elemental Equation'!$E$5) -> 0.029856996
E10: Sum: | F10: =SUM(F3:F9) -> 417 | G10: Weight of Total Lipids (g) per mole Total Lipids (g/mol): | H10: =SUM(H3:H9) -> 584.12911 | I10: =SUM(I3:I7) -> 1 | J10: =SUM(J3:J7) -> 0.68666326 | K10: =SUM(K3:K7) -> 0.4011
A15: Free Sterols present in Ustilago plasma membrane according to A. Hernandez, D. Cooke, M. Lewis et al. (1997) | B15: IUPAC name: | C15: Absolute Amount (µg/mg protein): | D15: Relative Amount (w/w): | E15: Molecular Weight (g/mol): | F15: Adapted Absolute Amount based of Free Sterols present in Model! | G15: Adapted Relative Amount (w/w) based of Free Sterols present in Model!: | H15: Weight of Free Sterols per mole Free Sterols (g Sterols/mol Sterols | I15: Weight of Free Sterols per weight of Total Free Sterols(g Sterols/g Total Sterols) | J15: Free Sterols present in Model CL1710
A16: Ergosterol | B16: ergosta-5,7,22-trien-3β-ol | C16: 69.1 | D16: =(C16)/($C$26) -> 0.72204807 | E16: 396.65 | F16: 69.1 | G16: =(F16)/($F$26) -> 1 | H16: =(E16)* (G16) -> 396.65 | I16: =(H16)*1/($H$44) -> 1.44382 | J16: ERGOSTEROL_c
A17: ergosta-5,7-dienol | C17: 18.4 | D17: =(C17)/($C$26) -> 0.1922675 | E17: 398.671 | F17: 0 | G17: =(F17)/($F$43) -> 0 | H17: =(E17)* (G17) -> 0 | I17: =(H17)*1/($H$44) -> 0 | J17: X
A18: Ergosta-7-enol | B18: ergost-7-enol | C18: 4.5 | D18: =(C18)/($C$26) -> 0.047021944 | E18: 0 | F18: 0 | G18: =(F18)/($F$43) -> 0 | H18: =(E18)* (G18) -> 0 | I18: =(H18)*1/($H$44) -> 0 | J18: X
A19: 14-Methylfecosterol | C19: 0.3 | D19: =(C19)/($C$26) -> 0.0031347962 | E19: 412.37052 | F19: 0 | G19: =(F19)/($F$43) -> 0 | H19: =(E19)* (G19) -> 0 | I19: =(H19)*1/($H$44) -> 0 | J19: X
A20: Obtusifoliol | C20: 0 | D20: =(C20)/($C$26) -> 0 | E20: 426.7174 | F20: 0 | G20: =(F20)/($F$43) -> 0 | H20: =(E20)* (G20) -> 0 | I20: =(H20)*1/($H$44) -> 0 | J20: OBTUSIFOLIOL_c
A21: Eburicol | C21: 1.3 | D21: =(C21)/($C$26) -> 0.013584117 | E21: 440.744 | F21: 0 | G21: =(F21)/($F$43) -> 0 | H21: =(E21)* (G21) -> 0 | I21: =(H21)*1/($H$44) -> 0 | J21: X
A22: Ergosta-5,8,22-trienol | B22: (3β,22E)-Ergosta-5,8,22-trien-3-ol | C22: 1.1 | D22: =(C22)/($C$26) -> 0.011494253 | E22: 0 | F22: 0 | G22: =(F22)/($F$43) -> 0 | H22: =(E22)* (G22) -> 0 | I22: =(H22)*1/($H$44) -> 0 | J22: X
A23: Ergosta-8,22-dienol | C23: 0 | D23: =(C23)/($C$26) -> 0 | E23: 0 | F23: 0 | G23: =(F23)/($F$43) -> 0 | H23: =(E23)* (G23) -> 0 | I23: =(H23)*1/($H$44) -> 0 | J23: X
A24: Ergosta-8-enol | C24: 0 | D24: =(C24)/($C$26) -> 0 | E24: 0 | F24: 0 | G24: =(F24)/($F$43) -> 0 | H24: =(E24)* (G24) -> 0 | I24: =(H24)*1/($H$44) -> 0 | J24: X
A25: Unknown Sterols | C25: 1 | D25: =(C25)/($C$26) -> 0.010449321 | E25: 0 | F25: 0 | J25: X
B26: Sum: | C26: =SUM(C16:C25) -> 95.7 | E26: Sum: | F26: =SUM(F16:F24) -> 69.1
G27: Average Molecular Weight of a typical sterol (g/mol): | H27: =SUM(H16:H24) -> 396.65
A33: Free Fatty Acids present in Ustilago plasma membrane according to A. Hernandez, D. Cooke, M. Lewis et al. (1997) | B33: Abbreviation: | C33: Absolute Amount (µg/mg protein): | D33: Relative Amount (w/w): | E33: Molecular Weight (g/mol): | F33: Adapted Absolute Amount based on FA present in Model! | G33: Adapted Relative Amount (w/w) based on FA present in Model!: | H33: Weight of Fatty Acid per mole Total Fatty Acids (g Fatty Acid/mol Free Fatty Acids) | I33: Weight of Free Fatty Acids per mole Total Fatty Acids (g Free Fatty Acid/mol Total Fatty Acids) | J33: Weight of Fatty Acids per weight of Total Fatty Acids(g Fatty Acid/g Total Fatty Acids) | K33: Fatty Acids present in Model CL1710 | L33: mmol Free Fatty Acids / g DW
A34: Palmitinsäure | B34: 16:0 | C34: 25.1 | D34: =(C34)/($C$43) -> 0.251 | E34: 254.408 | F34: 25.1 | G34: =(F34)/($F$43) -> 0.27312296 | H34: =(E34)* (G34) -> 69.484666 | I34: =(H34)*($G$7) -> 10.997573 | J34: =(I34)*1/($H$10) -> 0.018827298 | K34: PALMITATE_c | L34: =((J34)*('Elemental Equation'!$E$5)*1000)/(E34) -> 0.029683144
A35: Stearinsäure | B35: 18:0 | C35: 28 | D35: =(C35)/($C$43) -> 0.28 | E35: 284.48 | F35: 28 | G35: =(F35)/($F$43) -> 0.304679 | H35: =(E35)* (G35) -> 86.675082 | I35: =(H35)*($G$7) -> 13.718358 | J35: =(I35)*1/($H$10) -> 0.023485147 | K35: STEARIC_ACID_c | L35: =((J35)*('Elemental Equation'!$E$5)*1000)/(E35) -> 0.033112671
A36: Ölsäure | B36: 18:1 | C36: 7.6 | D36: =(C36)/($C$43) -> 0.076 | E36: 282.46 | F36: 7.6 | G36: =(F36)/($F$43) -> 0.082698585 | H36: =(E36)* (G36) -> 23.359042 | I36: =(H36)*($G$7) -> 3.6971146 | J36: =(I36)*1/($H$10) -> 0.0063292764 | K36: OLEATE__45__CPD_c | L36: =((J36)*('Elemental Equation'!$E$5)*1000)/(E36) -> 0.0089877249
A37: Linolsäure | B37: 18:2 | C37: 30.8 | D37: =(C37)/($C$43) -> 0.308 | E37: 280.45 | F37: 30.8 | G37: =(F37)/($F$43) -> 0.3351469 | H37: =(E37)* (G37) -> 93.991948 | I37: =(H37)*($G$7) -> 14.876423 | J37: =(I37)*1/($H$10) -> 0.025467697 | K37: LINOLEIC_ACID_c | L37: =((J37)*('Elemental Equation'!$E$5)*1000)/(E37) -> 0.036423938
A38: Alpha-Linolensäure | B38: 18:3 | C38: 0.4 | D38: =(C38)/($C$43) -> 0.004 | E38: 278.43 | F38: 0.4 | G38: =(F38)/($F$43) -> 0.0043525571 | H38: =(E38)* (G38) -> 1.2118825 | I38: =(H38)*($G$7) -> 0.19180874 | J38: =(I38)*1/($H$10) -> 0.00032836702 | K38: LINOLENIC_ACID_c | L38: =((J38)*('Elemental Equation'!$E$5)*1000)/(E38) -> 0.00047303815
A39: Arachinsäure | B39: 20:0 | C39: 3.7 | D39: =(C39)/($C$43) -> 0.037 | E39: 312.54 | F39: 0 | G39: =(F39)/($F$43) -> 0 | H39: =(E39)* (G39) -> 0 | I39: =(H39)*($G$7) -> 0 | J39: =(I39)*1/($H$10) -> 0 | K39: X
A40: 11-Eicosenoic acid | B40: 20:1 | C40: 0.7 | D40: =(C40)/($C$43) -> 0.007 | E40: 310.51 | F40: 0 | G40: =(F40)/($F$43) -> 0 | H40: =(E40)* (G40) -> 0 | I40: =(H40)*($G$7) -> 0 | J40: =(I40)*1/($H$10) -> 0 | K40: X
A41: Behenic acid | B41: 22:0 | C41: 1.8 | D41: =(C41)/($C$43) -> 0.018 | E41: 340.58 | F41: 0 | G41: =(F41)/($F$43) -> 0 | H41: =(E41)* (G41) -> 0 | I41: =(H41)*($G$7) -> 0 | J41: =(I41)*1/($H$10) -> 0 | K41: X
A42: Erucic acid | B42: 22:1 | C42: 1.9 | D42: =(C42)/($C$43) -> 0.019 | E42: 338.57 | F42: 0 | G42: =(F42)/($F$43) -> 0 | H42: =(E42)* (G42) -> 0 | I42: =(H42)*($G$7) -> 0 | J42: =(I42)*1/($H$10) -> 0 | K42: X
B43: Sum: | C43: =SUM(C34:C42) -> 100 | E43: Sum: | F43: =SUM(F34:F42) -> 91.9
G44: Average Molecular Weight of a typical free fatty acid (g/mol): | H44: =SUM(H34:H42) -> 274.72262 | I44: =SUM(I34:I42) -> 43.481278 | J44: =SUM(J34:J42) -> 0.074437786 | L44: =SUM(L34:L42) -> 0.10868052
A47: Fatty Acid Tails of Complex Lipids present in Ustilago plasma membrane according to A. Hernandez, D. Cooke, M. Lewis et al. (1997) | B47: Abbreviation: | C47: Absolute Amount (µg/mg protein): | D47: Relative Amount (w/w): | E47: Molecular Weight (g/mol): | F47: Adapted Absolute Amount based on FA present in Model! | G47: Adapted Relative Amount (w/w) based on FA present in Model!: | H47: Weight of Fatty Acid per mole Total Fatty Acids (g Fatty Acid/mol Complex Lipids) | I47: Weight of Fatty Acids per weight of Total Fatty Acids(g Fatty Acid/g Total Fatty Acids) | J47: Fatty Acids present in Model CL1710
A48: Palmitinsäure | B48: 16:0 | C48: 29.3 | D48: =(C48)/($C$58) -> 0.29867482 | E48: 254.408 | F48: 29.3 | G48: =(F48)/($F$58) -> 0.29867482 | H48: =(E48)* (G48) -> 75.985264 | I48: =(H48)*1/($H$44) -> 0.27658903 | J48: PALMITATE_c
A49: Palmitoleic acid | B49: 16:1 | C49: 2 | D49: =(C49)/($C$58) -> 0.02038736 | E49: 254.41 | F49: 0 | G49: =(F49)/($F$58) -> 0 | H49: =(E49)* (G49) -> 0 | J49: X
A50: Stearinsäure | B50: 18:0 | C50: 20 | D50: =(C50)/($C$58) -> 0.2038736 | E50: 284.48 | F50: 20 | G50: =(F50)/($F$58) -> 0.2038736 | H50: =(E50)* (G50) -> 57.997961 | I50: =(H50)*1/($H$44) -> 0.21111462 | J50: STEARIC_ACID_c
A51: Ölsäure | B51: 18:1 | C51: 24.4 | D51: =(C51)/($C$58) -> 0.24872579 | E51: 282.46 | F51: 24.4 | G51: =(F51)/($F$58) -> 0.24872579 | H51: =(E51)* (G51) -> 70.255087 | I51: =(H51)*1/($H$44) -> 0.25573099 | J51: OLEATE__45__CPD_c
A52: Linolsäure | B52: 18:2 | C52: 20.5 | D52: =(C52)/($C$58) -> 0.20897044 | E52: 280.45 | F52: 20.5 | G52: =(F52)/($F$58) -> 0.20897044 | H52: =(E52)* (G52) -> 58.605759 | I52: =(H52)*1/($H$44) -> 0.21332703 | J52: LINOLEIC_ACID_c
A53: Alpha-Linolensäure | B53: 18:3 | C53: 1.3 | D53: =(C53)/($C$58) -> 0.013251784 | E53: 278.43 | F53: 1.3 | G53: =(F53)/($F$58) -> 0.013251784 | H53: =(E53)* (G53) -> 3.6896942 | I53: =(H53)*1/($H$44) -> 0.013430617 | J53: LINOLENIC_ACID_c
...

Sheet Cell Wall Composition
A1: Based on J. Ruiz-Herrera, C. Leon et al (1996) DOI: 10.1006/fgbi.1996.0028 | B1: Total amount of Nucleotides (µg/mg protein): | D1: =SUM(C3:C8) -> 104.1
A2: CELL WALL (Focus on Monomer and Polysaccharides) | B2: Abbreviation: | C2: Average Percentage of total dry weight (g /100g Cell Wall): | D2: Relative Amount (no unit): | E2: Average Molecular Weight (g/mol) combined from average molecular weight of CW components: | F2: Adapted Absolute Amount based on CW components present in Model! (µg/mg protein) | G2: Adapted Relative Amount (w/w) based on CW components present in Model!: | H2: Weight of CW component per mole Total Cell Wall (g CW component/mol Total Cell Wall) | I2: Weight of individual Cell Wall Components per weight of Total Cell Wall (g Cell Wall Component/g Total Cell Wall) | J2: Fatty Acids present in Model CL1710 | K2: mmol Cell Wall Components / g DW
A3: Chitin | C3: 14.2 | D3: =(C3)/($D$1) -> 0.1364073 | E3: 203.19 | F3: 14.2 | G3: =(F3)/($F$10) -> 0.16099773 | H3: =(E3)* (G3) -> 32.713129 | I3: =(H3)*1/($H$10) -> 0.2162899 | J3: CHITIN_c | K3: =((I3)*('Elemental Equation'!$E$6)*1000)/(E3) -> 0.17393459
A4: Chitosan | C4: 0 | D4: =(C4)/($D$1) -> 0 | E4: 0 | F4: 0 | G4: =(F4)/($F$10) -> 0 | H4: =(E4)* (G4) -> 0 | I4: =(H4)*1/($H$10) -> 0 | J4: X
A5: Protein | C5: 15.9 | D5: =(C5)/($D$1) -> 0.15273775 | E5: 0 | F5: 0 | G5: =(F5)/($F$10) -> 0 | H5: =(E5)* (G5) -> 0 | I5: =(H5)*1/($H$10) -> 0 | J5: X
A6: Polyuronides | C6: 0 | D6: =(C6)/($D$1) -> 0 | E6: 0 | F6: 0 | G6: =(F6)/($F$10) -> 0 | H6: =(E6)* (G6) -> 0 | I6: =(H6)*1/($H$10) -> 0 | J6: X
A7: Phosphate | C7: 0.9 | D7: =(C7)/($D$1) -> 0.0086455331 | E7: 94.971 | F7: 0.9 | G7: =(F7)/($F$10) -> 0.010204082 | H7: =(E7)* (G7) -> 0.96909184 | I7: =(H7)*1/($H$10) -> 0.0064073593 | J7: Pi_c | K7: =((I7)*('Elemental Equation'!$E$6)*1000)/(E7) -> 0.011024023
A8: Neutral Polysaccharides | C8: 73.1 | D8: =(C8)/($D$1) -> 0.70220941 | E8: =(H22) -> 141.84932 | F8: 73.1 | G8: =(F8)/($F$10) -> 0.82879819 | H8: =(E8)* (G8) -> 117.56446 | I8: =(H8)*1/($H$10) -> 0.77730274 | K8: =((I8)*('Elemental Equation'!$E$6)*1000)/(E8) -> 0.89539566
E10: Sum: | F10: =SUM(F3:F9) -> 88.2 | G10: Weight of CellWall (g) per mole CellWall (g/mol): | H10: =SUM(H3:H9) -> 151.24668 | I10: =SUM(I3:I8) -> 1 | K10: =SUM(K3:K8) -> 1.0803543
A13: Neutral Polysaccharides present in Ustilago cell wall Based on J. Ruiz-Herrera, C. Leon et al (1996) DOI: 10.1006/fgbi.1996.0028 | B13: IUPAC name: | C13: Percentage of total neutral polysaccharide content | D13: Relative Amount (w/w): | E13: Molecular Weight (g/mol) - 2 H2O (36 g/mol): | F13: Adapted Absolute Amount based on CW components present in Model! (µg/mg protein) | G13: Adapted Relative Amount (w/w) based on CW components present in Model!: | H13: Weight of neutral polysaccarides per mole per mole Total neutral polysaccharides (g neutralpolysaccharides/mol total neutral polysaccharides) | I13: Weight of neutral polysaccarides per mole Total Cell Wall (g CW component/mol Total Cell Wall) | J13: Weight of individual Neutral Polysaccharides per weight of Total Cell Wall (g Cell Wall Component/g Total Cell Wall) | K13: Neutral Polysaccharides present in Model CL1710
A14: Xylose | C14: 23 | D14: =(C14)/($C$21) -> 0.23 | E14: =150.13 - 36 -> 114.13 | F14: 0 | G14: =(F14)/($F$21) -> 0 | H14: =(E14)* (G14) -> 0 | I14: =(H14)* ($G$8) -> 0 | J14: =(I14)*1/($H$10) -> 0 | K14: X
A15: Mannose | C15: 23 | D15: =(C15)/($C$21) -> 0.23 | E15: =180.16-36 -> 144.16 | F15: 23 | G15: =(F15)/($F$21) -> 0.35384615 | H15: =(E15)* (G15) -> 51.010462 | I15: =(H15)* ($G$8) -> 42.277378 | J15: =(I15)*1/($H$10) -> 0.27952599 | K15: CPD-13559 | L15: =((J15)*('Elemental Equation'!$E$6)*1000)/(E15) -> 0.31683231
A16: Galactose | C16: 11 | D16: =(C16)/($C$21) -> 0.11 | E16: =180.156-36 -> 144.156 | F16: 11 | G16: =(F16)/($F$21) -> 0.16923077 | H16: =(E16)* (G16) -> 24.395631 | I16: =(H16)* ($G$8) -> 20.219055 | J16: =(I16)*1/($H$10) -> 0.13368263 | K16: ALPHA-D-GALACTOSE | L16: =((J16)*('Elemental Equation'!$E$6)*1000)/(E16) -> 0.1515285
A17: Glucose | C17: 26 | D17: =(C17)/($C$21) -> 0.26 | E17: =180.16-36 -> 144.16 | F17: 26 | G17: =(F17)/($F$21) -> 0.4 | H17: =(E17)* (G17) -> 57.664 | I17: =(H17)* ($G$8) -> 47.791819 | J17: =(I17)*1/($H$10) -> 0.3159859 | K17: ALPHA-GLUCOSE | L17: =((J17)*('Elemental Equation'!$E$6)*1000)/(E17) -> 0.35815826
A18: Ribose | C18: 5 | D18: =(C18)/($C$21) -> 0.05 | E18: =150.13-36 -> 114.13 | F18: 5 | G18: =(F18)/($F$21) -> 0.076923077 | H18: =(E18)* (G18) -> 8.7792308 | I18: =(H18)* ($G$8) -> 7.2762105 | J18: =(I18)*1/($H$10) -> 0.048108232 | K18: CPD-10330 | L18: =((J18)*('Elemental Equation'!$E$6)*1000)/(E18) -> 0.068876589
A19: Arabinose | C19: 6 | D19: =(C19)/($C$21) -> 0.06 | E19: =150.13 -36 -> 114.13 | F19: 0 | G19: =(F19)/($F$21) -> 0 | H19: =(E19)* (G19) -> 0 | I19: =(H19)* ($G$8) -> 0 | J19: =(I19)*1/($H$10) -> 0 | K19: X
A20: Fucose | C20: 6 | D20: =(C20)/($C$21) -> 0.06 | E20: =164.16-36 -> 128.16 | F20: 0 | G20: =(F20)/($F$21) -> 0 | H20: =(E20)* (G20) -> 0 | I20: =(H20)* ($G$8) -> 0 | J20: =(I20)*1/($H$10) -> 0 | K20: X
B21: Sum: | C21: =SUM(C14:C20) -> 100 | E21: Sum: | F21: =SUM(F14:F20) -> 65
G22: Average Molecular Weight of a typical Polysaccharide (g/mol): | H22: =SUM(H14:H21) -> 141.84932 | I22: =SUM(I14:I21) -> 117.56446 | J22: =SUM(J14:J21) -> 0.77730274 | L22: =SUM(L15:L20) -> 0.89539566
I26: C6H12O6
I27: C16H23N5O16P2
C33: Absolute amount of C per AA | D33: Absolute amount of H | E33: Absolute amount of O | F33: Absolute amount of N | G33: Absolute amount of P | H33: Relative amount of C | I33: Relative amount of H | J33: Relative amount of O | K33: Relative amount of N | L33: Relative amount of P
B34: CPD-13559 /D__45__mannopyranose_c | C34: 6 | D34: 12 | E34: 6 | F34: 0 | G34: 0 | H34: =(C34)*($D15) -> 1.38 | I34: =(D34)*($D$15) -> 2.76 | J34: =(E34)*($D$15) -> 1.38 | K34: =(F34)*($D$15) -> 0 | L34: =(G34)*($D$15) -> 0
B35: ALPHA-D-GALACTOSE | C35: 6 | D35: 12 | E35: 6 | F35: 0 | G35: 0 | H35: =(C35)*($D16) -> 0.66 | I35: =(D35)*($D$15) -> 2.76 | J35: =(E35)*($D$15) -> 1.38 | K35: =(F35)*($D$15) -> 0 | L35: =(G35)*($D$15) -> 0
B36: ALPHA-GLUCOSE | C36: 6 | D36: 12 | E36: 6 | F36: 0 | G36: 0 | H36: =(C36)*($D17) -> 1.56 | I36: =(D36)*($D$15) -> 2.76 | J36: =(E36)*($D$15) -> 1.38 | K36: =(F36)*($D$15) -> 0 | L36: =(G36)*($D$15) -> 0
B37: CPD-10330 | C37: 5 | D37: 10 | E37: 5 | F37: 0 | G37: 0 | H37: =(C37)*($D18) -> 0.25 | I37: =(D37)*($D$15) -> 2.3 | J37: =(E37)*($D$15) -> 1.15 | K37: =(F37)*($D$15) -> 0 | L37: =(G37)*($D$15) -> 0
B38: Total Neutral Polysaccharides | C38: =SUM(C34:C37) -> 23 | D38: =SUM(D34:D37) -> 46 | E38: =SUM(E34:E37) -> 23 | F38: =SUM(F34:F37) -> 0 | G38: =SUM(G34:G37) -> 0 | H38: =($G$8)*SUM(H34:H37) -> 3.190873 | I38: =($G$8)*SUM(I34:I37) -> 8.7686848 | J38: =($G$8)*SUM(J34:J37) -> 4.3843424 | K38: =($G$8)*SUM(K34:K37) -> 0 | L38: =($G$7)*SUM(L34:L37) -> 0
B49: CHITIN_c | C49: 8 | D49: 13 | E49: 5 | F49: 1 | G49: 0 | H49: =(C49)*($G$3) -> 1.2879819 | I49: =(D49)*($G$3) -> 2.0929705 | J49: =(E49)*($G$3) -> 0.80498866 | K49: =(F49)*($G$3) -> 0.16099773 | L49: =(G49)*($G$3) -> 0
B52: Pi_c | C52: =SUM(C50:C51) -> 0 | D52: 1 | E52: =SUM(E50:E51) -> 0 | F52: 4 | G52: 1 | H52: =(C52)*($G$7) -> 0 | I52: =(D52)*($G$7) -> 0.010204082 | J52: =(E52)*($G$7) -> 0 | K52: =(F52)*($G$7) -> 0.040816327 | L52: =(G52)*($G$7) -> 0.010204082
B58: Total Elemental Equation per mole Cell Wall: | C58: =SUM((C52),(C38),(C49),(C56)) -> 31 | D58: =SUM((D52),(D38),(D49),(D56)) -> 60 | E58: =SUM((E52),(E38),(E49),(E56)) -> 28 | F58: =SUM((F52),(F38),(F49),(F56)) -> 5 | G58: =SUM((G52),(G38),(G49),(G56)) -> 1 | H58: =SUM((H52),(H38),(H49)) -> 4.4788549 | I58: =SUM((I52),(I38),(I49)) -> 10.871859 | J58: =SUM((J52),(J38),(J49)) -> 5.1893311 | K58: =SUM((K52),(K38),(K49)) -> 0.20181406 | L58: =SUM((L52),(L38),(L49)) -> 0.010204082
G59: Normalized to C: | H59: =(H58)/($H$58) -> 1 | I59: =(I58)/($H$58) -> 2.4273748 | J59: =(J58)/($H$58) -> 1.158629 | K59: =(K58)/($H$58) -> 0.045059299 | L59: =(L58)/($H$58) -> 0.0022782791

Sheet Elemental Equation
D1: Unknown Percentages | E1: Percentages Calculated from combined elemental composition U. maydis (CHNO) and S. cerevisiae (PS) [xchangedbounds] [Unit: g/g DW] | F1: C | G1: H | H1: O | I1: N | J1: P | K1: S | M1: Percentages Calculated from combined elemental composition U. maydis (CHNO) and S. cerevisiae (PS). Phoshorus content varied by *1 order of magnitude! | N1: C | O1: H | P1: O | Q1: N | R1: P | S1: S | T1: Percentages Calculated from combined elemental composition U. maydis (CHNO) and S. cerevisiae (PS). Phoshorus content varied by /1 order of magnitude! | U1: C | V1: H | W1: O | X1: N | Y1: P | Z1: S
A2: Protein | B2: 0.3018 | C2: X | E2: 0.3018 | F2: 1 | G2: 2.0025296 | H2: 0.52029269 | I2: 0.28854803 | J2: 0 | K2: 0.0062645989 | M2: 0.29 | N2: 1 | O2: 2.0025296 | P2: 0.52029269 | Q2: 0.28854803 | R2: 0 | S2: 0.0062645989 | T2: 0.3001 | U2: 1 | V2: 2.0025296 | W2: 0.52029269 | X2: 0.28854803 | Y2: 0 | Z2: 0.0062645989
A3: DNA | B3: 0.003 | C3: Y | E3: 0.003 | F3: 1 | G3: 1.2569415 | H3: 0.61665966 | I3: 0.38748425 | J3: 0.10277661 | K3: 0 | M3: 0.003 | N3: 1 | O3: 1.2569415 | P3: 0.61665966 | Q3: 0.38748425 | R3: 0.10277661 | S3: 0 | T3: 0.003 | U3: 1 | V3: 1.2569415 | W3: 0.61665966 | X3: 0.38748425 | Y3: 0.10277661 | Z3: 0
A4: RNA | B4: 0.1 | C4: Z | E4: 0.1 | F4: 1 | G4: 1.2389642 | H4: 0.84210526 | I4: 0.39685893 | J4: 0.10526316 | K4: 0 | M4: 0.1 | N4: 1 | O4: 1.2389642 | P4: 0.84210526 | Q4: 0.39685893 | R4: 0.10526316 | S4: 0 | T4: 0.1 | U4: 1 | V4: 1.2389642 | W4: 0.84210526 | X4: 0.39685893 | Y4: 0.10526316 | Z4: 0
A5: Lipids | B5: 0.4011 | C5: A | E5: 0.4011 | F5: 1 | G5: 1.7834137 | H5: 0.13995973 | I5: 0.0047750382 | J5: 0.0047750382 | K5: 0 | M5: 0.4047 | N5: 1 | O5: 1.7834137 | P5: 0.13995973 | Q5: 0.0047750382 | R5: 0.0047750382 | S5: 0 | T5: 0.4023 | U5: 1 | V5: 1.7834137 | W5: 0.13995973 | X5: 0.0047750382 | Y5: 0.0047750382 | Z5: 0
A6: Cell Wall | B6: 0.1634 | C6: B | E6: 0.1634 | F6: 1 | G6: 2.4273748 | H6: 1.158629 | I6: 0.045059299 | J6: 0.0022782791 | K6: 0 | M6: 0.1653 | N6: 1 | O6: 2.4273748 | P6: 1.158629 | Q6: 0.045059299 | R6: 0.0022782791 | S6: 0 | T6: 0.1639 | U6: 1 | V6: 2.4273748 | W6: 1.158629 | X6: 0.045059299 | Y6: 0.0022782791 | Z6: 0
A7: Ash | E7: =1-SUM(E2:E6) -> 0.0307
A9: Result: | D9: =SUM(D2:D7) -> 0 | F9: =((F2)*($E$2))+((F3)*($E$3))+((F4)*($E$4))+((F5)*($E$5))+((F6)*($E$6)) -> 0.9693 | G9: =((G2)*($E$2))+((G3)*($E$3))+((G4)*($E$4))+((G5)*($E$5))+((G6)*($E$6)) -> 1.8439909 | H9: =((H2)*($E$2))+((H3)*($E$3))+((H4)*($E$4))+((H5)*($E$5))+((H6)*($E$6)) -> 0.48854267 | I9: =((I2)*($E$2))+((I3)*($E$3))+((I4)*($E$4))+((I5)*($E$5))+((I6)*($E$6)) -> 0.1372101 | J9: =((J2)*($E$2))+((J3)*($E$3))+((J4)*($E$4))+((J5)*($E$5))+((J6)*($E$6)) -> 0.013122184 | K9: =((K2)*($E$2))+((K3)*($E$3))+((K4)*($E$4))+((K5)*($E$5))+((K6)*($E$6)) -> 0.0018906559 | L9: <= LinOpt solved with Matlab! Upper and Lower bounds taken from D. Griffin Fungal Physiology 2nd Edition 1994 | N9: =((N2)*($M$2))+((N3)*($M$3))+((N4)*($M$4))+((N5)*($M$5))+((N6)*($M$6)) -> 0.963 | O9: =((O2)*($M$2))+((O3)*($M$3))+((O4)*($M$4))+((O5)*($M$5))+((O6)*($M$6)) -> 1.8313934 | P9: =((P2)*($M$2))+((P3)*($M$3))+((P4)*($M$4))+((P5)*($M$5))+((P6)*($M$6)) -> 0.48510846 | Q9: =((Q2)*($M$2))+((Q3)*($M$3))+((Q4)*($M$4))+((Q5)*($M$5))+((Q6)*($M$6)) -> 0.13390803 | R9: =((R2)*($M$2))+((R3)*($M$3))+((R4)*($M$4))+((R5)*($M$5))+((R6)*($M$6)) -> 0.013143703 | S9: =((S2)*($M$2))+((S3)*($M$3))+((S4)*($M$4))+((S5)*($M$5))+((S6)*($M$6)) -> 0.0018167337 | U9: =((U2)*($T$2))+((U3)*($T$3))+((U4)*($T$4))+((U5)*($T$5))+((U6)*($T$6)) -> 0.9693 | V9: =((V2)*($T$2))+((V3)*($T$3))+((V4)*($T$4))+((V5)*($T$5))+((V6)*($T$6)) -> 1.8439404 | W9: =((W2)*($T$2))+((W3)*($T$3))+((W4)*($T$4))+((W5)*($T$5))+((W6)*($T$6)) -> 0.48840543 | X9: =((X2)*($T$2))+((X3)*($T$3))+((X4)*($T$4))+((X5)*($T$5))+((X6)*($T$6)) -> 0.13674782 | Y9: =((Y2)*($T$2))+((Y3)*($T$3))+((Y4)*($T$4))+((Y5)*($T$5))+((Y6)*($T$6)) -> 0.013129053 | Z9: =((Z2)*($T$2))+((Z3)*($T$3))+((Z4)*($T$4))+((Z5)*($T$5))+((Z6)*($T$6)) -> 0.0018800061
A10: Result Phosphor *10: | F10: 0.963 | G10: 1.8313934 | H10: 0.48510846 | I10: 0.13390803 | J10: 0.013143703 | K10: 0.0018167337 | M10: Percentages Calculated from combined elemental composition U. maydis (CHNO) and S. cerevisiae (PS). Sulphur content varied by *1 order of magnitude! | N10: C | O10: H | P10: O | Q10: N | R10: P | S10: S | T10: Percentages Calculated from combined elemental composition U. maydis (CHNO) and S. cerevisiae (PS). Sulphur content varied by /1 order of magnitude! | U10: C | V10: H | W10: O | X10: N | Y10: P | Z10: S
A11: Result Phosphor /10: | F11: 0.9693 | G11: 1.8439404 | H11: 0.48840543 | I11: 0.13674782 | J11: 0.013129053 | K11: 0.0018800061 | M11: 0.3001 | N11: 1 | O11: 2.0025296 | P11: 0.52029269 | Q11: 0.28854803 | R11: 0 | S11: 0.0062645989 | T11: 0.2974 | U11: 1 | V11: 2.0025296 | W11: 0.52029269 | X11: 0.28854803 | Y11: 0 | Z11: 0.0062645989
A12: Result Sulphur*10: | F12: 0.9693 | G12: 1.8441336 | H12: 0.48871103 | I12: 0.13675991 | J12: 0.013128304 | K12: 0.0018800061 | M12: 0.003 | N12: 1 | O12: 1.2569415 | P12: 0.61665966 | Q12: 0.38748425 | R12: 0.10277661 | S12: 0 | T12: 0.003 | U12: 1 | V12: 1.2569415 | W12: 0.61665966 | X12: 0.38748425 | Y12: 0.10277661 | Z12: 0
A13: Result Sulphur /10: | F13: 0.9691 | G13: 1.8440224 | H13: 0.48898041 | I13: 0.13604514 | J13: 0.013136996 | K13: 0.0018630917 | M13: 0.1 | N13: 1 | O13: 1.2389642 | P13: 0.84210526 | Q13: 0.39685893 | R13: 0.10526316 | S13: 0 | T13: 0.1 | U13: 1 | V13: 1.2389642 | W13: 0.84210526 | X13: 0.39685893 | Y13: 0.10526316 | Z13: 0
M14: 0.402 | N14: 1 | O14: 1.7834137 | P14: 0.13995973 | Q14: 0.0047750382 | R14: 0.0047750382 | S14: 0 | T14: 0.4032 | U14: 1 | V14: 1.7834137 | W14: 0.13995973 | X14: 0.0047750382 | Y14: 0.0047750382 | Z14: 0
M15: 0.1642 | N15: 1 | O15: 2.4273748 | P15: 1.158629 | Q15: 0.045059299 | R15: 0.0022782791 | S15: 0 | T15: 0.1655 | U15: 1 | V15: 2.4273748 | W15: 1.158629 | X15: 0.045059299 | Y15: 0.0022782791 | Z15: 0
A18: During unlimited growth phase | F18: 1 | G18: 1.826 | H18: 0.5 | I18: 0.136 | J18: 0.012 | K18: 0.003 | N18: =((N11)*($M$11))+((N12)*($M$12))+((N13)*($M$13))+((N14)*($M$14))+((N15)*($M$15)) -> 0.9693 | O18: =((O11)*($M$11))+((O12)*($M$12))+((O13)*($M$13))+((O14)*($M$14))+((O15)*($M$15)) -> 1.8441336 | P18: =((P11)*($M$11))+((P12)*($M$12))+((P13)*($M$13))+((P14)*($M$14))+((P15)*($M$15)) -> 0.48871103 | Q18: =((Q11)*($M$11))+((Q12)*($M$12))+((Q13)*($M$13))+((Q14)*($M$14))+((Q15)*($M$15)) -> 0.13675991 | R18: =((R11)*($M$11))+((R12)*($M$12))+((R13)*($M$13))+((R14)*($M$14))+((R15)*($M$15)) -> 0.013128304 | S18: =((S11)*($M$11))+((S12)*($M$12))+((S13)*($M$13))+((S14)*($M$14))+((S15)*($M$15)) -> 0.0018800061 | U18: =((U11)*($T$11))+((U12)*($T$12))+((U13)*($T$13))+((U14)*($T$14))+((U15)*($T$15)) -> 0.9691 | V18: =((V11)*($T$11))+((V12)*($T$12))+((V13)*($T$13))+((V14)*($T$14))+((V15)*($T$15)) -> 1.8440224 | W18: =((W11)*($T$11))+((W12)*($T$12))+((W13)*($T$13))+((W14)*($T$14))+((W15)*($T$15)) -> 0.48898041 | X18: =((X11)*($T$11))+((X12)*($T$12))+((X13)*($T$13))+((X14)*($T$14))+((X15)*($T$15)) -> 0.13604514 | Y18: =((Y11)*($T$11))+((Y12)*($T$12))+((Y13)*($T$13))+((Y14)*($T$14))+((Y15)*($T$15)) -> 0.013136996 | Z18: =((Z11)*($T$11))+((Z12)*($T$12))+((Z13)*($T$13))+((Z14)*($T$14))+((Z15)*($T$15)) -> 0.0018630917
A19: During Nitrogen limitation | F19: 1 | G19: 1.85 | H19: 0.33 | I19: 0.05
A23: Biomass comp of A.Niger:
A24: Protein | C24: 0.263 | D24: 0.263 | E24: =(D24)/($D$31) -> 0.34042223
A25: DNA | C25: 0.00244 | D25: 0.00244 | E25: =(D25)/($D$31) -> 0.0031582899
A26: RNA | C26: 0.01814 | D26: 0.01814 | E26: =(D26)/($D$31) -> 0.023480073
A27: Lipids | C27: 0.10899 | D27: 0.10899 | E27: =(D27)/($D$31) -> 0.1410746
A28: Cell Wall | C28: 0.38 | D28: 0.38 | E28: =(D28)/($D$31) -> 0.49186481
A29: Small molecules | C29: 0.131 | D29: 0 | E29: =(D29)/($D$31) -> 0
A30: Ash | C30: 0.075 | D30: 0 | E30: =(D30)/($D$31) -> 0
A31: Sum | C31: =SUM(C24:C30) -> 0.97857 | D31: =SUM(D24:D30) -> 0.77257
A36: Non Normalized Elemental Composition of Biomass: | E36: C | F36: H | G36: O | H36: N | I36: P | J36: S | K36: Percentages Calculated from combined elemental composition U. maydis (CHNO) and S. cerevisiae (PS) [xchangedbounds] [Unit: g/g DW]
D37: Proteins | E37: 4.775632 | F37: 9.5633442 | G37: 2.4847264 | H37: 1.3779992 | J37: 0.029917419 | K37: 0.3018
D38: DNA | E38: 9.7298402 | F38: 12.22984 | G38: 6 | H38: 3.7701598 | I38: 1 | J38: 0 | K38: 0.003
D39: RNA | E39: 9.5 | F39: 11.77016 | G39: 8 | H39: 3.7701598 | I39: 1 | J39: 0 | K39: 0.1
D40: Lipids | E40: 102.65213 | F40: 183.07122 | G40: 14.367165 | H40: 0.49016787 | I40: 0.49016787 | J40: 0 | K40: 0.4011
D41: Cell Wall | E41: 4.4788549 | F41: 10.871859 | G41: 5.1893311 | H41: 0.20181406 | I41: 0.010204082 | J41: 0 | K41: 0.1634
K42: =1-SUM(K37:K41) -> 0.0307
C44: Result: | E44: =((E37)*($E$2))+((E38)*($E$3))+((E39)*($E$4))+((E40)*($E$5))+((E41)*($E$6)) -> 44.326091 | F44: =((F37)*($E$2))+((F38)*($E$3))+((F39)*($E$4))+((F40)*($E$5))+((F41)*($E$6)) -> 79.30625 | G44: =((G37)*($E$2))+((G38)*($E$3))+((G39)*($E$4))+((G40)*($E$5))+((G41)*($E$6)) -> 8.1784972 | H44: =((H37)*($E$2))+((H38)*($E$3))+((H39)*($E$4))+((H40)*($E$5))+((H41)*($E$6)) -> 1.0337894 | I44: =((I37)*($E$2))+((I38)*($E$3))+((I39)*($E$4))+((I40)*($E$5))+((I41)*($E$6)) -> 0.30127368 | J44: =((J37)*($E$2))+((J38)*($E$3))+((J39)*($E$4))+((J40)*($E$5))+((J41)*($E$6)) -> 0.009029077
E45: =(E44)/($E$44) -> 1 | F45: =(F44)/($E$44) -> 1.7891551 | G45: =(G44)/($E$44) -> 0.18450752 | H45: =(H44)/($E$44) -> 0.023322367 | I45: =(I44)/($E$44) -> 0.0067967572 | J45: =(J44)/($E$44) -> 0.00020369667
