Workbook

Sheet Rohdaten
A1: t0 | B1: 2.1 | AP1: mit deckel | AQ1: t0 | AR1: 2.abiotic
B2: 1 | C2: 2 | D2: 3 | E2: 4 | F2: 5 | G2: 6 | H2: 7 | I2: 8 | J2: 9 | K2: 10 | L2: 11 | M2: 12 | AR2: 1 | AS2: 2 | AT2: 3 | AU2: 4 | AV2: 5 | AW2: 6 | AX2: 7 | AY2: 8 | AZ2: 9 | BA2: 10 | BB2: 11 | BC2: 12
A3: A | B3: 0.123 | C3: 0.115 | D3: 0.12 | E3: 0.129 | F3: 0.115 | G3: 0.129 | H3: 0.146 | I3: 0.128 | J3: 0.12 | K3: 0.119 | L3: 0.121 | M3: 0.213 | N3: 490 | AQ3: A | AR3: 0.112 | AS3: 0.112 | AT3: 0.116 | AU3: 0.119 | AV3: 0.119 | AW3: 0.136 | AX3: 0.145 | AY3: 0.121 | AZ3: 0.136 | BA3: 0.111 | BB3: 0.119 | BC3: 0.205 | BD3: 490
B4: 0.093 | C4: 0.088 | D4: 0.091 | E4: 0.097 | F4: 0.087 | G4: 0.091 | H4: 0.117 | I4: 0.093 | J4: 0.092 | K4: 0.091 | L4: 0.091 | M4: 0.128 | N4: 750 | AR4: 0.088 | AS4: 0.093 | AT4: 0.091 | AU4: 0.092 | AV4: 0.093 | AW4: 0.101 | AX4: 0.12 | AY4: 0.09 | AZ4: 0.112 | BA4: 0.088 | BB4: 0.097 | BC4: 0.126 | BD4: 750
A5: B | B5: 0.122 | C5: 0.115 | D5: 0.119 | E5: 0.119 | F5: 0.194 | G5: 0.127 | H5: 0.121 | I5: 0.124 | J5: 0.152 | K5: 0.119 | L5: 0.118 | M5: 0.119 | N5: 490 | AQ5: B | AR5: 0.113 | AS5: 0.111 | AT5: 0.123 | AU5: 0.119 | AV5: 0.185 | AW5: 0.116 | AX5: 0.117 | AY5: 0.117 | AZ5: 0.139 | BA5: 0.112 | BB5: 0.115 | BC5: 0.113 | BD5: 490
B6: 0.092 | C6: 0.088 | D6: 0.089 | E6: 0.09 | F6: 0.088 | G6: 0.096 | H6: 0.092 | I6: 0.092 | J6: 0.096 | K6: 0.09 | L6: 0.088 | M6: 0.09 | N6: 750 | AR6: 0.088 | AS6: 0.089 | AT6: 0.097 | AU6: 0.092 | AV6: 0.09 | AW6: 0.089 | AX6: 0.092 | AY6: 0.088 | AZ6: 0.09 | BA6: 0.089 | BB6: 0.089 | BC6: 0.089 | BD6: 750
A7: C | B7: 0.114 | C7: 0.109 | D7: 0.114 | E7: 0.117 | F7: 0.109 | G7: 0.122 | H7: 0.118 | I7: 0.12 | J7: 0.119 | K7: 0.116 | L7: 0.112 | M7: 0.158 | N7: 490 | AQ7: C | AR7: 0.112 | AS7: 0.126 | AT7: 0.12 | AU7: 0.127 | AV7: 0.123 | AW7: 0.128 | AX7: 0.117 | AY7: 0.122 | AZ7: 0.114 | BA7: 0.113 | BB7: 0.111 | BC7: 0.115 | BD7: 490
B8: 0.086 | C8: 0.083 | D8: 0.086 | E8: 0.089 | F8: 0.085 | G8: 0.092 | H8: 0.089 | I8: 0.09 | J8: 0.091 | K8: 0.088 | L8: 0.087 | M8: 0.115 | N8: 750 | AR8: 0.087 | AS8: 0.102 | AT8: 0.093 | AU8: 0.097 | AV8: 0.097 | AW8: 0.099 | AX8: 0.091 | AY8: 0.097 | AZ8: 0.089 | BA8: 0.09 | BB8: 0.088 | BC8: 0.089 | BD8: 750
A9: D | B9: 0.112 | C9: 0.109 | D9: 0.114 | E9: 0.125 | F9: 0.108 | G9: 0.451 | H9: 0.117 | I9: 0.118 | J9: 0.119 | K9: 0.116 | L9: 0.113 | M9: 0.118 | N9: 490 | AQ9: D | AR9: 0.116 | AS9: 0.11 | AT9: 0.116 | AU9: 0.121 | AV9: 0.114 | AW9: 0.131 | AX9: 0.114 | AY9: 0.112 | AZ9: 0.113 | BA9: 0.112 | BB9: 0.114 | BC9: 0.112 | BD9: 490
B10: 0.086 | C10: 0.084 | D10: 0.087 | E10: 0.098 | F10: 0.084 | G10: 0.094 | H10: 0.088 | I10: 0.088 | J10: 0.09 | K10: 0.089 | L10: 0.087 | M10: 0.089 | N10: 750 | AR10: 0.092 | AS10: 0.086 | AT10: 0.092 | AU10: 0.094 | AV10: 0.091 | AW10: 0.091 | AX10: 0.088 | AY10: 0.087 | AZ10: 0.089 | BA10: 0.087 | BB10: 0.09 | BC10: 0.088 | BD10: 750
A11: E | B11: 0.133 | C11: 0.111 | D11: 0.113 | E11: 0.125 | F11: 0.157 | G11: 0.12 | H11: 0.123 | I11: 0.117 | J11: 0.132 | K11: 0.116 | L11: 0.114 | M11: 0.146 | N11: 490 | AQ11: E | AR11: 0.137 | AS11: 0.115 | AT11: 0.115 | AU11: 0.12 | AV11: 0.165 | AW11: 0.131 | AX11: 0.131 | AY11: 0.129 | AZ11: 0.118 | BA11: 0.132 | BB11: 0.115 | BC11: 0.147 | BD11: 490
B12: 0.11 | C12: 0.087 | D12: 0.089 | E12: 0.096 | F12: 0.085 | G12: 0.09 | H12: 0.089 | I12: 0.088 | J12: 0.101 | K12: 0.089 | L12: 0.089 | M12: 0.09 | N12: 750 | AR12: 0.11 | AS12: 0.09 | AT12: 0.092 | AU12: 0.093 | AV12: 0.099 | AW12: 0.099 | AX12: 0.098 | AY12: 0.102 | AZ12: 0.092 | BA12: 0.105 | BB12: 0.093 | BC12: 0.095 | BD12: 750
A13: F | B13: 0.118 | C13: 0.11 | D13: 0.148 | E13: 0.122 | F13: 0.112 | G13: 0.122 | H13: 0.111 | I13: 0.126 | J13: 0.129 | K13: 0.125 | L13: 0.114 | M13: 0.144 | N13: 490 | AQ13: F | AR13: 0.113 | AS13: 0.11 | AT13: 0.116 | AU13: 0.127 | AV13: 0.114 | AW13: 0.114 | AX13: 0.115 | AY13: 0.119 | AZ13: 0.131 | BA13: 0.112 | BB13: 0.113 | BC13: 0.113 | BD13: 490
B14: 0.091 | C14: 0.087 | D14: 0.107 | E14: 0.096 | F14: 0.085 | G14: 0.092 | H14: 0.084 | I14: 0.096 | J14: 0.089 | K14: 0.089 | L14: 0.086 | M14: 0.11 | N14: 750 | AR14: 0.087 | AS14: 0.088 | AT14: 0.092 | AU14: 0.104 | AV14: 0.089 | AW14: 0.089 | AX14: 0.089 | AY14: 0.093 | AZ14: 0.092 | BA14: 0.091 | BB14: 0.092 | BC14: 0.09 | BD14: 750
A15: G | B15: 0.115 | C15: 0.108 | D15: 0.111 | E15: 0.131 | F15: 0.109 | G15: 0.117 | H15: 0.124 | I15: 0.121 | J15: 0.132 | K15: 0.162 | L15: 0.114 | M15: 0.128 | N15: 490 | AQ15: G | AR15: 0.113 | AS15: 0.111 | AT15: 0.121 | AU15: 0.114 | AV15: 0.111 | AW15: 0.114 | AX15: 0.117 | AY15: 0.116 | AZ15: 0.116 | BA15: 0.117 | BB15: 0.114 | BC15: 0.114 | BD15: 490
B16: 0.087 | C16: 0.085 | D16: 0.088 | E16: 0.102 | F16: 0.085 | G16: 0.089 | H16: 0.094 | I16: 0.092 | J16: 0.103 | K16: 0.134 | L16: 0.088 | M16: 0.098 | N16: 750 | AR16: 0.088 | AS16: 0.089 | AT16: 0.099 | AU16: 0.088 | AV16: 0.087 | AW16: 0.088 | AX16: 0.092 | AY16: 0.091 | AZ16: 0.09 | BA16: 0.093 | BB16: 0.091 | BC16: 0.091 | BD16: 750
A17: H | B17: 0.266 | C17: 0.129 | D17: 0.115 | E17: 0.12 | F17: 0.112 | G17: 0.12 | H17: 0.121 | I17: 0.12 | J17: 0.241 | K17: 0.116 | L17: 0.12 | M17: 0.122 | N17: 490 | AQ17: H | AR17: 0.113 | AS17: 0.111 | AT17: 0.112 | AU17: 0.113 | AV17: 0.11 | AW17: 0.114 | AX17: 0.118 | AY17: 0.113 | AZ17: 0.216 | BA17: 0.112 | BB17: 0.118 | BC17: 0.113 | BD17: 490
B18: 0.242 | C18: 0.101 | D18: 0.088 | E18: 0.091 | F18: 0.086 | G18: 0.09 | H18: 0.088 | I18: 0.091 | J18: 0.093 | K18: 0.088 | L18: 0.086 | M18: 0.092 | N18: 750 | AR18: 0.088 | AS18: 0.088 | AT18: 0.087 | AU18: 0.088 | AV18: 0.086 | AW18: 0.088 | AX18: 0.088 | AY18: 0.088 | AZ18: 0.088 | BA18: 0.087 | BB18: 0.087 | BC18: 0.087 | BD18: 750
A20: t1 | B20: 2.1 | O20: t1 | P20: 2.2 | AC20: t1 | AD20: 2.3
B21: 1 | C21: 2 | D21: 3 | E21: 4 | F21: 5 | G21: 6 | H21: 7 | I21: 8 | J21: 9 | K21: 10 | L21: 11 | M21: 12 | P21: 1 | Q21: 2 | R21: 3 | S21: 4 | T21: 5 | U21: 6 | V21: 7 | W21: 8 | X21: 9 | Y21: 10 | Z21: 11 | AA21: 12 | AD21: 1 | AE21: 2 | AF21: 3 | AG21: 4 | AH21: 5 | AI21: 6 | AJ21: 7 | AK21: 8 | AL21: 9 | AM21: 10 | AN21: 11 | AO21: 12
A22: A | B22: 0.169 | C22: 0.159 | D22: 0.186 | E22: 0.178 | F22: 0.155 | G22: 0.208 | H22: 0.143 | I22: 0.165 | J22: 0.172 | K22: 0.5 | L22: 0.169 | M22: 0.368 | N22: 490 | O22: A | P22: 0.167 | Q22: 0.155 | R22: 0.162 | S22: 0.18 | T22: 0.163 | U22: 0.207 | V22: 0.174 | W22: 0.17 | X22: 0.179 | Y22: 0.457 | Z22: 0.172 | AA22: 0.351 | AB22: 490 | AC22: A | AD22: 0.167 | AE22: 0.17 | AF22: 0.162 | AG22: 0.178 | AH22: 0.166 | AI22: 0.213 | AJ22: 0.165 | AK22: 0.161 | AL22: 0.179 | AM22: 0.424 | AN22: 0.174 | AO22: 0.359 | AP22: 490
B23: 0.122 | C23: 0.113 | D23: 0.134 | E23: 0.128 | F23: 0.116 | G23: 0.141 | H23: 0.1 | I23: 0.11 | J23: 0.126 | K23: 0.304 | L23: 0.121 | M23: 0.216 | N23: 750 | P23: 0.12 | Q23: 0.111 | R23: 0.119 | S23: 0.13 | T23: 0.122 | U23: 0.141 | V23: 0.123 | W23: 0.115 | X23: 0.131 | Y23: 0.278 | Z23: 0.123 | AA23: 0.208 | AB23: 750 | AD23: 0.119 | AE23: 0.119 | AF23: 0.12 | AG23: 0.129 | AH23: 0.122 | AI23: 0.145 | AJ23: 0.115 | AK23: 0.111 | AL23: 0.131 | AM23: 0.255 | AN23: 0.125 | AO23: 0.209 | AP23: 750
A24: B | B24: 0.168 | C24: 0.148 | D24: 0.184 | E24: 0.274 | F24: 0.394 | G24: 0.377 | H24: 0.369 | I24: 0.178 | J24: 0.288 | K24: 0.443 | L24: 0.201 | M24: 0.142 | N24: 490 | O24: B | P24: 0.167 | Q24: 0.14 | R24: 0.189 | S24: 0.266 | T24: 0.41 | U24: 0.315 | V24: 0.328 | W24: 0.183 | X24: 0.315 | Y24: 0.328 | Z24: 0.208 | AA24: 0.144 | AB24: 490 | AC24: B | AD24: 0.17 | AE24: 0.148 | AF24: 0.178 | AG24: 0.273 | AH24: 0.337 | AI24: 0.338 | AJ24: 0.366 | AK24: 0.175 | AL24: 0.251 | AM24: 0.375 | AN24: 0.19 | AO24: 0.145 | AP24: 490
B25: 0.121 | C25: 0.107 | D25: 0.118 | E25: 0.192 | F25: 0.13 | G25: 0.225 | H25: 0.256 | I25: 0.125 | J25: 0.113 | K25: 0.29 | L25: 0.138 | M25: 0.098 | N25: 750 | P25: 0.12 | Q25: 0.101 | R25: 0.122 | S25: 0.19 | T25: 0.132 | U25: 0.192 | V25: 0.232 | W25: 0.13 | X25: 0.129 | Y25: 0.213 | Z25: 0.143 | AA25: 0.099 | AB25: 750 | AD25: 0.122 | AE25: 0.106 | AF25: 0.121 | AG25: 0.194 | AH25: 0.132 | AI25: 0.207 | AJ25: 0.257 | AK25: 0.124 | AL25: 0.107 | AM25: 0.242 | AN25: 0.135 | AO25: 0.101 | AP25: 750
A26: C | B26: 0.17 | C26: 0.146 | D26: 0.165 | E26: 0.36 | F26: 0.195 | G26: 0.179 | H26: 0.174 | I26: 0.168 | J26: 0.173 | K26: 0.163 | L26: 0.165 | M26: 0.712 | N26: 490 | O26: C | P26: 0.169 | Q26: 0.151 | R26: 0.168 | S26: 0.355 | T26: 0.208 | U26: 0.178 | V26: 0.179 | W26: 0.169 | X26: 0.175 | Y26: 0.16 | Z26: 0.172 | AA26: 0.636 | AB26: 490 | AC26: C | AD26: 0.157 | AE26: 0.155 | AF26: 0.164 | AG26: 0.374 | AH26: 0.212 | AI26: 0.171 | AJ26: 0.177 | AK26: 0.16 | AL26: 0.175 | AM26: 0.17 | AN26: 0.164 | AO26: 0.614 | AP26: 490
B27: 0.122 | C27: 0.105 | D27: 0.119 | E27: 0.225 | F27: 0.144 | G27: 0.128 | H27: 0.126 | I27: 0.117 | J27: 0.125 | K27: 0.119 | L27: 0.122 | M27: 0.393 | N27: 750 | P27: 0.121 | Q27: 0.108 | R27: 0.122 | S27: 0.223 | T27: 0.153 | U27: 0.129 | V27: 0.13 | W27: 0.119 | X27: 0.128 | Y27: 0.118 | Z27: 0.128 | AA27: 0.336 | AB27: 750 | AD27: 0.113 | AE27: 0.111 | AF27: 0.119 | AG27: 0.236 | AH27: 0.154 | AI27: 0.125 | AJ27: 0.127 | AK27: 0.114 | AL27: 0.127 | AM27: 0.123 | AN27: 0.122 | AO27: 0.333 | AP27: 750
A28: D | B28: 0.171 | C28: 0.151 | D28: 0.158 | E28: 0.148 | F28: 0.158 | G28: 0.257 | H28: 0.42 | I28: 0.317 | J28: 0.153 | K28: 0.191 | L28: 0.154 | M28: 0.164 | N28: 490 | O28: D | P28: 0.173 | Q28: 0.155 | R28: 0.163 | S28: 0.15 | T28: 0.168 | U28: 0.263 | V28: 0.443 | W28: 0.307 | X28: 0.15 | Y28: 0.171 | Z28: 0.156 | AA28: 0.157 | AB28: 490 | AC28: D | AD28: 0.171 | AE28: 0.157 | AF28: 0.166 | AG28: 0.14 | AH28: 0.173 | AI28: 0.235 | AJ28: 0.461 | AK28: 0.328 | AL28: 0.158 | AM28: 0.168 | AN28: 0.154 | AO28: 0.161 | AP28: 490
B29: 0.124 | C29: 0.11 | D29: 0.115 | E29: 0.093 | F29: 0.116 | G29: 0.145 | H29: 0.188 | I29: 0.209 | J29: 0.108 | K29: 0.135 | L29: 0.111 | M29: 0.118 | N29: 750 | P29: 0.125 | Q29: 0.114 | R29: 0.119 | S29: 0.094 | T29: 0.123 | U29: 0.149 | V29: 0.189 | W29: 0.208 | X29: 0.108 | Y29: 0.127 | Z29: 0.113 | AA29: 0.114 | AB29: 750 | AD29: 0.123 | AE29: 0.113 | AF29: 0.12 | AG29: 0.091 | AH29: 0.125 | AI29: 0.147 | AJ29: 0.204 | AK29: 0.217 | AL29: 0.111 | AM29: 0.123 | AN29: 0.113 | AO29: 0.116 | AP29: 750
A30: E | B30: 0.095 | C30: 0.136 | D30: 0.154 | E30: 0.285 | F30: 0.399 | G30: 0.168 | H30: 0.167 | I30: 0.166 | J30: 0.159 | K30: 0.159 | L30: 0.149 | M30: 0.321 | N30: 490 | O30: E | P30: 0.089 | Q30: 0.131 | R30: 0.159 | S30: 0.276 | T30: 0.427 | U30: 0.168 | V30: 0.174 | W30: 0.173 | X30: 0.157 | Y30: 0.176 | Z30: 0.154 | AA30: 0.337 | AB30: 490 | AC30: E | AD30: 0.089 | AE30: 0.138 | AF30: 0.154 | AG30: 0.261 | AH30: 0.396 | AI30: 0.166 | AJ30: 0.173 | AK30: 0.16 | AL30: 0.161 | AM30: 0.156 | AN30: 0.148 | AO30: 0.303 | AP30: 490
B31: 0.065 | C31: 0.097 | D31: 0.114 | E31: 0.21 | F31: 0.097 | G31: 0.12 | H31: 0.119 | I31: 0.121 | J31: 0.111 | K31: 0.112 | L31: 0.109 | M31: 0.122 | N31: 750 | P31: 0.06 | Q31: 0.096 | R31: 0.119 | S31: 0.204 | T31: 0.103 | U31: 0.121 | V31: 0.124 | W31: 0.127 | X31: 0.112 | Y31: 0.132 | Z31: 0.114 | AA31: 0.123 | AB31: 750 | AD31: 0.06 | AE31: 0.098 | AF31: 0.115 | AG31: 0.193 | AH31: 0.102 | AI31: 0.119 | AJ31: 0.121 | AK31: 0.117 | AL31: 0.115 | AM31: 0.11 | AN31: 0.109 | AO31: 0.122 | AP31: 750
A32: F | B32: 0.155 | C32: 0.144 | D32: 0.175 | E32: 0.165 | F32: 0.18 | G32: 0.164 | H32: 0.152 | I32: 0.172 | J32: 0.233 | K32: 0.155 | L32: 0.153 | M32: 0.161 | N32: 490 | O32: F | P32: 0.166 | Q32: 0.147 | R32: 0.155 | S32: 0.161 | T32: 0.186 | U32: 0.161 | V32: 0.171 | W32: 0.162 | X32: 0.243 | Y32: 0.157 | Z32: 0.162 | AA32: 0.149 | AB32: 490 | AC32: F | AD32: 0.152 | AE32: 0.153 | AF32: 0.162 | AG32: 0.16 | AH32: 0.189 | AI32: 0.162 | AJ32: 0.166 | AK32: 0.151 | AL32: 0.24 | AM32: 0.178 | AN32: 0.148 | AO32: 0.158 | AP32: 490
B33: 0.112 | C33: 0.106 | D33: 0.119 | E33: 0.123 | F33: 0.112 | G33: 0.117 | H33: 0.111 | I33: 0.124 | J33: 0.101 | K33: 0.112 | L33: 0.111 | M33: 0.115 | N33: 750 | P33: 0.12 | Q33: 0.11 | R33: 0.114 | S33: 0.121 | T33: 0.116 | U33: 0.118 | V33: 0.124 | W33: 0.119 | X33: 0.111 | Y33: 0.116 | Z33: 0.12 | AA33: 0.108 | AB33: 750 | AD33: 0.11 | AE33: 0.112 | AF33: 0.118 | AG33: 0.118 | AH33: 0.117 | AI33: 0.116 | AJ33: 0.12 | AK33: 0.11 | AL33: 0.105 | AM33: 0.127 | AN33: 0.108 | AO33: 0.113 | AP33: 750
A34: G | B34: 0.177 | C34: 0.285 | D34: 0.16 | E34: 0.217 | F34: 0.123 | G34: 0.158 | H34: 0.146 | I34: 0.155 | J34: 0.151 | K34: 0.199 | L34: 0.13 | M34: 0.148 | N34: 490 | O34: G | P34: 0.148 | Q34: 0.158 | R34: 0.156 | S34: 0.263 | T34: 0.13 | U34: 0.157 | V34: 0.147 | W34: 0.159 | X34: 0.156 | Y34: 0.142 | Z34: 0.136 | AA34: 0.149 | AB34: 490 | AC34: G | AD34: 0.159 | AE34: 0.173 | AF34: 0.153 | AG34: 0.245 | AH34: 0.133 | AI34: 0.15 | AJ34: 0.145 | AK34: 0.145 | AL34: 0.171 | AM34: 0.146 | AN34: 0.126 | AO34: 0.15 | AP34: 490
B35: 0.124 | C35: 0.196 | D35: 0.12 | E35: 0.163 | F35: 0.088 | G35: 0.108 | H35: 0.103 | I35: 0.111 | J35: 0.108 | K35: 0.136 | L35: 0.09 | M35: 0.103 | N35: 750 | P35: 0.106 | Q35: 0.12 | R35: 0.117 | S35: 0.196 | T35: 0.093 | U35: 0.11 | V35: 0.104 | W35: 0.115 | X35: 0.11 | Y35: 0.103 | Z35: 0.094 | AA35: 0.104 | AB35: 750 | AD35: 0.113 | AE35: 0.128 | AF35: 0.114 | AG35: 0.179 | AH35: 0.093 | AI35: 0.102 | AJ35: 0.101 | AK35: 0.104 | AL35: 0.119 | AM35: 0.105 | AN35: 0.088 | AO35: 0.105 | AP35: 750
A36: H | B36: 0.308 | C36: 0.121 | D36: 0.165 | E36: 0.159 | F36: 0.153 | G36: 0.162 | H36: 0.161 | I36: 0.171 | J36: 0.887 | K36: 0.16 | L36: 0.175 | M36: 0.172 | N36: 490 | O36: H | P36: 0.307 | Q36: 0.134 | R36: 0.153 | S36: 0.154 | T36: 0.151 | U36: 0.158 | V36: 0.161 | W36: 0.164 | X36: 0.858 | Y36: 0.163 | Z36: 0.183 | AA36: 0.172 | AB36: 490 | AC36: H | AD36: 0.279 | AE36: 0.133 | AF36: 0.149 | AG36: 0.153 | AH36: 0.15 | AI36: 0.153 | AJ36: 0.16 | AK36: 0.158 | AL36: 0.93 | AM36: 0.165 | AN36: 0.168 | AO36: 0.164 | AP36: 490
B37: 0.211 | C37: 0.085 | D37: 0.118 | E37: 0.113 | F37: 0.11 | G37: 0.114 | H37: 0.112 | I37: 0.124 | J37: 0.315 | K37: 0.114 | L37: 0.11 | M37: 0.124 | N37: 750 | P37: 0.212 | Q37: 0.094 | R37: 0.11 | S37: 0.11 | T37: 0.11 | U37: 0.112 | V37: 0.113 | W37: 0.119 | X37: 0.273 | Y37: 0.118 | Z37: 0.118 | AA37: 0.124 | AB37: 750 | AD37: 0.194 | AE37: 0.093 | AF37: 0.107 | AG37: 0.108 | AH37: 0.107 | AI37: 0.108 | AJ37: 0.11 | AK37: 0.115 | AL37: 0.33 | AM37: 0.121 | AN37: 0.108 | AO37: 0.119 | AP37: 750
A39: t2 | B39: 2.1 | O39: t2 | P39: 2.2 | AC39: t2 | AD39: 2.3
B40: 1 | C40: 2 | D40: 3 | E40: 4 | F40: 5 | G40: 6 | H40: 7 | I40: 8 | J40: 9 | K40: 10 | L40: 11 | M40: 12 | P40: 1 | Q40: 2 | R40: 3 | S40: 4 | T40: 5 | U40: 6 | V40: 7 | W40: 8 | X40: 9 | Y40: 10 | Z40: 11 | AA40: 12 | AD40: 1 | AE40: 2 | AF40: 3 | AG40: 4 | AH40: 5 | AI40: 6 | AJ40: 7 | AK40: 8 | AL40: 9 | AM40: 10 | AN40: 11 | AO40: 12
A41: A | B41: 0.159 | C41: 0.182 | D41: 0.194 | E41: 0.205 | F41: 0.147 | G41: 0.201 | H41: 0.136 | I41: 0.157 | J41: 0.162 | K41: 0.557 | L41: 0.167 | M41: 0.345 | N41: 490 | O41: A | P41: 0.156 | Q41: 0.145 | R41: 0.152 | S41: 0.169 | T41: 0.153 | U41: 0.201 | V41: 0.163 | W41: 0.162 | X41: 0.168 | Y41: 0.537 | Z41: 0.164 | AA41: 0.333 | AB41: 490 | AC41: A | AD41: 0.156 | AE41: 0.157 | AF41: 0.151 | AG41: 0.201 | AH41: 0.156 | AI41: 0.204 | AJ41: 0.156 | AK41: 0.189 | AL41: 0.2 | AM41: 0.511 | AN41: 0.164 | AO41: 0.338 | AP41: 490
B42: 0.112 | C42: 0.117 | D42: 0.127 | E42: 0.133 | F42: 0.107 | G42: 0.13 | H42: 0.094 | I42: 0.103 | J42: 0.116 | K42: 0.33 | L42: 0.113 | M42: 0.197 | N42: 750 | P42: 0.109 | Q42: 0.101 | R42: 0.109 | S42: 0.12 | T42: 0.112 | U42: 0.131 | V42: 0.114 | W42: 0.107 | X42: 0.12 | Y42: 0.316 | Z42: 0.115 | AA42: 0.189 | AB42: 750 | AD42: 0.109 | AE42: 0.108 | AF42: 0.109 | AG42: 0.136 | AH42: 0.112 | AI42: 0.133 | AJ42: 0.107 | AK42: 0.123 | AL42: 0.131 | AM42: 0.298 | AN42: 0.115 | AO42: 0.192 | AP42: 750
...

Sheet Steigung
B1: PM2A.1 | O1: PM2.2 | AB1: PM2.3
B2: t0 | C2: - | D2: t1 | O2: t0 | P2: - | Q2: t1 | AB2: t0 | AC2: - | AD2: t1
B3: =Rohdaten!B22-Rohdaten!B3 -> 0.046 | C3: =Rohdaten!C22-Rohdaten!C3 -> 0.044 | D3: =Rohdaten!D22-Rohdaten!D3 -> 0.066 | E3: =Rohdaten!E22-Rohdaten!E3 -> 0.049 | F3: =Rohdaten!F22-Rohdaten!F3 -> 0.04 | G3: =Rohdaten!G22-Rohdaten!G3 -> 0.079 | H3: =Rohdaten!H22-Rohdaten!H3 -> -0.003 | I3: =Rohdaten!I22-Rohdaten!I3 -> 0.037 | ... M3: =Rohdaten!M22-Rohdaten!M3 -> 0.155 | O3: =Rohdaten!P22-Rohdaten!B3 -> 0.044 | P3: =Rohdaten!Q22-Rohdaten!C3 -> 0.04 | Q3: =Rohdaten!R22-Rohdaten!D3 -> 0.042 | R3: =Rohdaten!S22-Rohdaten!E3 -> 0.051 | S3: =Rohdaten!T22-Rohdaten!F3 -> 0.048 | T3: =Rohdaten!U22-Rohdaten!G3 -> 0.078 | U3: =Rohdaten!V22-Rohdaten!H3 -> 0.028 | V3: =Rohdaten!W22-Rohdaten!I3 -> 0.042 | ... Z3: =Rohdaten!AA22-Rohdaten!M3 -> 0.138 | AB3: =Rohdaten!AD22-Rohdaten!B3 -> 0.044 | AC3: =Rohdaten!AE22-Rohdaten!C3 -> 0.055 | AD3: =Rohdaten!AF22-Rohdaten!D3 -> 0.042 | AE3: =Rohdaten!AG22-Rohdaten!E3 -> 0.049 | AF3: =Rohdaten!AH22-Rohdaten!F3 -> 0.051 | AG3: =Rohdaten!AI22-Rohdaten!G3 -> 0.084 | AH3: =Rohdaten!AJ22-Rohdaten!H3 -> 0.019 | AI3: =Rohdaten!AK22-Rohdaten!I3 -> 0.033 | ... AM3: =Rohdaten!AO22-Rohdaten!M3 -> 0.146 | AO3: =(AB3+O3+B3)/3 -> 0.044666667
B4: =Rohdaten!B23-Rohdaten!B4 -> 0.029 | C4: =Rohdaten!C23-Rohdaten!C4 -> 0.025 | D4: =Rohdaten!D23-Rohdaten!D4 -> 0.043 | E4: =Rohdaten!E23-Rohdaten!E4 -> 0.031 | F4: =Rohdaten!F23-Rohdaten!F4 -> 0.029 | G4: =Rohdaten!G23-Rohdaten!G4 -> 0.05 | H4: =Rohdaten!H23-Rohdaten!H4 -> -0.017 | I4: =Rohdaten!I23-Rohdaten!I4 -> 0.017 | ... M4: =Rohdaten!M23-Rohdaten!M4 -> 0.088 | O4: =Rohdaten!P23-Rohdaten!B4 -> 0.027 | P4: =Rohdaten!Q23-Rohdaten!C4 -> 0.023 | Q4: =Rohdaten!R23-Rohdaten!D4 -> 0.028 | R4: =Rohdaten!S23-Rohdaten!E4 -> 0.033 | S4: =Rohdaten!T23-Rohdaten!F4 -> 0.035 | T4: =Rohdaten!U23-Rohdaten!G4 -> 0.05 | U4: =Rohdaten!V23-Rohdaten!H4 -> 0.006 | V4: =Rohdaten!W23-Rohdaten!I4 -> 0.022 | ... Z4: =Rohdaten!AA23-Rohdaten!M4 -> 0.08 | AB4: =Rohdaten!AD23-Rohdaten!B4 -> 0.026 | AC4: =Rohdaten!AE23-Rohdaten!C4 -> 0.031 | AD4: =Rohdaten!AF23-Rohdaten!D4 -> 0.029 | AE4: =Rohdaten!AG23-Rohdaten!E4 -> 0.032 | AF4: =Rohdaten!AH23-Rohdaten!F4 -> 0.035 | AG4: =Rohdaten!AI23-Rohdaten!G4 -> 0.054 | AH4: =Rohdaten!AJ23-Rohdaten!H4 -> -0.002 | AI4: =Rohdaten!AK23-Rohdaten!I4 -> 0.018 | ... AM4: =Rohdaten!AO23-Rohdaten!M4 -> 0.081 | AO4: =_xlfn.STDEV.P(AB3+O3+B3) -> 0
B5: =Rohdaten!B24-Rohdaten!B5 -> 0.046 | C5: =Rohdaten!C24-Rohdaten!C5 -> 0.033 | D5: =Rohdaten!D24-Rohdaten!D5 -> 0.065 | E5: =Rohdaten!E24-Rohdaten!E5 -> 0.155 | F5: =Rohdaten!F24-Rohdaten!F5 -> 0.2 | G5: =Rohdaten!G24-Rohdaten!G5 -> 0.25 | H5: =Rohdaten!H24-Rohdaten!H5 -> 0.248 | I5: =Rohdaten!I24-Rohdaten!I5 -> 0.054 | ... M5: =Rohdaten!M24-Rohdaten!M5 -> 0.023 | O5: =Rohdaten!P24-Rohdaten!B5 -> 0.045 | P5: =Rohdaten!Q24-Rohdaten!C5 -> 0.025 | Q5: =Rohdaten!R24-Rohdaten!D5 -> 0.07 | R5: =Rohdaten!S24-Rohdaten!E5 -> 0.147 | S5: =Rohdaten!T24-Rohdaten!F5 -> 0.216 | T5: =Rohdaten!U24-Rohdaten!G5 -> 0.188 | U5: =Rohdaten!V24-Rohdaten!H5 -> 0.207 | V5: =Rohdaten!W24-Rohdaten!I5 -> 0.059 | ... Z5: =Rohdaten!AA24-Rohdaten!M5 -> 0.025 | AB5: =Rohdaten!AD24-Rohdaten!B5 -> 0.048 | AC5: =Rohdaten!AE24-Rohdaten!C5 -> 0.033 | AD5: =Rohdaten!AF24-Rohdaten!D5 -> 0.059 | AE5: =Rohdaten!AG24-Rohdaten!E5 -> 0.154 | AF5: =Rohdaten!AH24-Rohdaten!F5 -> 0.143 | AG5: =Rohdaten!AI24-Rohdaten!G5 -> 0.211 | AH5: =Rohdaten!AJ24-Rohdaten!H5 -> 0.245 | AI5: =Rohdaten!AK24-Rohdaten!I5 -> 0.051 | ... AM5: =Rohdaten!AO24-Rohdaten!M5 -> 0.026
B6: =Rohdaten!B25-Rohdaten!B6 -> 0.029 | C6: =Rohdaten!C25-Rohdaten!C6 -> 0.019 | D6: =Rohdaten!D25-Rohdaten!D6 -> 0.029 | E6: =Rohdaten!E25-Rohdaten!E6 -> 0.102 | F6: =Rohdaten!F25-Rohdaten!F6 -> 0.042 | G6: =Rohdaten!G25-Rohdaten!G6 -> 0.129 | H6: =Rohdaten!H25-Rohdaten!H6 -> 0.164 | I6: =Rohdaten!I25-Rohdaten!I6 -> 0.033 | ... M6: =Rohdaten!M25-Rohdaten!M6 -> 0.008 | O6: =Rohdaten!P25-Rohdaten!B6 -> 0.028 | P6: =Rohdaten!Q25-Rohdaten!C6 -> 0.013 | Q6: =Rohdaten!R25-Rohdaten!D6 -> 0.033 | R6: =Rohdaten!S25-Rohdaten!E6 -> 0.1 | S6: =Rohdaten!T25-Rohdaten!F6 -> 0.044 | T6: =Rohdaten!U25-Rohdaten!G6 -> 0.096 | U6: =Rohdaten!V25-Rohdaten!H6 -> 0.14 | V6: =Rohdaten!W25-Rohdaten!I6 -> 0.038 | ... Z6: =Rohdaten!AA25-Rohdaten!M6 -> 0.009 | AB6: =Rohdaten!AD25-Rohdaten!B6 -> 0.03 | AC6: =Rohdaten!AE25-Rohdaten!C6 -> 0.018 | AD6: =Rohdaten!AF25-Rohdaten!D6 -> 0.032 | AE6: =Rohdaten!AG25-Rohdaten!E6 -> 0.104 | AF6: =Rohdaten!AH25-Rohdaten!F6 -> 0.044 | AG6: =Rohdaten!AI25-Rohdaten!G6 -> 0.111 | AH6: =Rohdaten!AJ25-Rohdaten!H6 -> 0.165 | AI6: =Rohdaten!AK25-Rohdaten!I6 -> 0.032 | ... AM6: =Rohdaten!AO25-Rohdaten!M6 -> 0.011
B7: =Rohdaten!B26-Rohdaten!B7 -> 0.056 | C7: =Rohdaten!C26-Rohdaten!C7 -> 0.037 | D7: =Rohdaten!D26-Rohdaten!D7 -> 0.051 | E7: =Rohdaten!E26-Rohdaten!E7 -> 0.243 | F7: =Rohdaten!F26-Rohdaten!F7 -> 0.086 | G7: =Rohdaten!G26-Rohdaten!G7 -> 0.057 | H7: =Rohdaten!H26-Rohdaten!H7 -> 0.056 | I7: =Rohdaten!I26-Rohdaten!I7 -> 0.048 | ... M7: =Rohdaten!M26-Rohdaten!M7 -> 0.554 | O7: =Rohdaten!P26-Rohdaten!B7 -> 0.055 | P7: =Rohdaten!Q26-Rohdaten!C7 -> 0.042 | Q7: =Rohdaten!R26-Rohdaten!D7 -> 0.054 | R7: =Rohdaten!S26-Rohdaten!E7 -> 0.238 | S7: =Rohdaten!T26-Rohdaten!F7 -> 0.099 | T7: =Rohdaten!U26-Rohdaten!G7 -> 0.056 | U7: =Rohdaten!V26-Rohdaten!H7 -> 0.061 | V7: =Rohdaten!W26-Rohdaten!I7 -> 0.049 | ... Z7: =Rohdaten!AA26-Rohdaten!M7 -> 0.478 | AB7: =Rohdaten!AD26-Rohdaten!B7 -> 0.043 | AC7: =Rohdaten!AE26-Rohdaten!C7 -> 0.046 | AD7: =Rohdaten!AF26-Rohdaten!D7 -> 0.05 | AE7: =Rohdaten!AG26-Rohdaten!E7 -> 0.257 | AF7: =Rohdaten!AH26-Rohdaten!F7 -> 0.103 | AG7: =Rohdaten!AI26-Rohdaten!G7 -> 0.049 | AH7: =Rohdaten!AJ26-Rohdaten!H7 -> 0.059 | AI7: =Rohdaten!AK26-Rohdaten!I7 -> 0.04 | ... AM7: =Rohdaten!AO26-Rohdaten!M7 -> 0.456
B8: =Rohdaten!B27-Rohdaten!B8 -> 0.036 | C8: =Rohdaten!C27-Rohdaten!C8 -> 0.022 | D8: =Rohdaten!D27-Rohdaten!D8 -> 0.033 | E8: =Rohdaten!E27-Rohdaten!E8 -> 0.136 | F8: =Rohdaten!F27-Rohdaten!F8 -> 0.059 | G8: =Rohdaten!G27-Rohdaten!G8 -> 0.036 | H8: =Rohdaten!H27-Rohdaten!H8 -> 0.037 | I8: =Rohdaten!I27-Rohdaten!I8 -> 0.027 | ... M8: =Rohdaten!M27-Rohdaten!M8 -> 0.278 | O8: =Rohdaten!P27-Rohdaten!B8 -> 0.035 | P8: =Rohdaten!Q27-Rohdaten!C8 -> 0.025 | Q8: =Rohdaten!R27-Rohdaten!D8 -> 0.036 | R8: =Rohdaten!S27-Rohdaten!E8 -> 0.134 | S8: =Rohdaten!T27-Rohdaten!F8 -> 0.068 | T8: =Rohdaten!U27-Rohdaten!G8 -> 0.037 | U8: =Rohdaten!V27-Rohdaten!H8 -> 0.041 | V8: =Rohdaten!W27-Rohdaten!I8 -> 0.029 | ... Z8: =Rohdaten!AA27-Rohdaten!M8 -> 0.221 | AB8: =Rohdaten!AD27-Rohdaten!B8 -> 0.027 | AC8: =Rohdaten!AE27-Rohdaten!C8 -> 0.028 | AD8: =Rohdaten!AF27-Rohdaten!D8 -> 0.033 | AE8: =Rohdaten!AG27-Rohdaten!E8 -> 0.147 | AF8: =Rohdaten!AH27-Rohdaten!F8 -> 0.069 | AG8: =Rohdaten!AI27-Rohdaten!G8 -> 0.033 | AH8: =Rohdaten!AJ27-Rohdaten!H8 -> 0.038 | AI8: =Rohdaten!AK27-Rohdaten!I8 -> 0.024 | ... AM8: =Rohdaten!AO27-Rohdaten!M8 -> 0.218
B9: =Rohdaten!B28-Rohdaten!B9 -> 0.059 | C9: =Rohdaten!C28-Rohdaten!C9 -> 0.042 | D9: =Rohdaten!D28-Rohdaten!D9 -> 0.044 | E9: =Rohdaten!E28-Rohdaten!E9 -> 0.023 | F9: =Rohdaten!F28-Rohdaten!F9 -> 0.05 | G9: =Rohdaten!G28-Rohdaten!G9 -> -0.194 | H9: =Rohdaten!H28-Rohdaten!H9 -> 0.303 | I9: =Rohdaten!I28-Rohdaten!I9 -> 0.199 | ... M9: =Rohdaten!M28-Rohdaten!M9 -> 0.046 | O9: =Rohdaten!P28-Rohdaten!B9 -> 0.061 | P9: =Rohdaten!Q28-Rohdaten!C9 -> 0.046 | Q9: =Rohdaten!R28-Rohdaten!D9 -> 0.049 | R9: =Rohdaten!S28-Rohdaten!E9 -> 0.025 | S9: =Rohdaten!T28-Rohdaten!F9 -> 0.06 | T9: =Rohdaten!U28-Rohdaten!G9 -> -0.188 | U9: =Rohdaten!V28-Rohdaten!H9 -> 0.326 | V9: =Rohdaten!W28-Rohdaten!I9 -> 0.189 | ... Z9: =Rohdaten!AA28-Rohdaten!M9 -> 0.039 | AB9: =Rohdaten!AD28-Rohdaten!B9 -> 0.059 | AC9: =Rohdaten!AE28-Rohdaten!C9 -> 0.048 | AD9: =Rohdaten!AF28-Rohdaten!D9 -> 0.052 | AE9: =Rohdaten!AG28-Rohdaten!E9 -> 0.015 | AF9: =Rohdaten!AH28-Rohdaten!F9 -> 0.065 | AG9: =Rohdaten!AI28-Rohdaten!G9 -> -0.216 | AH9: =Rohdaten!AJ28-Rohdaten!H9 -> 0.344 | AI9: =Rohdaten!AK28-Rohdaten!I9 -> 0.21 | ... AM9: =Rohdaten!AO28-Rohdaten!M9 -> 0.043
B10: =Rohdaten!B29-Rohdaten!B10 -> 0.038 | C10: =Rohdaten!C29-Rohdaten!C10 -> 0.026 | D10: =Rohdaten!D29-Rohdaten!D10 -> 0.028 | E10: =Rohdaten!E29-Rohdaten!E10 -> -0.005 | F10: =Rohdaten!F29-Rohdaten!F10 -> 0.032 | G10: =Rohdaten!G29-Rohdaten!G10 -> 0.051 | H10: =Rohdaten!H29-Rohdaten!H10 -> 0.1 | I10: =Rohdaten!I29-Rohdaten!I10 -> 0.121 | ... M10: =Rohdaten!M29-Rohdaten!M10 -> 0.029 | O10: =Rohdaten!P29-Rohdaten!B10 -> 0.039 | P10: =Rohdaten!Q29-Rohdaten!C10 -> 0.03 | Q10: =Rohdaten!R29-Rohdaten!D10 -> 0.032 | R10: =Rohdaten!S29-Rohdaten!E10 -> -0.004 | S10: =Rohdaten!T29-Rohdaten!F10 -> 0.039 | T10: =Rohdaten!U29-Rohdaten!G10 -> 0.055 | U10: =Rohdaten!V29-Rohdaten!H10 -> 0.101 | V10: =Rohdaten!W29-Rohdaten!I10 -> 0.12 | ... Z10: =Rohdaten!AA29-Rohdaten!M10 -> 0.025 | AB10: =Rohdaten!AD29-Rohdaten!B10 -> 0.037 | AC10: =Rohdaten!AE29-Rohdaten!C10 -> 0.029 | AD10: =Rohdaten!AF29-Rohdaten!D10 -> 0.033 | AE10: =Rohdaten!AG29-Rohdaten!E10 -> -0.007 | AF10: =Rohdaten!AH29-Rohdaten!F10 -> 0.041 | AG10: =Rohdaten!AI29-Rohdaten!G10 -> 0.053 | AH10: =Rohdaten!AJ29-Rohdaten!H10 -> 0.116 | AI10: =Rohdaten!AK29-Rohdaten!I10 -> 0.129 | ... AM10: =Rohdaten!AO29-Rohdaten!M10 -> 0.027
B11: =Rohdaten!B30-Rohdaten!B11 -> -0.038 | C11: =Rohdaten!C30-Rohdaten!C11 -> 0.025 | D11: =Rohdaten!D30-Rohdaten!D11 -> 0.041 | E11: =Rohdaten!E30-Rohdaten!E11 -> 0.16 | F11: =Rohdaten!F30-Rohdaten!F11 -> 0.242 | G11: =Rohdaten!G30-Rohdaten!G11 -> 0.048 | H11: =Rohdaten!H30-Rohdaten!H11 -> 0.044 | I11: =Rohdaten!I30-Rohdaten!I11 -> 0.049 | ... M11: =Rohdaten!M30-Rohdaten!M11 -> 0.175 | O11: =Rohdaten!P30-Rohdaten!B11 -> -0.044 | P11: =Rohdaten!Q30-Rohdaten!C11 -> 0.02 | Q11: =Rohdaten!R30-Rohdaten!D11 -> 0.046 | R11: =Rohdaten!S30-Rohdaten!E11 -> 0.151 | S11: =Rohdaten!T30-Rohdaten!F11 -> 0.27 | T11: =Rohdaten!U30-Rohdaten!G11 -> 0.048 | U11: =Rohdaten!V30-Rohdaten!H11 -> 0.051 | V11: =Rohdaten!W30-Rohdaten!I11 -> 0.056 | ... Z11: =Rohdaten!AA30-Rohdaten!M11 -> 0.191 | AB11: =Rohdaten!AD30-Rohdaten!B11 -> -0.044 | AC11: =Rohdaten!AE30-Rohdaten!C11 -> 0.027 | AD11: =Rohdaten!AF30-Rohdaten!D11 -> 0.041 | AE11: =Rohdaten!AG30-Rohdaten!E11 -> 0.136 | AF11: =Rohdaten!AH30-Rohdaten!F11 -> 0.239 | AG11: =Rohdaten!AI30-Rohdaten!G11 -> 0.046 | AH11: =Rohdaten!AJ30-Rohdaten!H11 -> 0.05 | AI11: =Rohdaten!AK30-Rohdaten!I11 -> 0.043 | ... AM11: =Rohdaten!AO30-Rohdaten!M11 -> 0.157
B12: =Rohdaten!B31-Rohdaten!B12 -> -0.045 | C12: =Rohdaten!C31-Rohdaten!C12 -> 0.01 | D12: =Rohdaten!D31-Rohdaten!D12 -> 0.025 | E12: =Rohdaten!E31-Rohdaten!E12 -> 0.114 | F12: =Rohdaten!F31-Rohdaten!F12 -> 0.012 | G12: =Rohdaten!G31-Rohdaten!G12 -> 0.03 | H12: =Rohdaten!H31-Rohdaten!H12 -> 0.03 | I12: =Rohdaten!I31-Rohdaten!I12 -> 0.033 | ... M12: =Rohdaten!M31-Rohdaten!M12 -> 0.032 | O12: =Rohdaten!P31-Rohdaten!B12 -> -0.05 | P12: =Rohdaten!Q31-Rohdaten!C12 -> 0.009 | Q12: =Rohdaten!R31-Rohdaten!D12 -> 0.03 | R12: =Rohdaten!S31-Rohdaten!E12 -> 0.108 | S12: =Rohdaten!T31-Rohdaten!F12 -> 0.018 | T12: =Rohdaten!U31-Rohdaten!G12 -> 0.031 | U12: =Rohdaten!V31-Rohdaten!H12 -> 0.035 | V12: =Rohdaten!W31-Rohdaten!I12 -> 0.039 | ... Z12: =Rohdaten!AA31-Rohdaten!M12 -> 0.033 | AB12: =Rohdaten!AD31-Rohdaten!B12 -> -0.05 | AC12: =Rohdaten!AE31-Rohdaten!C12 -> 0.011 | AD12: =Rohdaten!AF31-Rohdaten!D12 -> 0.026 | AE12: =Rohdaten!AG31-Rohdaten!E12 -> 0.097 | AF12: =Rohdaten!AH31-Rohdaten!F12 -> 0.017 | AG12: =Rohdaten!AI31-Rohdaten!G12 -> 0.029 | AH12: =Rohdaten!AJ31-Rohdaten!H12 -> 0.032 | AI12: =Rohdaten!AK31-Rohdaten!I12 -> 0.029 | ... AM12: =Rohdaten!AO31-Rohdaten!M12 -> 0.032
B13: =Rohdaten!B32-Rohdaten!B13 -> 0.037 | C13: =Rohdaten!C32-Rohdaten!C13 -> 0.034 | D13: =Rohdaten!D32-Rohdaten!D13 -> 0.027 | E13: =Rohdaten!E32-Rohdaten!E13 -> 0.043 | F13: =Rohdaten!F32-Rohdaten!F13 -> 0.068 | G13: =Rohdaten!G32-Rohdaten!G13 -> 0.042 | H13: =Rohdaten!H32-Rohdaten!H13 -> 0.041 | I13: =Rohdaten!I32-Rohdaten!I13 -> 0.046 | ... M13: =Rohdaten!M32-Rohdaten!M13 -> 0.017 | O13: =Rohdaten!P32-Rohdaten!B13 -> 0.048 | P13: =Rohdaten!Q32-Rohdaten!C13 -> 0.037 | Q13: =Rohdaten!R32-Rohdaten!D13 -> 0.007 | R13: =Rohdaten!S32-Rohdaten!E13 -> 0.039 | S13: =Rohdaten!T32-Rohdaten!F13 -> 0.074 | T13: =Rohdaten!U32-Rohdaten!G13 -> 0.039 | U13: =Rohdaten!V32-Rohdaten!H13 -> 0.06 | V13: =Rohdaten!W32-Rohdaten!I13 -> 0.036 | ... Z13: =Rohdaten!AA32-Rohdaten!M13 -> 0.005 | AB13: =Rohdaten!AD32-Rohdaten!B13 -> 0.034 | AC13: =Rohdaten!AE32-Rohdaten!C13 -> 0.043 | AD13: =Rohdaten!AF32-Rohdaten!D13 -> 0.014 | AE13: =Rohdaten!AG32-Rohdaten!E13 -> 0.038 | AF13: =Rohdaten!AH32-Rohdaten!F13 -> 0.077 | AG13: =Rohdaten!AI32-Rohdaten!G13 -> 0.04 | AH13: =Rohdaten!AJ32-Rohdaten!H13 -> 0.055 | AI13: =Rohdaten!AK32-Rohdaten!I13 -> 0.025 | ... AM13: =Rohdaten!AO32-Rohdaten!M13 -> 0.014
B14: =Rohdaten!B33-Rohdaten!B14 -> 0.021 | C14: =Rohdaten!C33-Rohdaten!C14 -> 0.019 | D14: =Rohdaten!D33-Rohdaten!D14 -> 0.012 | E14: =Rohdaten!E33-Rohdaten!E14 -> 0.027 | F14: =Rohdaten!F33-Rohdaten!F14 -> 0.027 | G14: =Rohdaten!G33-Rohdaten!G14 -> 0.025 | H14: =Rohdaten!H33-Rohdaten!H14 -> 0.027 | I14: =Rohdaten!I33-Rohdaten!I14 -> 0.028 | ... M14: =Rohdaten!M33-Rohdaten!M14 -> 0.005 | O14: =Rohdaten!P33-Rohdaten!B14 -> 0.029 | P14: =Rohdaten!Q33-Rohdaten!C14 -> 0.023 | Q14: =Rohdaten!R33-Rohdaten!D14 -> 0.007 | R14: =Rohdaten!S33-Rohdaten!E14 -> 0.025 | S14: =Rohdaten!T33-Rohdaten!F14 -> 0.031 | T14: =Rohdaten!U33-Rohdaten!G14 -> 0.026 | U14: =Rohdaten!V33-Rohdaten!H14 -> 0.04 | V14: =Rohdaten!W33-Rohdaten!I14 -> 0.023 | ... Z14: =Rohdaten!AA33-Rohdaten!M14 -> -0.002 | AB14: =Rohdaten!AD33-Rohdaten!B14 -> 0.019 | AC14: =Rohdaten!AE33-Rohdaten!C14 -> 0.025 | AD14: =Rohdaten!AF33-Rohdaten!D14 -> 0.011 | AE14: =Rohdaten!AG33-Rohdaten!E14 -> 0.022 | AF14: =Rohdaten!AH33-Rohdaten!F14 -> 0.032 | AG14: =Rohdaten!AI33-Rohdaten!G14 -> 0.024 | AH14: =Rohdaten!AJ33-Rohdaten!H14 -> 0.036 | AI14: =Rohdaten!AK33-Rohdaten!I14 -> 0.014 | ... AM14: =Rohdaten!AO33-Rohdaten!M14 -> 0.003
B15: =Rohdaten!B34-Rohdaten!B15 -> 0.062 | C15: =Rohdaten!C34-Rohdaten!C15 -> 0.177 | D15: =Rohdaten!D34-Rohdaten!D15 -> 0.049 | E15: =Rohdaten!E34-Rohdaten!E15 -> 0.086 | F15: =Rohdaten!F34-Rohdaten!F15 -> 0.014 | G15: =Rohdaten!G34-Rohdaten!G15 -> 0.041 | H15: =Rohdaten!H34-Rohdaten!H15 -> 0.022 | I15: =Rohdaten!I34-Rohdaten!I15 -> 0.034 | ... M15: =Rohdaten!M34-Rohdaten!M15 -> 0.02 | O15: =Rohdaten!P34-Rohdaten!B15 -> 0.033 | P15: =Rohdaten!Q34-Rohdaten!C15 -> 0.05 | Q15: =Rohdaten!R34-Rohdaten!D15 -> 0.045 | R15: =Rohdaten!S34-Rohdaten!E15 -> 0.132 | S15: =Rohdaten!T34-Rohdaten!F15 -> 0.021 | T15: =Rohdaten!U34-Rohdaten!G15 -> 0.04 | U15: =Rohdaten!V34-Rohdaten!H15 -> 0.023 | V15: =Rohdaten!W34-Rohdaten!I15 -> 0.038 | ... Z15: =Rohdaten!AA34-Rohdaten!M15 -> 0.021 | AB15: =Rohdaten!AD34-Rohdaten!B15 -> 0.044 | AC15: =Rohdaten!AE34-Rohdaten!C15 -> 0.065 | AD15: =Rohdaten!AF34-Rohdaten!D15 -> 0.042 | AE15: =Rohdaten!AG34-Rohdaten!E15 -> 0.114 | AF15: =Rohdaten!AH34-Rohdaten!F15 -> 0.024 | AG15: =Rohdaten!AI34-Rohdaten!G15 -> 0.033 | AH15: =Rohdaten!AJ34-Rohdaten!H15 -> 0.021 | AI15: =Rohdaten!AK34-Rohdaten!I15 -> 0.024 | ... AM15: =Rohdaten!AO34-Rohdaten!M15 -> 0.022
B16: =Rohdaten!B35-Rohdaten!B16 -> 0.037 | C16: =Rohdaten!C35-Rohdaten!C16 -> 0.111 | D16: =Rohdaten!D35-Rohdaten!D16 -> 0.032 | E16: =Rohdaten!E35-Rohdaten!E16 -> 0.061 | F16: =Rohdaten!F35-Rohdaten!F16 -> 0.003 | G16: =Rohdaten!G35-Rohdaten!G16 -> 0.019 | H16: =Rohdaten!H35-Rohdaten!H16 -> 0.009 | I16: =Rohdaten!I35-Rohdaten!I16 -> 0.019 | ... M16: =Rohdaten!M35-Rohdaten!M16 -> 0.005 | O16: =Rohdaten!P35-Rohdaten!B16 -> 0.019 | P16: =Rohdaten!Q35-Rohdaten!C16 -> 0.035 | Q16: =Rohdaten!R35-Rohdaten!D16 -> 0.029 | R16: =Rohdaten!S35-Rohdaten!E16 -> 0.094 | S16: =Rohdaten!T35-Rohdaten!F16 -> 0.008 | T16: =Rohdaten!U35-Rohdaten!G16 -> 0.021 | U16: =Rohdaten!V35-Rohdaten!H16 -> 0.01 | V16: =Rohdaten!W35-Rohdaten!I16 -> 0.023 | ... Z16: =Rohdaten!AA35-Rohdaten!M16 -> 0.006 | AB16: =Rohdaten!AD35-Rohdaten!B16 -> 0.026 | AC16: =Rohdaten!AE35-Rohdaten!C16 -> 0.043 | AD16: =Rohdaten!AF35-Rohdaten!D16 -> 0.026 | AE16: =Rohdaten!AG35-Rohdaten!E16 -> 0.077 | AF16: =Rohdaten!AH35-Rohdaten!F16 -> 0.008 | AG16: =Rohdaten!AI35-Rohdaten!G16 -> 0.013 | AH16: =Rohdaten!AJ35-Rohdaten!H16 -> 0.007 | AI16: =Rohdaten!AK35-Rohdaten!I16 -> 0.012 | ... AM16: =Rohdaten!AO35-Rohdaten!M16 -> 0.007
... B18: =Rohdaten!B37-Rohdaten!B18 -> -0.031 | C18: =Rohdaten!C37-Rohdaten!C18 -> -0.016 | D18: =Rohdaten!D37-Rohdaten!D18 -> 0.03 | E18: =Rohdaten!E37-Rohdaten!E18 -> 0.022 | F18: =Rohdaten!F37-Rohdaten!F18 -> 0.024 | G18: =Rohdaten!G37-Rohdaten!G18 -> 0.024 | H18: =Rohdaten!H37-Rohdaten!H18 -> 0.024 | I18: =Rohdaten!I37-Rohdaten!I18 -> 0.033 | ... M18: =Rohdaten!M37-Rohdaten!M18 -> 0.032 | O18: =Rohdaten!P37-Rohdaten!B18 -> -0.03 | P18: =Rohdaten!Q37-Rohdaten!C18 -> -0.007 | Q18: =Rohdaten!R37-Rohdaten!D18 -> 0.022 | R18: =Rohdaten!S37-Rohdaten!E18 -> 0.019 | S18: =Rohdaten!T37-Rohdaten!F18 -> 0.024 | T18: =Rohdaten!U37-Rohdaten!G18 -> 0.022 | U18: =Rohdaten!V37-Rohdaten!H18 -> 0.025 | V18: =Rohdaten!W37-Rohdaten!I18 -> 0.028 | ... Z18: =Rohdaten!AA37-Rohdaten!M18 -> 0.032 | AB18: =Rohdaten!AD37-Rohdaten!B18 -> -0.048 | AC18: =Rohdaten!AE37-Rohdaten!C18 -> -0.008 | AD18: =Rohdaten!AF37-Rohdaten!D18 -> 0.019 | AE18: =Rohdaten!AG37-Rohdaten!E18 -> 0.017 | AF18: =Rohdaten!AH37-Rohdaten!F18 -> 0.021 | AG18: =Rohdaten!AI37-Rohdaten!G18 -> 0.018 | AH18: =Rohdaten!AJ37-Rohdaten!H18 -> 0.022 | AI18: =Rohdaten!AK37-Rohdaten!I18 -> 0.024 | ... AM18: =Rohdaten!AO37-Rohdaten!M18 -> 0.027
B20: t1 | C20: - | D20: t2
B21: =Rohdaten!B41-Rohdaten!B22 -> -0.01 | C21: =Rohdaten!C41-Rohdaten!C22 -> 0.023 | D21: =Rohdaten!D41-Rohdaten!D22 -> 0.008 | E21: =Rohdaten!E41-Rohdaten!E22 -> 0.027 | F21: =Rohdaten!F41-Rohdaten!F22 -> -0.008 | G21: =Rohdaten!G41-Rohdaten!G22 -> -0.007 | H21: =Rohdaten!H41-Rohdaten!H22 -> -0.007 | I21: =Rohdaten!I41-Rohdaten!I22 -> -0.008 | ... M21: =Rohdaten!M41-Rohdaten!M22 -> -0.023 | O21: =Rohdaten!P41-Rohdaten!P22 -> -0.011 | P21: =Rohdaten!Q41-Rohdaten!Q22 -> -0.01 | Q21: =Rohdaten!R41-Rohdaten!R22 -> -0.01 | R21: =Rohdaten!S41-Rohdaten!S22 -> -0.011 | S21: =Rohdaten!T41-Rohdaten!T22 -> -0.01 | T21: =Rohdaten!U41-Rohdaten!U22 -> -0.006 | U21: =Rohdaten!V41-Rohdaten!V22 -> -0.011 | V21: =Rohdaten!W41-Rohdaten!W22 -> -0.008 | ... Z21: =Rohdaten!AA41-Rohdaten!AA22 -> -0.018 | AB21: =Rohdaten!AD41-Rohdaten!AD22 -> -0.011 | AC21: =Rohdaten!AE41-Rohdaten!AE22 -> -0.013 | AD21: =Rohdaten!AF41-Rohdaten!AF22 -> -0.011 | AE21: =Rohdaten!AG41-Rohdaten!AG22 -> 0.023 | AF21: =Rohdaten!AH41-Rohdaten!AH22 -> -0.01 | AG21: =Rohdaten!AI41-Rohdaten!AI22 -> -0.009 | AH21: =Rohdaten!AJ41-Rohdaten!AJ22 -> -0.009 | AI21: =Rohdaten!AK41-Rohdaten!AK22 -> 0.028 | ... AM21: =Rohdaten!AO41-Rohdaten!AO22 -> -0.021 | AO21: =(AB21+O21+B21)/3 -> -0.010666667
B22: =Rohdaten!B42-Rohdaten!B23 -> -0.01 | C22: =Rohdaten!C42-Rohdaten!C23 -> 0.004 | D22: =Rohdaten!D42-Rohdaten!D23 -> -0.007 | E22: =Rohdaten!E42-Rohdaten!E23 -> 0.005 | F22: =Rohdaten!F42-Rohdaten!F23 -> -0.009 | G22: =Rohdaten!G42-Rohdaten!G23 -> -0.011 | H22: =Rohdaten!H42-Rohdaten!H23 -> -0.006 | I22: =Rohdaten!I42-Rohdaten!I23 -> -0.007 | ... M22: =Rohdaten!M42-Rohdaten!M23 -> -0.019 | O22: =Rohdaten!P42-Rohdaten!P23 -> -0.011 | P22: =Rohdaten!Q42-Rohdaten!Q23 -> -0.01 | Q22: =Rohdaten!R42-Rohdaten!R23 -> -0.01 | R22: =Rohdaten!S42-Rohdaten!S23 -> -0.01 | S22: =Rohdaten!T42-Rohdaten!T23 -> -0.01 | T22: =Rohdaten!U42-Rohdaten!U23 -> -0.01 | U22: =Rohdaten!V42-Rohdaten!V23 -> -0.009 | V22: =Rohdaten!W42-Rohdaten!W23 -> -0.008 | ... Z22: =Rohdaten!AA42-Rohdaten!AA23 -> -0.019 | AB22: =Rohdaten!AD42-Rohdaten!AD23 -> -0.01 | AC22: =Rohdaten!AE42-Rohdaten!AE23 -> -0.011 | AD22: =Rohdaten!AF42-Rohdaten!AF23 -> -0.011 | AE22: =Rohdaten!AG42-Rohdaten!AG23 -> 0.007 | AF22: =Rohdaten!AH42-Rohdaten!AH23 -> -0.01 | AG22: =Rohdaten!AI42-Rohdaten!AI23 -> -0.012 | AH22: =Rohdaten!AJ42-Rohdaten!AJ23 -> -0.008 | AI22: =Rohdaten!AK42-Rohdaten!AK23 -> 0.012 | ... AM22: =Rohdaten!AO42-Rohdaten!AO23 -> -0.017 | AO22: =_xlfn.STDEV.P(AB21+O21+B21) -> 0
B23: =Rohdaten!B43-Rohdaten!B24 -> -0.01 | C23: =Rohdaten!C43-Rohdaten!C24 -> -0.006 | D23: =Rohdaten!D43-Rohdaten!D24 -> 0.015 | E23: =Rohdaten!E43-Rohdaten!E24 -> 0.047 | F23: =Rohdaten!F43-Rohdaten!F24 -> 0.031 | G23: =Rohdaten!G43-Rohdaten!G24 -> 0.223 | H23: =Rohdaten!H43-Rohdaten!H24 -> 0.12 | I23: =Rohdaten!I43-Rohdaten!I24 -> -0.007 | ... M23: =Rohdaten!M43-Rohdaten!M24 -> -0.001 | O23: =Rohdaten!P43-Rohdaten!P24 -> -0.009 | P23: =Rohdaten!Q43-Rohdaten!Q24 -> -0.004 | Q23: =Rohdaten!R43-Rohdaten!R24 -> 0.017 | R23: =Rohdaten!S43-Rohdaten!S24 -> 0.033 | S23: =Rohdaten!T43-Rohdaten!T24 -> 0.028 | T23: =Rohdaten!U43-Rohdaten!U24 -> 0.19 | U23: =Rohdaten!V43-Rohdaten!V24 -> 0.159 | V23: =Rohdaten!W43-Rohdaten!W24 -> -0.007 | ... Z23: =Rohdaten!AA43-Rohdaten!AA24 -> -0.003 | AB23: =Rohdaten!AD43-Rohdaten!AD24 -> -0.01 | AC23: =Rohdaten!AE43-Rohdaten!AE24 -> -0.006 | AD23: =Rohdaten!AF43-Rohdaten!AF24 -> 0.01 | AE23: =Rohdaten!AG43-Rohdaten!AG24 -> 0.038 | AF23: =Rohdaten!AH43-Rohdaten!AH24 -> 0.021 | AG23: =Rohdaten!AI43-Rohdaten!AI24 -> 0.184 | AH23: =Rohdaten!AJ43-Rohdaten!AJ24 -> 0.131 | AI23: =Rohdaten!AK43-Rohdaten!AK24 -> 0.03 | ... AM23: =Rohdaten!AO43-Rohdaten!AO24 -> -0.003
B24: =Rohdaten!B44-Rohdaten!B25 -> -0.01 | C24: =Rohdaten!C44-Rohdaten!C25 -> -0.007 | D24: =Rohdaten!D44-Rohdaten!D25 -> 0.004 | E24: =Rohdaten!E44-Rohdaten!E25 -> 0.015 | F24: =Rohdaten!F44-Rohdaten!F25 -> 0.002 | G24: =Rohdaten!G44-Rohdaten!G25 -> 0.068 | H24: =Rohdaten!H44-Rohdaten!H25 -> 0.061 | I24: =Rohdaten!I44-Rohdaten!I25 -> -0.007 | ... M24: =Rohdaten!M44-Rohdaten!M25 -> -0.005 | O24: =Rohdaten!P44-Rohdaten!P25 -> -0.009 | P24: =Rohdaten!Q44-Rohdaten!Q25 -> -0.003 | Q24: =Rohdaten!R44-Rohdaten!R25 -> 0.004 | R24: =Rohdaten!S44-Rohdaten!S25 -> 0.021 | S24: =Rohdaten!T44-Rohdaten!T25 -> 0.001 | T24: =Rohdaten!U44-Rohdaten!U25 -> 0.061 | U24: =Rohdaten!V44-Rohdaten!V25 -> 0.075 | V24: =Rohdaten!W44-Rohdaten!W25 -> -0.01 | ... Z24: =Rohdaten!AA44-Rohdaten!AA25 -> -0.004 | AB24: =Rohdaten!AD44-Rohdaten!AD25 -> -0.01 | AC24: =Rohdaten!AE44-Rohdaten!AE25 -> -0.007 | AD24: =Rohdaten!AF44-Rohdaten!AF25 -> 0.002 | AE24: =Rohdaten!AG44-Rohdaten!AG25 -> 0.024 | AF24: =Rohdaten!AH44-Rohdaten!AH25 -> -0.002 | AG24: =Rohdaten!AI44-Rohdaten!AI25 -> 0.043 | AH24: =Rohdaten!AJ44-Rohdaten!AJ25 -> 0.07 | AI24: =Rohdaten!AK44-Rohdaten!AK25 -> 0 | ... AM24: =Rohdaten!AO44-Rohdaten!AO25 -> -0.005
B25: =Rohdaten!B45-Rohdaten!B26 -> -0.002 | C25: =Rohdaten!C45-Rohdaten!C26 -> -0.004 | D25: =Rohdaten!D45-Rohdaten!D26 -> -0.007 | E25: =Rohdaten!E45-Rohdaten!E26 -> 0.231 | F25: =Rohdaten!F45-Rohdaten!F26 -> 0.041 | G25: =Rohdaten!G45-Rohdaten!G26 -> 0.013 | H25: =Rohdaten!H45-Rohdaten!H26 -> -0.008 | I25: =Rohdaten!I45-Rohdaten!I26 -> 0.054 | ... M25: =Rohdaten!M45-Rohdaten!M26 -> 0.237 | O25: =Rohdaten!P45-Rohdaten!P26 -> -0.002 | P25: =Rohdaten!Q45-Rohdaten!Q26 -> -0.003 | Q25: =Rohdaten!R45-Rohdaten!R26 -> 0.021 | R25: =Rohdaten!S45-Rohdaten!S26 -> 0.283 | S25: =Rohdaten!T45-Rohdaten!T26 -> 0.063 | T25: =Rohdaten!U45-Rohdaten!U26 -> -0.011 | U25: =Rohdaten!V45-Rohdaten!V26 -> -0.008 | V25: =Rohdaten!W45-Rohdaten!W26 -> 0.057 | ... Z25: =Rohdaten!AA45-Rohdaten!AA26 -> 0.24 | AB25: =Rohdaten!AD45-Rohdaten!AD26 -> -0.002 | AC25: =Rohdaten!AE45-Rohdaten!AE26 -> -0.005 | AD25: =Rohdaten!AF45-Rohdaten!AF26 -> -0.007 | AE25: =Rohdaten!AG45-Rohdaten!AG26 -> 0.217 | AF25: =Rohdaten!AH45-Rohdaten!AH26 -> 0.178 | AG25: =Rohdaten!AI45-Rohdaten!AI26 -> -0.011 | AH25: =Rohdaten!AJ45-Rohdaten!AJ26 -> -0.009 | AI25: =Rohdaten!AK45-Rohdaten!AK26 -> 0.034 | ... AM25: =Rohdaten!AO45-Rohdaten!AO26 -> 0.285
B26: =Rohdaten!B46-Rohdaten!B27 -> -0.008 | C26: =Rohdaten!C46-Rohdaten!C27 -> -0.005 | D26: =Rohdaten!D46-Rohdaten!D27 -> -0.007 | E26: =Rohdaten!E46-Rohdaten!E27 -> 0.11 | F26: =Rohdaten!F46-Rohdaten!F27 -> 0.019 | G26: =Rohdaten!G46-Rohdaten!G27 -> -0.001 | H26: =Rohdaten!H46-Rohdaten!H27 -> -0.008 | I26: =Rohdaten!I46-Rohdaten!I27 -> -0.002 | ... M26: =Rohdaten!M46-Rohdaten!M27 -> 0.138 | O26: =Rohdaten!P46-Rohdaten!P27 -> -0.008 | P26: =Rohdaten!Q46-Rohdaten!Q27 -> -0.005 | Q26: =Rohdaten!R46-Rohdaten!R27 -> 0.003 | R26: =Rohdaten!S46-Rohdaten!S27 -> 0.092 | S26: =Rohdaten!T46-Rohdaten!T27 -> 0.032 | T26: =Rohdaten!U46-Rohdaten!U27 -> -0.011 | U26: =Rohdaten!V46-Rohdaten!V27 -> -0.009 | V26: =Rohdaten!W46-Rohdaten!W27 -> 0 | ... Z26: =Rohdaten!AA46-Rohdaten!AA27 -> 0.136 | AB26: =Rohdaten!AD46-Rohdaten!AD27 -> -0.008 | AC26: =Rohdaten!AE46-Rohdaten!AE27 -> -0.006 | AD26: =Rohdaten!AF46-Rohdaten!AF27 -> -0.008 | AE26: =Rohdaten!AG46-Rohdaten!AG27 -> 0.098 | AF26: =Rohdaten!AH46-Rohdaten!AH27 -> 0.11 | AG26: =Rohdaten!AI46-Rohdaten!AI27 -> -0.011 | AH26: =Rohdaten!AJ46-Rohdaten!AJ27 -> -0.009 | AI26: =Rohdaten!AK46-Rohdaten!AK27 -> 0 | ... AM26: =Rohdaten!AO46-Rohdaten!AO27 -> 0.173
B27: =Rohdaten!B47-Rohdaten!B28 -> 0.075 | C27: =Rohdaten!C47-Rohdaten!C28 -> -0.004 | D27: =Rohdaten!D47-Rohdaten!D28 -> -0.006 | E27: =Rohdaten!E47-Rohdaten!E28 -> -0.002 | F27: =Rohdaten!F47-Rohdaten!F28 -> -0.007 | G27: =Rohdaten!G47-Rohdaten!G28 -> 0.023 | H27: =Rohdaten!H47-Rohdaten!H28 -> 0.148 | I27: =Rohdaten!I47-Rohdaten!I28 -> 0.271 | ... M27: =Rohdaten!M47-Rohdaten!M28 -> -0.011 | O27: =Rohdaten!P47-Rohdaten!P28 -> -0.012 | P27: =Rohdaten!Q47-Rohdaten!Q28 -> -0.005 | Q27: =Rohdaten!R47-Rohdaten!R28 -> 0 | R27: =Rohdaten!S47-Rohdaten!S28 -> -0.002 | S27: =Rohdaten!T47-Rohdaten!T28 -> 0.023 | T27: =Rohdaten!U47-Rohdaten!U28 -> 0.022 | U27: =Rohdaten!V47-Rohdaten!V28 -> 0.219 | V27: =Rohdaten!W47-Rohdaten!W28 -> 0.244 | ... Z27: =Rohdaten!AA47-Rohdaten!AA28 -> -0.009 | AB27: =Rohdaten!AD47-Rohdaten!AD28 -> -0.012 | AC27: =Rohdaten!AE47-Rohdaten!AE28 -> -0.006 | AD27: =Rohdaten!AF47-Rohdaten!AF28 -> 0.042 | AE27: =Rohdaten!AG47-Rohdaten!AG28 -> -0.004 | AF27: =Rohdaten!AH47-Rohdaten!AH28 -> -0.01 | AG27: =Rohdaten!AI47-Rohdaten!AI28 -> 0.082 | AH27: =Rohdaten!AJ47-Rohdaten!AJ28 -> 0.126 | AI27: =Rohdaten!AK47-Rohdaten!AK28 -> 0.196 | ... AM27: =Rohdaten!AO47-Rohdaten!AO28 -> -0.011
B28: =Rohdaten!B48-Rohdaten!B29 -> 0.02 | C28: =Rohdaten!C48-Rohdaten!C29 -> -0.003 | D28: =Rohdaten!D48-Rohdaten!D29 -> -0.006 | E28: =Rohdaten!E48-Rohdaten!E29 -> -0.007 | F28: =Rohdaten!F48-Rohdaten!F29 -> -0.007 | G28: =Rohdaten!G48-Rohdaten!G29 -> 0.005 | H28: =Rohdaten!H48-Rohdaten!H29 -> 0.056 | I28: =Rohdaten!I48-Rohdaten!I29 -> 0.078 | ... M28: =Rohdaten!M48-Rohdaten!M29 -> -0.01 | O28: =Rohdaten!P48-Rohdaten!P29 -> -0.012 | P28: =Rohdaten!Q48-Rohdaten!Q29 -> -0.007 | Q28: =Rohdaten!R48-Rohdaten!R29 -> -0.005 | R28: =Rohdaten!S48-Rohdaten!S29 -> -0.009 | S28: =Rohdaten!T48-Rohdaten!T29 -> 0.005 | T28: =Rohdaten!U48-Rohdaten!U29 -> 0.003 | U28: =Rohdaten!V48-Rohdaten!V29 -> 0.078 | V28: =Rohdaten!W48-Rohdaten!W29 -> 0.115 | ... Z28: =Rohdaten!AA48-Rohdaten!AA29 -> -0.01 | AB28: =Rohdaten!AD48-Rohdaten!AD29 -> -0.012 | AC28: =Rohdaten!AE48-Rohdaten!AE29 -> -0.007 | AD28: =Rohdaten!AF48-Rohdaten!AF29 -> 0.013 | AE28: =Rohdaten!AG48-Rohdaten!AG29 -> -0.009 | AF28: =Rohdaten!AH48-Rohdaten!AH29 -> -0.009 | AG28: =Rohdaten!AI48-Rohdaten!AI29 -> 0.002 | AH28: =Rohdaten!AJ48-Rohdaten!AJ29 -> 0.029 | AI28: =Rohdaten!AK48-Rohdaten!AK29 -> 0.081 | ... AM28: =Rohdaten!AO48-Rohdaten!AO29 -> -0.01
B29: =Rohdaten!B49-Rohdaten!B30 -> 0.005 | C29: =Rohdaten!C49-Rohdaten!C30 -> -0.003 | D29: =Rohdaten!D49-Rohdaten!D30 -> -0.005 | E29: =Rohdaten!E49-Rohdaten!E30 -> 0.047 | F29: =Rohdaten!F49-Rohdaten!F30 -> 0.016 | G29: =Rohdaten!G49-Rohdaten!G30 -> -0.006 | H29: =Rohdaten!H49-Rohdaten!H30 -> -0.007 | I29: =Rohdaten!I49-Rohdaten!I30 -> -0.003 | ... M29: =Rohdaten!M49-Rohdaten!M30 -> 0.06 | O29: =Rohdaten!P49-Rohdaten!P30 -> 0 | P29: =Rohdaten!Q49-Rohdaten!Q30 -> -0.001 | Q29: =Rohdaten!R49-Rohdaten!R30 -> -0.006 | R29: =Rohdaten!S49-Rohdaten!S30 -> 0.008 | S29: =Rohdaten!T49-Rohdaten!T30 -> 0.015 | T29: =Rohdaten!U49-Rohdaten!U30 -> -0.006 | U29: =Rohdaten!V49-Rohdaten!V30 -> -0.006 | V29: =Rohdaten!W49-Rohdaten!W30 -> -0.009 | ... Z29: =Rohdaten!AA49-Rohdaten!AA30 -> 0.062 | AB29: =Rohdaten!AD49-Rohdaten!AD30 -> 0.002 | AC29: =Rohdaten!AE49-Rohdaten!AE30 -> -0.002 | AD29: =Rohdaten!AF49-Rohdaten!AF30 -> 0.157 | AE29: =Rohdaten!AG49-Rohdaten!AG30 -> 0.042 | AF29: =Rohdaten!AH49-Rohdaten!AH30 -> 0.016 | AG29: =Rohdaten!AI49-Rohdaten!AI30 -> -0.008 | AH29: =Rohdaten!AJ49-Rohdaten!AJ30 -> -0.008 | AI29: =Rohdaten!AK49-Rohdaten!AK30 -> 0.365 | ... AM29: =Rohdaten!AO49-Rohdaten!AO30 -> 0.058
B30: =Rohdaten!B50-Rohdaten!B31 -> 0.003 | C30: =Rohdaten!C50-Rohdaten!C31 -> -0.002 | D30: =Rohdaten!D50-Rohdaten!D31 -> -0.005 | E30: =Rohdaten!E50-Rohdaten!E31 -> 0.038 | F30: =Rohdaten!F50-Rohdaten!F31 -> -0.002 | G30: =Rohdaten!G50-Rohdaten!G31 -> -0.006 | H30: =Rohdaten!H50-Rohdaten!H31 -> -0.006 | I30: =Rohdaten!I50-Rohdaten!I31 -> -0.007 | ... M30: =Rohdaten!M50-Rohdaten!M31 -> -0.005 | O30: =Rohdaten!P50-Rohdaten!P31 -> 0 | P30: =Rohdaten!Q50-Rohdaten!Q31 -> -0.004 | Q30: =Rohdaten!R50-Rohdaten!R31 -> -0.007 | R30: =Rohdaten!S50-Rohdaten!S31 -> 0.006 | S30: =Rohdaten!T50-Rohdaten!T31 -> -0.003 | T30: =Rohdaten!U50-Rohdaten!U31 -> -0.007 | U30: =Rohdaten!V50-Rohdaten!V31 -> -0.007 | V30: =Rohdaten!W50-Rohdaten!W31 -> -0.009 | ... Z30: =Rohdaten!AA50-Rohdaten!AA31 -> -0.004 | AB30: =Rohdaten!AD50-Rohdaten!AD31 -> 0.002 | AC30: =Rohdaten!AE50-Rohdaten!AE31 -> -0.003 | AD30: =Rohdaten!AF50-Rohdaten!AF31 -> 0.043 | AE30: =Rohdaten!AG50-Rohdaten!AG31 -> 0.018 | AF30: =Rohdaten!AH50-Rohdaten!AH31 -> -0.004 | AG30: =Rohdaten!AI50-Rohdaten!AI31 -> -0.008 | AH30: =Rohdaten!AJ50-Rohdaten!AJ31 -> -0.007 | AI30: =Rohdaten!AK50-Rohdaten!AK31 -> 0.1 | ... AM30: =Rohdaten!AO50-Rohdaten!AO31 -> -0.005
B31: =Rohdaten!B51-Rohdaten!B32 -> -0.01 | C31: =Rohdaten!C51-Rohdaten!C32 -> -0.005 | D31: =Rohdaten!D51-Rohdaten!D32 -> -0.005 | E31: =Rohdaten!E51-Rohdaten!E32 -> -0.007 | F31: =Rohdaten!F51-Rohdaten!F32 -> 0.122 | G31: =Rohdaten!G51-Rohdaten!G32 -> -0.009 | H31: =Rohdaten!H51-Rohdaten!H32 -> -0.006 | I31: =Rohdaten!I51-Rohdaten!I32 -> -0.008 | ... M31: =Rohdaten!M51-Rohdaten!M32 -> 0.505 | O31: =Rohdaten!P51-Rohdaten!P32 -> 0.172 | P31: =Rohdaten!Q51-Rohdaten!Q32 -> -0.006 | Q31: =Rohdaten!R51-Rohdaten!R32 -> -0.004 | R31: =Rohdaten!S51-Rohdaten!S32 -> -0.005 | S31: =Rohdaten!T51-Rohdaten!T32 -> 0.024 | T31: =Rohdaten!U51-Rohdaten!U32 -> -0.006 | U31: =Rohdaten!V51-Rohdaten!V32 -> -0.008 | V31: =Rohdaten!W51-Rohdaten!W32 -> -0.007 | ... Z31: =Rohdaten!AA51-Rohdaten!AA32 -> -0.008 | AB31: =Rohdaten!AD51-Rohdaten!AD32 -> -0.011 | AC31: =Rohdaten!AE51-Rohdaten!AE32 -> -0.007 | AD31: =Rohdaten!AF51-Rohdaten!AF32 -> 0.062 | AE31: =Rohdaten!AG51-Rohdaten!AG32 -> -0.006 | AF31: =Rohdaten!AH51-Rohdaten!AH32 -> 0.006 | AG31: =Rohdaten!AI51-Rohdaten!AI32 -> 0.023 | AH31: =Rohdaten!AJ51-Rohdaten!AJ32 -> 0.025 | AI31: =Rohdaten!AK51-Rohdaten!AK32 -> -0.007 | ... AM31: =Rohdaten!AO51-Rohdaten!AO32 -> -0.011
B32: =Rohdaten!B52-Rohdaten!B33 -> -0.009 | C32: =Rohdaten!C52-Rohdaten!C33 -> -0.006 | D32: =Rohdaten!D52-Rohdaten!D33 -> -0.004 | E32: =Rohdaten!E52-Rohdaten!E33 -> -0.006 | F32: =Rohdaten!F52-Rohdaten!F33 -> 0.04 | G32: =Rohdaten!G52-Rohdaten!G33 -> -0.007 | H32: =Rohdaten!H52-Rohdaten!H33 -> -0.005 | I32: =Rohdaten!I52-Rohdaten!I33 -> -0.008 | ... M32: =Rohdaten!M52-Rohdaten!M33 -> 0.115 | O32: =Rohdaten!P52-Rohdaten!P33 -> 0.053 | P32: =Rohdaten!Q52-Rohdaten!Q33 -> -0.008 | Q32: =Rohdaten!R52-Rohdaten!R33 -> -0.004 | R32: =Rohdaten!S52-Rohdaten!S33 -> -0.005 | S32: =Rohdaten!T52-Rohdaten!T33 -> -0.006 | T32: =Rohdaten!U52-Rohdaten!U33 -> -0.006 | U32: =Rohdaten!V52-Rohdaten!V33 -> -0.008 | V32: =Rohdaten!W52-Rohdaten!W33 -> -0.008 | ... Z32: =Rohdaten!AA52-Rohdaten!AA33 -> -0.008 | AB32: =Rohdaten!AD52-Rohdaten!AD33 -> -0.01 | AC32: =Rohdaten!AE52-Rohdaten!AE33 -> -0.007 | AD32: =Rohdaten!AF52-Rohdaten!AF33 -> 0.02 | AE32: =Rohdaten!AG52-Rohdaten!AG33 -> -0.006 | AF32: =Rohdaten!AH52-Rohdaten!AH33 -> -0.007 | AG32: =Rohdaten!AI52-Rohdaten!AI33 -> -0.007 | AH32: =Rohdaten!AJ52-Rohdaten!AJ33 -> 0.006 | AI32: =Rohdaten!AK52-Rohdaten!AK33 -> -0.007 | ... AM32: =Rohdaten!AO52-Rohdaten!AO33 -> -0.01
B33: =Rohdaten!B53-Rohdaten!B34 -> 0.008 | C33: =Rohdaten!C53-Rohdaten!C34 -> 0.067 | D33: =Rohdaten!D53-Rohdaten!D34 -> 0.106 | E33: =Rohdaten!E53-Rohdaten!E34 -> 0.026 | F33: =Rohdaten!F53-Rohdaten!F34 -> -0.003 | G33: =Rohdaten!G53-Rohdaten!G34 -> -0.006 | H33: =Rohdaten!H53-Rohdaten!H34 -> -0.004 | I33: =Rohdaten!I53-Rohdaten!I34 -> -0.005 | ... M33: =Rohdaten!M53-Rohdaten!M34 -> -0.005 | O33: =Rohdaten!P53-Rohdaten!P34 -> -0.007 | P33: =Rohdaten!Q53-Rohdaten!Q34 -> -0.002 | Q33: =Rohdaten!R53-Rohdaten!R34 -> -0.006 | R33: =Rohdaten!S53-Rohdaten!S34 -> 0.022 | S33: =Rohdaten!T53-Rohdaten!T34 -> -0.004 | T33: =Rohdaten!U53-Rohdaten!U34 -> -0.006 | U33: =Rohdaten!V53-Rohdaten!V34 -> 0.004 | V33: =Rohdaten!W53-Rohdaten!W34 -> 0.031 | ... Z33: =Rohdaten!AA53-Rohdaten!AA34 -> -0.004 | AB33: =Rohdaten!AD53-Rohdaten!AD34 -> -0.01 | AC33: =Rohdaten!AE53-Rohdaten!AE34 -> 0.063 | AD33: =Rohdaten!AF53-Rohdaten!AF34 -> -0.007 | AE33: =Rohdaten!AG53-Rohdaten!AG34 -> 0.035 | AF33: =Rohdaten!AH53-Rohdaten!AH34 -> 0.076 | AG33: =Rohdaten!AI53-Rohdaten!AI34 -> -0.007 | AH33: =Rohdaten!AJ53-Rohdaten!AJ34 -> -0.004 | AI33: =Rohdaten!AK53-Rohdaten!AK34 -> 0.06 | ... AM33: =Rohdaten!AO53-Rohdaten!AO34 -> 0.038
B34: =Rohdaten!B54-Rohdaten!B35 -> -0.006 | C34: =Rohdaten!C54-Rohdaten!C35 -> 0.01 | D34: =Rohdaten!D54-Rohdaten!D35 -> 0.032 | E34: =Rohdaten!E54-Rohdaten!E35 -> 0.008 | F34: =Rohdaten!F54-Rohdaten!F35 -> -0.002 | G34: =Rohdaten!G54-Rohdaten!G35 -> -0.001 | H34: =Rohdaten!H54-Rohdaten!H35 -> -0.003 | I34: =Rohdaten!I54-Rohdaten!I35 -> -0.005 | ... M34: =Rohdaten!M54-Rohdaten!M35 -> -0.005 | O34: =Rohdaten!P54-Rohdaten!P35 -> -0.007 | P34: =Rohdaten!Q54-Rohdaten!Q35 -> -0.005 | Q34: =Rohdaten!R54-Rohdaten!R35 -> -0.005 | R34: =Rohdaten!S54-Rohdaten!S35 -> 0.01 | S34: =Rohdaten!T54-Rohdaten!T35 -> -0.004 | T34: =Rohdaten!U54-Rohdaten!U35 -> -0.005 | U34: =Rohdaten!V54-Rohdaten!V35 -> 0.004 | V34: =Rohdaten!W54-Rohdaten!W35 -> 0.007 | ... Z34: =Rohdaten!AA54-Rohdaten!AA35 -> -0.004 | AB34: =Rohdaten!AD54-Rohdaten!AD35 -> -0.009 | AC34: =Rohdaten!AE54-Rohdaten!AE35 -> 0.016 | AD34: =Rohdaten!AF54-Rohdaten!AF35 -> -0.007 | AE34: =Rohdaten!AG54-Rohdaten!AG35 -> 0.013 | AF34: =Rohdaten!AH54-Rohdaten!AH35 -> 0.025 | AG34: =Rohdaten!AI54-Rohdaten!AI35 -> -0.003 | AH34: =Rohdaten!AJ54-Rohdaten!AJ35 -> -0.004 | AI34: =Rohdaten!AK54-Rohdaten!AK35 -> 0.022 | ... AM34: =Rohdaten!AO54-Rohdaten!AO35 -> 0.011
... B36: =Rohdaten!B56-Rohdaten!B37 -> 0.03 | C36: =Rohdaten!C56-Rohdaten!C37 -> -0.004 | D36: =Rohdaten!D56-Rohdaten!D37 -> -0.009 | E36: =Rohdaten!E56-Rohdaten!E37 -> -0.006 | F36: =Rohdaten!F56-Rohdaten!F37 -> -0.008 | G36: =Rohdaten!G56-Rohdaten!G37 -> -0.008 | H36: =Rohdaten!H56-Rohdaten!H37 -> -0.007 | I36: =Rohdaten!I56-Rohdaten!I37 -> -0.009 | ... M36: =Rohdaten!M56-Rohdaten!M37 -> -0.012 | O36: =Rohdaten!P56-Rohdaten!P37 -> 0.025 | P36: =Rohdaten!Q56-Rohdaten!Q37 -> -0.004 | Q36: =Rohdaten!R56-Rohdaten!R37 -> -0.006 | R36: =Rohdaten!S56-Rohdaten!S37 -> -0.004 | S36: =Rohdaten!T56-Rohdaten!T37 -> -0.006 | T36: =Rohdaten!U56-Rohdaten!U37 -> -0.007 | U36: =Rohdaten!V56-Rohdaten!V37 -> 0.01 | V36: =Rohdaten!W56-Rohdaten!W37 -> -0.007 | ... Z36: =Rohdaten!AA56-Rohdaten!AA37 -> -0.008 | AB36: =Rohdaten!AD56-Rohdaten!AD37 -> 0.025 | AC36: =Rohdaten!AE56-Rohdaten!AE37 -> -0.005 | AD36: =Rohdaten!AF56-Rohdaten!AF37 -> 0.298 | AE36: =Rohdaten!AG56-Rohdaten!AG37 -> -0.001 | AF36: =Rohdaten!AH56-Rohdaten!AH37 -> -0.008 | AG36: =Rohdaten!AI56-Rohdaten!AI37 -> -0.008 | AH36: =Rohdaten!AJ56-Rohdaten!AJ37 -> -0.009 | AI36: =Rohdaten!AK56-Rohdaten!AK37 -> 0.011 | ... AM36: =Rohdaten!AO56-Rohdaten!AO37 -> -0.012
B38: t2 | C38: - | D38: t3
B39: =Rohdaten!B60-Rohdaten!B41 -> -0.002 | C39: =Rohdaten!C60-Rohdaten!C41 -> -0.001 | D39: =Rohdaten!D60-Rohdaten!D41 -> 0.009 | E39: =Rohdaten!E60-Rohdaten!E41 -> 0.022 | F39: =Rohdaten!F60-Rohdaten!F41 -> -0.002 | G39: =Rohdaten!G60-Rohdaten!G41 -> -0.002 | H39: =Rohdaten!H60-Rohdaten!H41 -> -0.002 | I39: =Rohdaten!I60-Rohdaten!I41 -> -0.001 | ... M39: =Rohdaten!M60-Rohdaten!M41 -> -0.005 | O39: =Rohdaten!P60-Rohdaten!P41 -> -0.002 | P39: =Rohdaten!Q60-Rohdaten!Q41 -> -0.002 | Q39: =Rohdaten!R60-Rohdaten!R41 -> -0.002 | R39: =Rohdaten!S60-Rohdaten!S41 -> -0.001 | S39: =Rohdaten!T60-Rohdaten!T41 -> -0.002 | T39: =Rohdaten!U60-Rohdaten!U41 -> 0.001 | U39: =Rohdaten!V60-Rohdaten!V41 -> -0.001 | V39: =Rohdaten!W60-Rohdaten!W41 -> -0.003 | ... Z39: =Rohdaten!AA60-Rohdaten!AA41 -> -0.003 | AB39: =Rohdaten!AD60-Rohdaten!AD41 -> -0.002 | AC39: =Rohdaten!AE60-Rohdaten!AE41 -> -0.002 | AD39: =Rohdaten!AF60-Rohdaten!AF41 -> -0.002 | AE39: =Rohdaten!AG60-Rohdaten!AG41 -> 0.008 | AF39: =Rohdaten!AH60-Rohdaten!AH41 -> -0.002 | AG39: =Rohdaten!AI60-Rohdaten!AI41 -> -0.002 | AH39: =Rohdaten!AJ60-Rohdaten!AJ41 -> -0.003 | AI39: =Rohdaten!AK60-Rohdaten!AK41 -> 0.033 | ... AM39: =Rohdaten!AO60-Rohdaten!AO41 -> 0.004
B40: =Rohdaten!B61-Rohdaten!B42 -> -0.002 | C40: =Rohdaten!C61-Rohdaten!C42 -> -0.001 | D40: =Rohdaten!D61-Rohdaten!D42 -> 0.002 | E40: =Rohdaten!E61-Rohdaten!E42 -> 0.007 | F40: =Rohdaten!F61-Rohdaten!F42 -> -0.001 | G40: =Rohdaten!G61-Rohdaten!G42 -> -0.002 | H40: =Rohdaten!H61-Rohdaten!H42 -> -0.002 | I40: =Rohdaten!I61-Rohdaten!I42 -> -0.001 | ... M40: =Rohdaten!M61-Rohdaten!M42 -> -0.003 | O40: =Rohdaten!P61-Rohdaten!P42 -> -0.001 | P40: =Rohdaten!Q61-Rohdaten!Q42 -> -0.001 | Q40: =Rohdaten!R61-Rohdaten!R42 -> -0.001 | R40: =Rohdaten!S61-Rohdaten!S42 -> -0.002 | S40: =Rohdaten!T61-Rohdaten!T42 -> -0.002 | T40: =Rohdaten!U61-Rohdaten!U42 -> 0 | U40: =Rohdaten!V61-Rohdaten!V42 -> -0.001 | V40: =Rohdaten!W61-Rohdaten!W42 -> -0.002 | ... Z40: =Rohdaten!AA61-Rohdaten!AA42 -> -0.003 | AB40: =Rohdaten!AD61-Rohdaten!AD42 -> -0.002 | AC40: =Rohdaten!AE61-Rohdaten!AE42 -> -0.001 | AD40: =Rohdaten!AF61-Rohdaten!AF42 -> -0.002 | AE40: =Rohdaten!AG61-Rohdaten!AG42 -> -0.001 | AF40: =Rohdaten!AH61-Rohdaten!AH42 -> -0.001 | AG40: =Rohdaten!AI61-Rohdaten!AI42 -> -0.003 | AH40: =Rohdaten!AJ61-Rohdaten!AJ42 -> -0.002 | AI40: =Rohdaten!AK61-Rohdaten!AK42 -> 0.012 | ... AM40: =Rohdaten!AO61-Rohdaten!AO42 -> 0
B41: =Rohdaten!B62-Rohdaten!B43 -> -0.002 | C41: =Rohdaten!C62-Rohdaten!C43 -> -0.001 | D41: =Rohdaten!D62-Rohdaten!D43 -> 0.003 | E41: =Rohdaten!E62-Rohdaten!E43 -> 0.013 | F41: =Rohdaten!F62-Rohdaten!F43 -> 0.004 | G41: =Rohdaten!G62-Rohdaten!G43 -> 0.034 | H41: =Rohdaten!H62-Rohdaten!H43 -> 0.01 | I41: =Rohdaten!I62-Rohdaten!I43 -> 0.002 | ... M41: =Rohdaten!M62-Rohdaten!M43 -> -0.001 | O41: =Rohdaten!P62-Rohdaten!P43 -> -0.002 | P41: =Rohdaten!Q62-Rohdaten!Q43 -> -0.001 | Q41: =Rohdaten!R62-Rohdaten!R43 -> 0.003 | R41: =Rohdaten!S62-Rohdaten!S43 -> 0.009 | S41: =Rohdaten!T62-Rohdaten!T43 -> 0.005 | T41: =Rohdaten!U62-Rohdaten!U43 -> 0.039 | U41: =Rohdaten!V62-Rohdaten!V43 -> 0.025 | V41: =Rohdaten!W62-Rohdaten!W43 -> -0.001 | ... Z41: =Rohdaten!AA62-Rohdaten!AA43 -> 0 | AB41: =Rohdaten!AD62-Rohdaten!AD43 -> -0.002 | AC41: =Rohdaten!AE62-Rohdaten!AE43 -> -0.001 | AD41: =Rohdaten!AF62-Rohdaten!AF43 -> 0.001 | AE41: =Rohdaten!AG62-Rohdaten!AG43 -> 0.01 | AF41: =Rohdaten!AH62-Rohdaten!AH43 -> 0.002 | AG41: =Rohdaten!AI62-Rohdaten!AI43 -> 0.032 | AH41: =Rohdaten!AJ62-Rohdaten!AJ43 -> 0.006 | AI41: =Rohdaten!AK62-Rohdaten!AK43 -> -0.002 | ... AM41: =Rohdaten!AO62-Rohdaten!AO43 -> -0.001
B42: =Rohdaten!B63-Rohdaten!B44 -> -0.001 | C42: =Rohdaten!C63-Rohdaten!C44 -> -0.001 | D42: =Rohdaten!D63-Rohdaten!D44 -> 0.001 | E42: =Rohdaten!E63-Rohdaten!E44 -> 0.005 | F42: =Rohdaten!F63-Rohdaten!F44 -> 0 | G42: =Rohdaten!G63-Rohdaten!G44 -> 0.01 | H42: =Rohdaten!H63-Rohdaten!H44 -> 0.003 | I42: =Rohdaten!I63-Rohdaten!I44 -> 0.002 | ... M42: =Rohdaten!M63-Rohdaten!M44 -> 0 | O42: =Rohdaten!P63-Rohdaten!P44 -> -0.002 | P42: =Rohdaten!Q63-Rohdaten!Q44 -> -0.002 | Q42: =Rohdaten!R63-Rohdaten!R44 -> 0.001 | R42: =Rohdaten!S63-Rohdaten!S44 -> 0.004 | S42: =Rohdaten!T63-Rohdaten!T44 -> 0.001 | T42: =Rohdaten!U63-Rohdaten!U44 -> 0.018 | U42: =Rohdaten!V63-Rohdaten!V44 -> 0.015 | V42: =Rohdaten!W63-Rohdaten!W44 -> -0.001 | ... Z42: =Rohdaten!AA63-Rohdaten!AA44 -> -0.001 | AB42: =Rohdaten!AD63-Rohdaten!AD44 -> -0.001 | AC42: =Rohdaten!AE63-Rohdaten!AE44 -> -0.001 | AD42: =Rohdaten!AF63-Rohdaten!AF44 -> 0 | AE42: =Rohdaten!AG63-Rohdaten!AG44 -> 0.005 | AF42: =Rohdaten!AH63-Rohdaten!AH44 -> 0 | AG42: =Rohdaten!AI63-Rohdaten!AI44 -> 0.013 | AH42: =Rohdaten!AJ63-Rohdaten!AJ44 -> 0.003 | AI42: =Rohdaten!AK63-Rohdaten!AK44 -> -0.001 | ... AM42: =Rohdaten!AO63-Rohdaten!AO44 -> -0.001
B43: =Rohdaten!B64-Rohdaten!B45 -> 0.003 | C43: =Rohdaten!C64-Rohdaten!C45 -> -0.001 | D43: =Rohdaten!D64-Rohdaten!D45 -> -0.001 | E43: =Rohdaten!E64-Rohdaten!E45 -> 0.033 | F43: =Rohdaten!F64-Rohdaten!F45 -> 0.017 | G43: =Rohdaten!G64-Rohdaten!G45 -> 0.015 | H43: =Rohdaten!H64-Rohdaten!H45 -> -0.001 | I43: =Rohdaten!I64-Rohdaten!I45 -> 0.005 | ... M43: =Rohdaten!M64-Rohdaten!M45 -> 0.015 | O43: =Rohdaten!P64-Rohdaten!P45 -> -0.002 | P43: =Rohdaten!Q64-Rohdaten!Q45 -> -0.001 | Q43: =Rohdaten!R64-Rohdaten!R45 -> -0.002 | R43: =Rohdaten!S64-Rohdaten!S45 -> -0.042 | S43: =Rohdaten!T64-Rohdaten!T45 -> 0.008 | T43: =Rohdaten!U64-Rohdaten!U45 -> -0.002 | U43: =Rohdaten!V64-Rohdaten!V45 -> -0.001 | V43: =Rohdaten!W64-Rohdaten!W45 -> 0.005 | ... Z43: =Rohdaten!AA64-Rohdaten!AA45 -> 0.026 | AB43: =Rohdaten!AD64-Rohdaten!AD45 -> 0.003 | AC43: =Rohdaten!AE64-Rohdaten!AE45 -> -0.001 | AD43: =Rohdaten!AF64-Rohdaten!AF45 -> -0.001 | AE43: =Rohdaten!AG64-Rohdaten!AG45 -> 0.037 | AF43: =Rohdaten!AH64-Rohdaten!AH45 -> -0.013 | AG43: =Rohdaten!AI64-Rohdaten!AI45 -> -0.001 | AH43: =Rohdaten!AJ64-Rohdaten!AJ45 -> 0.006 | AI43: =Rohdaten!AK64-Rohdaten!AK45 -> 0.002 | ... AM43: =Rohdaten!AO64-Rohdaten!AO45 -> 0.031
B44: =Rohdaten!B65-Rohdaten!B46 -> -0.001 | C44: =Rohdaten!C65-Rohdaten!C46 -> -0.001 | D44: =Rohdaten!D65-Rohdaten!D46 -> -0.001 | E44: =Rohdaten!E65-Rohdaten!E46 -> 0.018 | F44: =Rohdaten!F65-Rohdaten!F46 -> 0.006 | G44: =Rohdaten!G65-Rohdaten!G46 -> 0.005 | H44: =Rohdaten!H65-Rohdaten!H46 -> -0.002 | I44: =Rohdaten!I65-Rohdaten!I46 -> 0.001 | ... M44: =Rohdaten!M65-Rohdaten!M46 -> 0.006 | O44: =Rohdaten!P65-Rohdaten!P46 -> -0.001 | P44: =Rohdaten!Q65-Rohdaten!Q46 -> -0.001 | Q44: =Rohdaten!R65-Rohdaten!R46 -> -0.001 | R44: =Rohdaten!S65-Rohdaten!S46 -> 0.017 | S44: =Rohdaten!T65-Rohdaten!T46 -> 0.003 | T44: =Rohdaten!U65-Rohdaten!U46 -> -0.002 | U44: =Rohdaten!V65-Rohdaten!V46 -> -0.002 | V44: =Rohdaten!W65-Rohdaten!W46 -> 0.001 | ... Z44: =Rohdaten!AA65-Rohdaten!AA46 -> 0.014 | AB44: =Rohdaten!AD65-Rohdaten!AD46 -> -0.001 | AC44: =Rohdaten!AE65-Rohdaten!AE46 -> -0.001 | AD44: =Rohdaten!AF65-Rohdaten!AF46 -> -0.001 | AE44: =Rohdaten!AG65-Rohdaten!AG46 -> 0.023 | AF44: =Rohdaten!AH65-Rohdaten!AH46 -> -0.019 | AG44: =Rohdaten!AI65-Rohdaten!AI46 -> -0.001 | AH44: =Rohdaten!AJ65-Rohdaten!AJ46 -> 0.005 | AI44: =Rohdaten!AK65-Rohdaten!AK46 -> -0.001 | ... AM44: =Rohdaten!AO65-Rohdaten!AO46 -> 0.016
...

Sheet Modell
B2: 1 | C2: 2 | D2: 3 | E2: 4 | F2: 5 | G2: 6 | H2: 7 | I2: 8 | J2: 9 | K2: 10 | L2: 11 | M2: 12 | P2: 1 | Q2: 2 | R2: 3 | S2: 4 | T2: 5 | U2: 6 | V2: 7 | W2: 8 | X2: 9 | Y2: 10 | Z2: 11 | AA2: 12 | AD2: 1 | AE2: 2 | AF2: 3 | AG2: 4 | AH2: 5 | AI2: 6 | AJ2: 7 | AK2: 8 | AL2: 9 | AM2: 10 | AN2: 11 | AO2: 12 | AR2: 1 | AS2: 2 | AT2: 3 | AU2: 4 | AV2: 5 | AW2: 6 | AX2: 7 | AY2: 8 | AZ2: 9 | BA2: 10 | BB2: 11 | BC2: 12
